package mod.krevik.world.gen.desert;

import mod.krevik.KCore;
import net.minecraft.block.Block;
import net.minecraft.block.state.IBlockState;
import net.minecraft.init.Blocks;
import net.minecraft.item.ItemStack;
import net.minecraft.tileentity.TileEntity;
import net.minecraft.tileentity.TileEntityChest;
import net.minecraft.util.math.BlockPos;
import net.minecraft.world.World;
import net.minecraft.world.gen.feature.WorldGenerator;

import java.util.Random;

public class WorldGenOldLibrary extends WorldGenerator
{
	public WorldGenOldLibrary() { }

	private void setBlock(World world, int x, int y, int z, Block block, int metadata)
	{
		setBlockAndNotifyAdequately(world,new BlockPos(x,y,z), block.getStateFromMeta(metadata));
	}
	private void setBlock(World world, int x, int y, int z, int c, int metadata)
	{
		if(c==0) {
			setBlockAndNotifyAdequately(world,new BlockPos(x,y,z),Blocks.AIR.getDefaultState());
		}
	}
    protected void setBlockAndNotifyAdequately(World worldIn, BlockPos pos, IBlockState state)
    {
            worldIn.setBlockState(pos, state, 2);
    }


	@Override
	public boolean generate(World world, Random rand, BlockPos pos) {
		int i=pos.getX();
		int j=pos.getY();
		int k=pos.getZ();
		if(world.getBlockState(pos.down())!= KCore.ForgottenSand.getDefaultState()) {
			return false;
		}
		if(j<180) {
		this.setBlock(world, i + 0, j + 0, k + 0, 0, 0);
		this.setBlock(world, i + 0, j + 0, k + 1, 0, 0);
		this.setBlock(world, i + 0, j + 0, k + 2, KCore.WeatheredRockBricks, 0);
		this.setBlock(world, i + 0, j + 0, k + 3, KCore.WeatheredRockBricks, 0);
		this.setBlock(world, i + 0, j + 0, k + 4, KCore.WeatheredRockBricks, 0);
		this.setBlock(world, i + 0, j + 0, k + 5, KCore.WeatheredRockBricks, 0);
		this.setBlock(world, i + 0, j + 0, k + 6, KCore.WeatheredRockBricks, 0);
		this.setBlock(world, i + 0, j + 0, k + 7, KCore.WeatheredRockBricks, 0);
		this.setBlock(world, i + 0, j + 0, k + 8, KCore.WeatheredRockBricks, 0);
		this.setBlock(world, i + 0, j + 0, k + 9, KCore.WeatheredRockBricks, 0);
		this.setBlock(world, i + 0, j + 0, k + 10, KCore.WeatheredRockBricks, 0);
		this.setBlock(world, i + 0, j + 0, k + 11, KCore.WeatheredRockBricks, 0);
		this.setBlock(world, i + 0, j + 0, k + 12, KCore.WeatheredRockBricks, 0);
		this.setBlock(world, i + 0, j + 0, k + 13, KCore.WeatheredRockBricks, 0);
		this.setBlock(world, i + 0, j + 0, k + 14, 0, 0);
		this.setBlock(world, i + 0, j + 0, k + 15, 0, 0);
		this.setBlock(world, i + 0, j + 0, k + 16, 0, 0);
		this.setBlock(world, i + 0, j + 0, k + 17, 0, 0);
		this.setBlock(world, i + 0, j + 1, k + 0, 0, 0);
		this.setBlock(world, i + 0, j + 1, k + 1, 0, 0);
		this.setBlock(world, i + 0, j + 1, k + 2, KCore.WeatheredRockBricks, 0);
		this.setBlock(world, i + 0, j + 1, k + 3, KCore.WeatheredRockBricks, 0);
		this.setBlock(world, i + 0, j + 1, k + 4, KCore.WeatheredRockBricks, 0);
		this.setBlock(world, i + 0, j + 1, k + 5, KCore.WeatheredRockBricks, 0);
		this.setBlock(world, i + 0, j + 1, k + 6, KCore.WeatheredRockBricks, 0);
		this.setBlock(world, i + 0, j + 1, k + 7, KCore.WeatheredRockBricks, 0);
		this.setBlock(world, i + 0, j + 1, k + 8, KCore.WeatheredRockBricks, 0);
		this.setBlock(world, i + 0, j + 1, k + 9, KCore.WeatheredRockBricks, 0);
		this.setBlock(world, i + 0, j + 1, k + 10, KCore.WeatheredRockBricks, 0);
		this.setBlock(world, i + 0, j + 1, k + 11, KCore.WeatheredRockBricks, 0);
		this.setBlock(world, i + 0, j + 1, k + 12, KCore.WeatheredRockBricks, 0);
		this.setBlock(world, i + 0, j + 1, k + 13, KCore.WeatheredRockBricks, 0);
		this.setBlock(world, i + 0, j + 1, k + 14, 0, 0);
		this.setBlock(world, i + 0, j + 1, k + 15, 0, 0);
		this.setBlock(world, i + 0, j + 1, k + 16, 0, 0);
		this.setBlock(world, i + 0, j + 1, k + 17, 0, 0);
		this.setBlock(world, i + 0, j + 2, k + 0, 0, 0);
		this.setBlock(world, i + 0, j + 2, k + 1, 0, 0);
		this.setBlock(world, i + 0, j + 2, k + 2, KCore.WeatheredRockBricks, 0);
		this.setBlock(world, i + 0, j + 2, k + 3, KCore.WeatheredRockBricks, 0);
		this.setBlock(world, i + 0, j + 2, k + 4, KCore.WeatheredRockBricks, 0);
		this.setBlock(world, i + 0, j + 2, k + 5, KCore.WeatheredRockBricks, 0);
		this.setBlock(world, i + 0, j + 2, k + 6, KCore.WeatheredRockBricks, 0);
		this.setBlock(world, i + 0, j + 2, k + 7, KCore.WeatheredRockBricks, 0);
		this.setBlock(world, i + 0, j + 2, k + 8, KCore.WeatheredRockBricks, 0);
		this.setBlock(world, i + 0, j + 2, k + 9, KCore.WeatheredRockBricks, 0);
		this.setBlock(world, i + 0, j + 2, k + 10, KCore.WeatheredRockBricks, 0);
		this.setBlock(world, i + 0, j + 2, k + 11, KCore.WeatheredRockBricks, 0);
		this.setBlock(world, i + 0, j + 2, k + 12, KCore.WeatheredRockBricks, 0);
		this.setBlock(world, i + 0, j + 2, k + 13, KCore.WeatheredRockBricks, 0);
		this.setBlock(world, i + 0, j + 2, k + 14, 0, 0);
		this.setBlock(world, i + 0, j + 2, k + 15, 0, 0);
		this.setBlock(world, i + 0, j + 2, k + 16, 0, 0);
		this.setBlock(world, i + 0, j + 2, k + 17, 0, 0);
		this.setBlock(world, i + 0, j + 3, k + 0, 0, 0);
		this.setBlock(world, i + 0, j + 3, k + 1, 0, 0);
		this.setBlock(world, i + 0, j + 3, k + 2, KCore.WeatheredRockBricks, 0);
		this.setBlock(world, i + 0, j + 3, k + 3, KCore.WeatheredRockBricks, 0);
		this.setBlock(world, i + 0, j + 3, k + 4, KCore.WeatheredRockBricks, 0);
		this.setBlock(world, i + 0, j + 3, k + 5, KCore.WeatheredRockBricks, 0);
		this.setBlock(world, i + 0, j + 3, k + 6, KCore.WeatheredRockBricks, 0);
		this.setBlock(world, i + 0, j + 3, k + 7, KCore.WeatheredRockBricks, 0);
		this.setBlock(world, i + 0, j + 3, k + 8, KCore.WeatheredRockBricks, 0);
		this.setBlock(world, i + 0, j + 3, k + 9, KCore.WeatheredRockBricks, 0);
		this.setBlock(world, i + 0, j + 3, k + 10, KCore.WeatheredRockBricks, 0);
		this.setBlock(world, i + 0, j + 3, k + 11, KCore.WeatheredRockBricks, 0);
		this.setBlock(world, i + 0, j + 3, k + 12, KCore.WeatheredRockBricks, 0);
		this.setBlock(world, i + 0, j + 3, k + 13, KCore.WeatheredRockBricks, 0);
		this.setBlock(world, i + 0, j + 3, k + 14, 0, 0);
		this.setBlock(world, i + 0, j + 3, k + 15, 0, 0);
		this.setBlock(world, i + 0, j + 3, k + 16, 0, 0);
		this.setBlock(world, i + 0, j + 3, k + 17, 0, 0);
		this.setBlock(world, i + 0, j + 4, k + 0, 0, 0);
		this.setBlock(world, i + 0, j + 4, k + 1, 0, 0);
		this.setBlock(world, i + 0, j + 4, k + 2, KCore.WeatheredRockBricks, 0);
		this.setBlock(world, i + 0, j + 4, k + 3, KCore.WeatheredRockBricks, 0);
		this.setBlock(world, i + 0, j + 4, k + 4, KCore.WeatheredRockBricks, 0);
		this.setBlock(world, i + 0, j + 4, k + 5, KCore.WeatheredRockBricks, 0);
		this.setBlock(world, i + 0, j + 4, k + 6, KCore.WeatheredRockBricks, 0);
		this.setBlock(world, i + 0, j + 4, k + 7, KCore.WeatheredRockBricks, 0);
		this.setBlock(world, i + 0, j + 4, k + 8, KCore.WeatheredRockBricks, 0);
		this.setBlock(world, i + 0, j + 4, k + 9, KCore.WeatheredRockBricks, 0);
		this.setBlock(world, i + 0, j + 4, k + 10, KCore.WeatheredRockBricks, 0);
		this.setBlock(world, i + 0, j + 4, k + 11, KCore.WeatheredRockBricks, 0);
		this.setBlock(world, i + 0, j + 4, k + 12, KCore.WeatheredRockBricks, 0);
		this.setBlock(world, i + 0, j + 4, k + 13, KCore.WeatheredRockBricks, 0);
		this.setBlock(world, i + 0, j + 4, k + 14, 0, 0);
		this.setBlock(world, i + 0, j + 4, k + 15, 0, 0);
		this.setBlock(world, i + 0, j + 4, k + 16, 0, 0);
		this.setBlock(world, i + 0, j + 4, k + 17, 0, 0);
		this.setBlock(world, i + 0, j + 5, k + 0, 0, 0);
		this.setBlock(world, i + 0, j + 5, k + 1, 0, 0);
		this.setBlock(world, i + 0, j + 5, k + 2, KCore.WeatheredRockBricks, 0);
		this.setBlock(world, i + 0, j + 5, k + 3, KCore.WeatheredRockBricks, 0);
		this.setBlock(world, i + 0, j + 5, k + 4, KCore.WeatheredRockBricks, 0);
		this.setBlock(world, i + 0, j + 5, k + 5, KCore.WeatheredRockBricks, 0);
		this.setBlock(world, i + 0, j + 5, k + 6, KCore.WeatheredRockBricks, 0);
		this.setBlock(world, i + 0, j + 5, k + 7, KCore.WeatheredRockBricks, 0);
		this.setBlock(world, i + 0, j + 5, k + 8, KCore.WeatheredRockBricks, 0);
		this.setBlock(world, i + 0, j + 5, k + 9, KCore.WeatheredRockBricks, 0);
		this.setBlock(world, i + 0, j + 5, k + 10, KCore.WeatheredRockBricks, 0);
		this.setBlock(world, i + 0, j + 5, k + 11, KCore.WeatheredRockBricks, 0);
		this.setBlock(world, i + 0, j + 5, k + 12, KCore.WeatheredRockBricks, 0);
		this.setBlock(world, i + 0, j + 5, k + 13, KCore.WeatheredRockBricks, 0);
		this.setBlock(world, i + 0, j + 5, k + 14, 0, 0);
		this.setBlock(world, i + 0, j + 5, k + 15, 0, 0);
		this.setBlock(world, i + 0, j + 5, k + 16, 0, 0);
		this.setBlock(world, i + 0, j + 5, k + 17, 0, 0);
		this.setBlock(world, i + 0, j + 6, k + 0, 0, 0);
		this.setBlock(world, i + 0, j + 6, k + 1, 0, 0);
		this.setBlock(world, i + 0, j + 6, k + 2, KCore.WeatheredRockBricks, 0);
		this.setBlock(world, i + 0, j + 6, k + 3, KCore.WeatheredRockBricks, 0);
		this.setBlock(world, i + 0, j + 6, k + 4, KCore.WeatheredRockBricks, 0);
		this.setBlock(world, i + 0, j + 6, k + 5, KCore.WeatheredRockBricks, 0);
		this.setBlock(world, i + 0, j + 6, k + 6, KCore.WeatheredRockBricks, 0);
		this.setBlock(world, i + 0, j + 6, k + 7, KCore.WeatheredRockBricks, 0);
		this.setBlock(world, i + 0, j + 6, k + 8, KCore.WeatheredRockBricks, 0);
		this.setBlock(world, i + 0, j + 6, k + 9, KCore.WeatheredRockBricks, 0);
		this.setBlock(world, i + 0, j + 6, k + 10, KCore.WeatheredRockBricks, 0);
		this.setBlock(world, i + 0, j + 6, k + 11, KCore.WeatheredRockBricks, 0);
		this.setBlock(world, i + 0, j + 6, k + 12, KCore.WeatheredRockBricks, 0);
		this.setBlock(world, i + 0, j + 6, k + 13, KCore.WeatheredRockBricks, 0);
		this.setBlock(world, i + 0, j + 6, k + 14, 0, 0);
		this.setBlock(world, i + 0, j + 6, k + 15, 0, 0);
		this.setBlock(world, i + 0, j + 6, k + 16, 0, 0);
		this.setBlock(world, i + 0, j + 6, k + 17, 0, 0);
		this.setBlock(world, i + 0, j + 7, k + 0, 0, 0);
		this.setBlock(world, i + 0, j + 7, k + 1, 0, 0);
		this.setBlock(world, i + 0, j + 7, k + 2, 0, 0);
		this.setBlock(world, i + 0, j + 7, k + 3, 0, 0);
		this.setBlock(world, i + 0, j + 7, k + 4, 0, 0);
		this.setBlock(world, i + 0, j + 7, k + 5, 0, 0);
		this.setBlock(world, i + 0, j + 7, k + 6, 0, 0);
		this.setBlock(world, i + 0, j + 7, k + 7, 0, 0);
		this.setBlock(world, i + 0, j + 7, k + 8, 0, 0);
		this.setBlock(world, i + 0, j + 7, k + 9, 0, 0);
		this.setBlock(world, i + 0, j + 7, k + 10, 0, 0);
		this.setBlock(world, i + 0, j + 7, k + 11, 0, 0);
		this.setBlock(world, i + 0, j + 7, k + 12, 0, 0);
		this.setBlock(world, i + 0, j + 7, k + 13, 0, 0);
		this.setBlock(world, i + 0, j + 7, k + 14, 0, 0);
		this.setBlock(world, i + 0, j + 7, k + 15, 0, 0);
		this.setBlock(world, i + 0, j + 7, k + 16, 0, 0);
		this.setBlock(world, i + 0, j + 7, k + 17, 0, 0);
		this.setBlock(world, i + 0, j + 8, k + 0, 0, 0);
		this.setBlock(world, i + 0, j + 8, k + 1, 0, 0);
		this.setBlock(world, i + 0, j + 8, k + 2, 0, 0);
		this.setBlock(world, i + 0, j + 8, k + 3, 0, 0);
		this.setBlock(world, i + 0, j + 8, k + 4, 0, 0);
		this.setBlock(world, i + 0, j + 8, k + 5, 0, 0);
		this.setBlock(world, i + 0, j + 8, k + 6, 0, 0);
		this.setBlock(world, i + 0, j + 8, k + 7, 0, 0);
		this.setBlock(world, i + 0, j + 8, k + 8, 0, 0);
		this.setBlock(world, i + 0, j + 8, k + 9, 0, 0);
		this.setBlock(world, i + 0, j + 8, k + 10, 0, 0);
		this.setBlock(world, i + 0, j + 8, k + 11, 0, 0);
		this.setBlock(world, i + 0, j + 8, k + 12, 0, 0);
		this.setBlock(world, i + 0, j + 8, k + 13, 0, 0);
		this.setBlock(world, i + 0, j + 8, k + 14, 0, 0);
		this.setBlock(world, i + 0, j + 8, k + 15, 0, 0);
		this.setBlock(world, i + 0, j + 8, k + 16, 0, 0);
		this.setBlock(world, i + 0, j + 8, k + 17, 0, 0);
		this.setBlock(world, i + 0, j + 9, k + 0, 0, 0);
		this.setBlock(world, i + 0, j + 9, k + 1, 0, 0);
		this.setBlock(world, i + 0, j + 9, k + 2, 0, 0);
		this.setBlock(world, i + 0, j + 9, k + 3, 0, 0);
		this.setBlock(world, i + 0, j + 9, k + 4, 0, 0);
		this.setBlock(world, i + 0, j + 9, k + 5, 0, 0);
		this.setBlock(world, i + 0, j + 9, k + 6, 0, 0);
		this.setBlock(world, i + 0, j + 9, k + 7, 0, 0);
		this.setBlock(world, i + 0, j + 9, k + 8, 0, 0);
		this.setBlock(world, i + 0, j + 9, k + 9, 0, 0);
		this.setBlock(world, i + 0, j + 9, k + 10, 0, 0);
		this.setBlock(world, i + 0, j + 9, k + 11, 0, 0);
		this.setBlock(world, i + 0, j + 9, k + 12, 0, 0);
		this.setBlock(world, i + 0, j + 9, k + 13, 0, 0);
		this.setBlock(world, i + 0, j + 9, k + 14, 0, 0);
		this.setBlock(world, i + 0, j + 9, k + 15, 0, 0);
		this.setBlock(world, i + 0, j + 9, k + 16, 0, 0);
		this.setBlock(world, i + 0, j + 9, k + 17, 0, 0);
		this.setBlock(world, i + 1, j + 0, k + 0, 0, 0);
		this.setBlock(world, i + 1, j + 0, k + 1, 0, 0);
		this.setBlock(world, i + 1, j + 0, k + 2, KCore.WeatheredRockBricks, 0);
		this.setBlock(world, i + 1, j + 0, k + 3, KCore.WeatheredRockBricks, 0);
		this.setBlock(world, i + 1, j + 0, k + 4, KCore.WeatheredRockBricks, 0);
		this.setBlock(world, i + 1, j + 0, k + 5, KCore.WeatheredRockBricks, 0);
		this.setBlock(world, i + 1, j + 0, k + 6, KCore.WeatheredRockBricks, 0);
		this.setBlock(world, i + 1, j + 0, k + 7, KCore.WeatheredRockBricks, 0);
		this.setBlock(world, i + 1, j + 0, k + 8, KCore.WeatheredRockBricks, 0);
		this.setBlock(world, i + 1, j + 0, k + 9, KCore.WeatheredRockBricks, 0);
		this.setBlock(world, i + 1, j + 0, k + 10, KCore.WeatheredRockBricks, 0);
		this.setBlock(world, i + 1, j + 0, k + 11, KCore.WeatheredRockBricks, 0);
		this.setBlock(world, i + 1, j + 0, k + 12, KCore.WeatheredRockBricks, 0);
		this.setBlock(world, i + 1, j + 0, k + 13, KCore.WeatheredRockBricks, 0);
		this.setBlock(world, i + 1, j + 0, k + 14, 0, 0);
		this.setBlock(world, i + 1, j + 0, k + 15, 0, 0);
		this.setBlock(world, i + 1, j + 0, k + 16, 0, 0);
		this.setBlock(world, i + 1, j + 0, k + 17, 0, 0);
		this.setBlock(world, i + 1, j + 1, k + 0, 0, 0);
		this.setBlock(world, i + 1, j + 1, k + 1, 0, 0);
		this.setBlock(world, i + 1, j + 1, k + 2, KCore.WeatheredRockBricks, 0);
		this.setBlock(world, i + 1, j + 1, k + 3, Blocks.BOOKSHELF, 0);
		this.setBlock(world, i + 1, j + 1, k + 4, Blocks.BOOKSHELF, 0);
		this.setBlock(world, i + 1, j + 1, k + 5, Blocks.BOOKSHELF, 0);
		this.setBlock(world, i + 1, j + 1, k + 6, Blocks.BOOKSHELF, 0);
		this.setBlock(world, i + 1, j + 1, k + 7, Blocks.BOOKSHELF, 0);
		this.setBlock(world, i + 1, j + 1, k + 8, Blocks.BOOKSHELF, 0);
		this.setBlock(world, i + 1, j + 1, k + 9, Blocks.BOOKSHELF, 0);
		this.setBlock(world, i + 1, j + 1, k + 10, Blocks.BOOKSHELF, 0);
		this.setBlock(world, i + 1, j + 1, k + 11, Blocks.BOOKSHELF, 0);
		this.setBlock(world, i + 1, j + 1, k + 12, Blocks.BOOKSHELF, 0);
		this.setBlock(world, i + 1, j + 1, k + 13, KCore.WeatheredRockBricks, 0);
		this.setBlock(world, i + 1, j + 1, k + 14, 0, 0);
		this.setBlock(world, i + 1, j + 1, k + 15, 0, 0);
		this.setBlock(world, i + 1, j + 1, k + 16, 0, 0);
		this.setBlock(world, i + 1, j + 1, k + 17, 0, 0);
		this.setBlock(world, i + 1, j + 2, k + 0, 0, 0);
		this.setBlock(world, i + 1, j + 2, k + 1, 0, 0);
		this.setBlock(world, i + 1, j + 2, k + 2, KCore.WeatheredRockBricks, 0);
		this.setBlock(world, i + 1, j + 2, k + 3, Blocks.BOOKSHELF, 0);
		this.setBlock(world, i + 1, j + 2, k + 4, Blocks.BOOKSHELF, 0);
		this.setBlock(world, i + 1, j + 2, k + 5, Blocks.BOOKSHELF, 0);
		this.setBlock(world, i + 1, j + 2, k + 6, Blocks.BOOKSHELF, 0);
		this.setBlock(world, i + 1, j + 2, k + 7, Blocks.BOOKSHELF, 0);
		this.setBlock(world, i + 1, j + 2, k + 8, Blocks.BOOKSHELF, 0);
		this.setBlock(world, i + 1, j + 2, k + 9, Blocks.BOOKSHELF, 0);
		this.setBlock(world, i + 1, j + 2, k + 10, Blocks.BOOKSHELF, 0);
		this.setBlock(world, i + 1, j + 2, k + 11, Blocks.BOOKSHELF, 0);
		this.setBlock(world, i + 1, j + 2, k + 12, Blocks.BOOKSHELF, 0);
		this.setBlock(world, i + 1, j + 2, k + 13, KCore.WeatheredRockBricks, 0);
		this.setBlock(world, i + 1, j + 2, k + 14, 0, 0);
		this.setBlock(world, i + 1, j + 2, k + 15, 0, 0);
		this.setBlock(world, i + 1, j + 2, k + 16, 0, 0);
		this.setBlock(world, i + 1, j + 2, k + 17, 0, 0);
		this.setBlock(world, i + 1, j + 3, k + 0, 0, 0);
		this.setBlock(world, i + 1, j + 3, k + 1, 0, 0);
		this.setBlock(world, i + 1, j + 3, k + 2, KCore.WeatheredRockBricks, 0);
		this.setBlock(world, i + 1, j + 3, k + 3, KCore.WeatheredRockBricks, 0);
		this.setBlock(world, i + 1, j + 3, k + 4, KCore.WeatheredRockBricks, 0);
		this.setBlock(world, i + 1, j + 3, k + 5, KCore.WeatheredRockBricks, 0);
		this.setBlock(world, i + 1, j + 3, k + 6, KCore.WeatheredRockBricks, 0);
		this.setBlock(world, i + 1, j + 3, k + 7, KCore.WeatheredRockBricks, 0);
		this.setBlock(world, i + 1, j + 3, k + 8, KCore.WeatheredRockBricks, 0);
		this.setBlock(world, i + 1, j + 3, k + 9, KCore.WeatheredRockBricks, 0);
		this.setBlock(world, i + 1, j + 3, k + 10, KCore.WeatheredRockBricks, 0);
		this.setBlock(world, i + 1, j + 3, k + 11, KCore.WeatheredRockBricks, 0);
		this.setBlock(world, i + 1, j + 3, k + 12, KCore.WeatheredRockBricks, 0);
		this.setBlock(world, i + 1, j + 3, k + 13, KCore.WeatheredRockBricks, 0);
		this.setBlock(world, i + 1, j + 3, k + 14, 0, 0);
		this.setBlock(world, i + 1, j + 3, k + 15, 0, 0);
		this.setBlock(world, i + 1, j + 3, k + 16, 0, 0);
		this.setBlock(world, i + 1, j + 3, k + 17, 0, 0);
		this.setBlock(world, i + 1, j + 4, k + 0, 0, 0);
		this.setBlock(world, i + 1, j + 4, k + 1, 0, 0);
		this.setBlock(world, i + 1, j + 4, k + 2, KCore.WeatheredRockBricks, 0);
		this.setBlock(world, i + 1, j + 4, k + 3, Blocks.BOOKSHELF, 0);
		this.setBlock(world, i + 1, j + 4, k + 4, Blocks.BOOKSHELF, 0);
		this.setBlock(world, i + 1, j + 4, k + 5, 0, 0);
		this.setBlock(world, i + 1, j + 4, k + 6, Blocks.WEB, 0);
		this.setBlock(world, i + 1, j + 4, k + 7, Blocks.WEB, 0);
		this.setBlock(world, i + 1, j + 4, k + 8, Blocks.WEB, 0);
		this.setBlock(world, i + 1, j + 4, k + 9, Blocks.WEB, 0);
		this.setBlock(world, i + 1, j + 4, k + 10, Blocks.WEB, 0);
		this.setBlock(world, i + 1, j + 4, k + 11, 0, 0);
		this.setBlock(world, i + 1, j + 4, k + 12, Blocks.WEB, 0);
		this.setBlock(world, i + 1, j + 4, k + 13, KCore.WeatheredRockBricks, 0);
		this.setBlock(world, i + 1, j + 4, k + 14, 0, 0);
		this.setBlock(world, i + 1, j + 4, k + 15, 0, 0);
		this.setBlock(world, i + 1, j + 4, k + 16, 0, 0);
		this.setBlock(world, i + 1, j + 4, k + 17, 0, 0);
		this.setBlock(world, i + 1, j + 5, k + 0, 0, 0);
		this.setBlock(world, i + 1, j + 5, k + 1, 0, 0);
		this.setBlock(world, i + 1, j + 5, k + 2, KCore.WeatheredRockBricks, 0);
		this.setBlock(world, i + 1, j + 5, k + 3, Blocks.BOOKSHELF, 0);
		this.setBlock(world, i + 1, j + 5, k + 4, Blocks.BOOKSHELF, 0);
		this.setBlock(world, i + 1, j + 5, k + 5, Blocks.WEB, 0);
		this.setBlock(world, i + 1, j + 5, k + 6, Blocks.WEB, 0);
		this.setBlock(world, i + 1, j + 5, k + 7, Blocks.WEB, 0);
		this.setBlock(world, i + 1, j + 5, k + 8, Blocks.WEB, 0);
		this.setBlock(world, i + 1, j + 5, k + 9, Blocks.WEB, 0);
		this.setBlock(world, i + 1, j + 5, k + 10, Blocks.WEB, 0);
		this.setBlock(world, i + 1, j + 5, k + 11, Blocks.WEB, 0);
		this.setBlock(world, i + 1, j + 5, k + 12, 0, 0);
		this.setBlock(world, i + 1, j + 5, k + 13, KCore.WeatheredRockBricks, 0);
		this.setBlock(world, i + 1, j + 5, k + 14, 0, 0);
		this.setBlock(world, i + 1, j + 5, k + 15, 0, 0);
		this.setBlock(world, i + 1, j + 5, k + 16, 0, 0);
		this.setBlock(world, i + 1, j + 5, k + 17, 0, 0);
		this.setBlock(world, i + 1, j + 6, k + 0, 0, 0);
		this.setBlock(world, i + 1, j + 6, k + 1, 0, 0);
		this.setBlock(world, i + 1, j + 6, k + 2, KCore.WeatheredRockBricks, 0);
		this.setBlock(world, i + 1, j + 6, k + 3, Blocks.BOOKSHELF, 0);
		this.setBlock(world, i + 1, j + 6, k + 4, Blocks.BOOKSHELF, 0);
		this.setBlock(world, i + 1, j + 6, k + 5, Blocks.WEB, 0);
		this.setBlock(world, i + 1, j + 6, k + 6, 0, 0);
		this.setBlock(world, i + 1, j + 6, k + 7, Blocks.WEB, 0);
		this.setBlock(world, i + 1, j + 6, k + 8, 0, 0);
		this.setBlock(world, i + 1, j + 6, k + 9, Blocks.WEB, 0);
		this.setBlock(world, i + 1, j + 6, k + 10, Blocks.WEB, 0);
		this.setBlock(world, i + 1, j + 6, k + 11, 0, 0);
		this.setBlock(world, i + 1, j + 6, k + 12, Blocks.WEB, 0);
		this.setBlock(world, i + 1, j + 6, k + 13, KCore.WeatheredRockBricks, 0);
		this.setBlock(world, i + 1, j + 6, k + 14, 0, 0);
		this.setBlock(world, i + 1, j + 6, k + 15, 0, 0);
		this.setBlock(world, i + 1, j + 6, k + 16, 0, 0);
		this.setBlock(world, i + 1, j + 6, k + 17, 0, 0);
		this.setBlock(world, i + 1, j + 7, k + 0, 0, 0);
		this.setBlock(world, i + 1, j + 7, k + 1, 0, 0);
		this.setBlock(world, i + 1, j + 7, k + 2, 0, 0);
		this.setBlock(world, i + 1, j + 7, k + 3, KCore.HardenedWeatheredRockStairs, 0);
		this.setBlock(world, i + 1, j + 7, k + 4, KCore.HardenedWeatheredRockStairs, 0);
		this.setBlock(world, i + 1, j + 7, k + 5, KCore.HardenedWeatheredRockStairs, 0);
		this.setBlock(world, i + 1, j + 7, k + 6, KCore.HardenedWeatheredRockStairs, 0);
		this.setBlock(world, i + 1, j + 7, k + 7, KCore.HardenedWeatheredRockStairs, 0);
		this.setBlock(world, i + 1, j + 7, k + 8, KCore.HardenedWeatheredRockStairs, 0);
		this.setBlock(world, i + 1, j + 7, k + 9, KCore.HardenedWeatheredRockStairs, 0);
		this.setBlock(world, i + 1, j + 7, k + 10, KCore.HardenedWeatheredRockStairs, 0);
		this.setBlock(world, i + 1, j + 7, k + 11, KCore.HardenedWeatheredRockStairs, 0);
		this.setBlock(world, i + 1, j + 7, k + 12, KCore.HardenedWeatheredRockStairs, 3);
		this.setBlock(world, i + 1, j + 7, k + 13, 0, 0);
		this.setBlock(world, i + 1, j + 7, k + 14, 0, 0);
		this.setBlock(world, i + 1, j + 7, k + 15, 0, 0);
		this.setBlock(world, i + 1, j + 7, k + 16, 0, 0);
		this.setBlock(world, i + 1, j + 7, k + 17, 0, 0);
		this.setBlock(world, i + 1, j + 8, k + 0, 0, 0);
		this.setBlock(world, i + 1, j + 8, k + 1, 0, 0);
		this.setBlock(world, i + 1, j + 8, k + 2, 0, 0);
		this.setBlock(world, i + 1, j + 8, k + 3, 0, 0);
		this.setBlock(world, i + 1, j + 8, k + 4, 0, 0);
		this.setBlock(world, i + 1, j + 8, k + 5, 0, 0);
		this.setBlock(world, i + 1, j + 8, k + 6, 0, 0);
		this.setBlock(world, i + 1, j + 8, k + 7, 0, 0);
		this.setBlock(world, i + 1, j + 8, k + 8, 0, 0);
		this.setBlock(world, i + 1, j + 8, k + 9, 0, 0);
		this.setBlock(world, i + 1, j + 8, k + 10, 0, 0);
		this.setBlock(world, i + 1, j + 8, k + 11, 0, 0);
		this.setBlock(world, i + 1, j + 8, k + 12, 0, 0);
		this.setBlock(world, i + 1, j + 8, k + 13, 0, 0);
		this.setBlock(world, i + 1, j + 8, k + 14, 0, 0);
		this.setBlock(world, i + 1, j + 8, k + 15, 0, 0);
		this.setBlock(world, i + 1, j + 8, k + 16, 0, 0);
		this.setBlock(world, i + 1, j + 8, k + 17, 0, 0);
		this.setBlock(world, i + 1, j + 9, k + 0, 0, 0);
		this.setBlock(world, i + 1, j + 9, k + 1, 0, 0);
		this.setBlock(world, i + 1, j + 9, k + 2, 0, 0);
		this.setBlock(world, i + 1, j + 9, k + 3, 0, 0);
		this.setBlock(world, i + 1, j + 9, k + 4, 0, 0);
		this.setBlock(world, i + 1, j + 9, k + 5, 0, 0);
		this.setBlock(world, i + 1, j + 9, k + 6, 0, 0);
		this.setBlock(world, i + 1, j + 9, k + 7, 0, 0);
		this.setBlock(world, i + 1, j + 9, k + 8, 0, 0);
		this.setBlock(world, i + 1, j + 9, k + 9, 0, 0);
		this.setBlock(world, i + 1, j + 9, k + 10, 0, 0);
		this.setBlock(world, i + 1, j + 9, k + 11, 0, 0);
		this.setBlock(world, i + 1, j + 9, k + 12, 0, 0);
		this.setBlock(world, i + 1, j + 9, k + 13, 0, 0);
		this.setBlock(world, i + 1, j + 9, k + 14, 0, 0);
		this.setBlock(world, i + 1, j + 9, k + 15, 0, 0);
		this.setBlock(world, i + 1, j + 9, k + 16, 0, 0);
		this.setBlock(world, i + 1, j + 9, k + 17, 0, 0);
		this.setBlock(world, i + 2, j + 0, k + 0, 0, 0);
		this.setBlock(world, i + 2, j + 0, k + 1, 0, 0);
		this.setBlock(world, i + 2, j + 0, k + 2, KCore.WeatheredRockBricks, 0);
		this.setBlock(world, i + 2, j + 0, k + 3, KCore.WeatheredRockBricks, 0);
		this.setBlock(world, i + 2, j + 0, k + 4, KCore.WeatheredRockBricks, 0);
		this.setBlock(world, i + 2, j + 0, k + 5, KCore.WeatheredRockBricks, 0);
		this.setBlock(world, i + 2, j + 0, k + 6, KCore.WeatheredRockBricks, 0);
		this.setBlock(world, i + 2, j + 0, k + 7, KCore.WeatheredRockBricks, 0);
		this.setBlock(world, i + 2, j + 0, k + 8, KCore.WeatheredRockBricks, 0);
		this.setBlock(world, i + 2, j + 0, k + 9, KCore.WeatheredRockBricks, 0);
		this.setBlock(world, i + 2, j + 0, k + 10, KCore.WeatheredRockBricks, 0);
		this.setBlock(world, i + 2, j + 0, k + 11, KCore.WeatheredRockBricks, 0);
		this.setBlock(world, i + 2, j + 0, k + 12, KCore.WeatheredRockBricks, 0);
		this.setBlock(world, i + 2, j + 0, k + 13, KCore.WeatheredRockBricks, 0);
		this.setBlock(world, i + 2, j + 0, k + 14, 0, 0);
		this.setBlock(world, i + 2, j + 0, k + 15, 0, 0);
		this.setBlock(world, i + 2, j + 0, k + 16, 0, 0);
		this.setBlock(world, i + 2, j + 0, k + 17, 0, 0);
		this.setBlock(world, i + 2, j + 1, k + 0, 0, 0);
		this.setBlock(world, i + 2, j + 1, k + 1, 0, 0);
		this.setBlock(world, i + 2, j + 1, k + 2, KCore.WeatheredRockBricks, 0);
		this.setBlock(world, i + 2, j + 1, k + 3, Blocks.BOOKSHELF, 0);
		this.setBlock(world, i + 2, j + 1, k + 4, Blocks.WEB, 0);
		this.setBlock(world, i + 2, j + 1, k + 5, Blocks.WEB, 0);
		this.setBlock(world, i + 2, j + 1, k + 6, Blocks.WEB, 0);
		this.setBlock(world, i + 2, j + 1, k + 7, Blocks.WEB, 0);
		this.setBlock(world, i + 2, j + 1, k + 8, Blocks.WEB, 0);
		this.setBlock(world, i + 2, j + 1, k + 9, Blocks.WEB, 0);
		this.setBlock(world, i + 2, j + 1, k + 10, Blocks.WEB, 0);
		this.setBlock(world, i + 2, j + 1, k + 11, Blocks.WEB, 0);
		this.setBlock(world, i + 2, j + 1, k + 12, Blocks.WEB, 0);
		this.setBlock(world, i + 2, j + 1, k + 13, KCore.WeatheredRockBricks, 0);
		this.setBlock(world, i + 2, j + 1, k + 14, 0, 0);
		this.setBlock(world, i + 2, j + 1, k + 15, 0, 0);
		this.setBlock(world, i + 2, j + 1, k + 16, 0, 0);
		this.setBlock(world, i + 2, j + 1, k + 17, 0, 0);
		this.setBlock(world, i + 2, j + 2, k + 0, 0, 0);
		this.setBlock(world, i + 2, j + 2, k + 1, 0, 0);
		this.setBlock(world, i + 2, j + 2, k + 2, KCore.WeatheredRockBricks, 0);
		this.setBlock(world, i + 2, j + 2, k + 3, Blocks.BOOKSHELF, 0);
		this.setBlock(world, i + 2, j + 2, k + 4, 0, 0);
		this.setBlock(world, i + 2, j + 2, k + 5, 0, 0);
		this.setBlock(world, i + 2, j + 2, k + 6, Blocks.WEB, 0);
		this.setBlock(world, i + 2, j + 2, k + 7, 0, 0);
		this.setBlock(world, i + 2, j + 2, k + 8, Blocks.WEB, 0);
		this.setBlock(world, i + 2, j + 2, k + 9, 0, 0);
		this.setBlock(world, i + 2, j + 2, k + 10, Blocks.WEB, 0);
		this.setBlock(world, i + 2, j + 2, k + 11, 0, 0);
		this.setBlock(world, i + 2, j + 2, k + 12, Blocks.WEB, 0);
		this.setBlock(world, i + 2, j + 2, k + 13, KCore.WeatheredRockBricks, 0);
		this.setBlock(world, i + 2, j + 2, k + 14, 0, 0);
		this.setBlock(world, i + 2, j + 2, k + 15, 0, 0);
		this.setBlock(world, i + 2, j + 2, k + 16, 0, 0);
		this.setBlock(world, i + 2, j + 2, k + 17, 0, 0);
		this.setBlock(world, i + 2, j + 3, k + 0, 0, 0);
		this.setBlock(world, i + 2, j + 3, k + 1, 0, 0);
		this.setBlock(world, i + 2, j + 3, k + 2, KCore.WeatheredRockBricks, 0);
		this.setBlock(world, i + 2, j + 3, k + 3, KCore.WeatheredRockBricks, 0);
		this.setBlock(world, i + 2, j + 3, k + 4, KCore.WeatheredRockBricks, 0);
		this.setBlock(world, i + 2, j + 3, k + 5, KCore.WeatheredRockBricks, 0);
		this.setBlock(world, i + 2, j + 3, k + 6, KCore.WeatheredRockBricks, 0);
		this.setBlock(world, i + 2, j + 3, k + 7, KCore.WeatheredRockBricks, 0);
		this.setBlock(world, i + 2, j + 3, k + 8, KCore.WeatheredRockBricks, 0);
		this.setBlock(world, i + 2, j + 3, k + 9, KCore.WeatheredRockBricks, 0);
		this.setBlock(world, i + 2, j + 3, k + 10, KCore.WeatheredRockBricks, 0);
		this.setBlock(world, i + 2, j + 3, k + 11, KCore.WeatheredRockBricks, 0);
		this.setBlock(world, i + 2, j + 3, k + 12, KCore.WeatheredRockBricks, 0);
		this.setBlock(world, i + 2, j + 3, k + 13, KCore.WeatheredRockBricks, 0);
		this.setBlock(world, i + 2, j + 3, k + 14, 0, 0);
		this.setBlock(world, i + 2, j + 3, k + 15, 0, 0);
		this.setBlock(world, i + 2, j + 3, k + 16, 0, 0);
		this.setBlock(world, i + 2, j + 3, k + 17, 0, 0);
		this.setBlock(world, i + 2, j + 4, k + 0, 0, 0);
		this.setBlock(world, i + 2, j + 4, k + 1, 0, 0);
		this.setBlock(world, i + 2, j + 4, k + 2, KCore.WeatheredRockBricks, 0);
		this.setBlock(world, i + 2, j + 4, k + 3, Blocks.WEB, 0);
		this.setBlock(world, i + 2, j + 4, k + 4, Blocks.WEB, 0);
		this.setBlock(world, i + 2, j + 4, k + 5, Blocks.WEB, 0);
		this.setBlock(world, i + 2, j + 4, k + 6, Blocks.BOOKSHELF, 0);
		this.setBlock(world, i + 2, j + 4, k + 7, Blocks.BOOKSHELF, 0);
		this.setBlock(world, i + 2, j + 4, k + 8, Blocks.BOOKSHELF, 0);
		this.setBlock(world, i + 2, j + 4, k + 9, Blocks.BOOKSHELF, 0);
		this.setBlock(world, i + 2, j + 4, k + 10, Blocks.BOOKSHELF, 0);
		this.setBlock(world, i + 2, j + 4, k + 11, Blocks.BOOKSHELF, 0);
		this.setBlock(world, i + 2, j + 4, k + 12, Blocks.WEB, 0);
		this.setBlock(world, i + 2, j + 4, k + 13, KCore.WeatheredRockBricks, 0);
		this.setBlock(world, i + 2, j + 4, k + 14, 0, 0);
		this.setBlock(world, i + 2, j + 4, k + 15, 0, 0);
		this.setBlock(world, i + 2, j + 4, k + 16, 0, 0);
		this.setBlock(world, i + 2, j + 4, k + 17, 0, 0);
		this.setBlock(world, i + 2, j + 5, k + 0, 0, 0);
		this.setBlock(world, i + 2, j + 5, k + 1, 0, 0);
		this.setBlock(world, i + 2, j + 5, k + 2, KCore.WeatheredRockBricks, 0);
		this.setBlock(world, i + 2, j + 5, k + 3, 0, 0);
		this.setBlock(world, i + 2, j + 5, k + 4, Blocks.WEB, 0);
		this.setBlock(world, i + 2, j + 5, k + 5, Blocks.WEB, 0);
		this.setBlock(world, i + 2, j + 5, k + 6, Blocks.BOOKSHELF, 0);
		this.setBlock(world, i + 2, j + 5, k + 7, Blocks.BOOKSHELF, 0);
		this.setBlock(world, i + 2, j + 5, k + 8, Blocks.BOOKSHELF, 0);
		this.setBlock(world, i + 2, j + 5, k + 9, Blocks.BOOKSHELF, 0);
		this.setBlock(world, i + 2, j + 5, k + 10, Blocks.BOOKSHELF, 0);
		this.setBlock(world, i + 2, j + 5, k + 11, Blocks.BOOKSHELF, 0);
		this.setBlock(world, i + 2, j + 5, k + 12, Blocks.WEB, 0);
		this.setBlock(world, i + 2, j + 5, k + 13, KCore.WeatheredRockBricks, 0);
		this.setBlock(world, i + 2, j + 5, k + 14, 0, 0);
		this.setBlock(world, i + 2, j + 5, k + 15, 0, 0);
		this.setBlock(world, i + 2, j + 5, k + 16, 0, 0);
		this.setBlock(world, i + 2, j + 5, k + 17, 0, 0);
		this.setBlock(world, i + 2, j + 6, k + 0, 0, 0);
		this.setBlock(world, i + 2, j + 6, k + 1, 0, 0);
		this.setBlock(world, i + 2, j + 6, k + 2, KCore.WeatheredRockBricks, 0);
		this.setBlock(world, i + 2, j + 6, k + 3, 0, 0);
		this.setBlock(world, i + 2, j + 6, k + 4, 0, 0);
		this.setBlock(world, i + 2, j + 6, k + 5, 0, 0);
		this.setBlock(world, i + 2, j + 6, k + 6, Blocks.BOOKSHELF, 0);
		this.setBlock(world, i + 2, j + 6, k + 7, Blocks.BOOKSHELF, 0);
		this.setBlock(world, i + 2, j + 6, k + 8, Blocks.BOOKSHELF, 0);
		this.setBlock(world, i + 2, j + 6, k + 9, Blocks.BOOKSHELF, 0);
		this.setBlock(world, i + 2, j + 6, k + 10, Blocks.BOOKSHELF, 0);
		this.setBlock(world, i + 2, j + 6, k + 11, Blocks.BOOKSHELF, 0);
		this.setBlock(world, i + 2, j + 6, k + 12, 0, 0);
		this.setBlock(world, i + 2, j + 6, k + 13, KCore.WeatheredRockBricks, 0);
		this.setBlock(world, i + 2, j + 6, k + 14, 0, 0);
		this.setBlock(world, i + 2, j + 6, k + 15, 0, 0);
		this.setBlock(world, i + 2, j + 6, k + 16, 0, 0);
		this.setBlock(world, i + 2, j + 6, k + 17, 0, 0);
		this.setBlock(world, i + 2, j + 7, k + 0, 0, 0);
		this.setBlock(world, i + 2, j + 7, k + 1, 0, 0);
		this.setBlock(world, i + 2, j + 7, k + 2, 0, 0);
		this.setBlock(world, i + 2, j + 7, k + 3, KCore.HardenedWeatheredRockStairs, 2);
		this.setBlock(world, i + 2, j + 7, k + 4, 0, 0);
		this.setBlock(world, i + 2, j + 7, k + 5, 0, 0);
		this.setBlock(world, i + 2, j + 7, k + 6, 0, 0);
		this.setBlock(world, i + 2, j + 7, k + 7, 0, 0);
		this.setBlock(world, i + 2, j + 7, k + 8, 0, 0);
		this.setBlock(world, i + 2, j + 7, k + 9, 0, 0);
		this.setBlock(world, i + 2, j + 7, k + 10, 0, 0);
		this.setBlock(world, i + 2, j + 7, k + 11, 0, 0);
		this.setBlock(world, i + 2, j + 7, k + 12, KCore.HardenedWeatheredRockStairs, 3);
		this.setBlock(world, i + 2, j + 7, k + 13, 0, 0);
		this.setBlock(world, i + 2, j + 7, k + 14, 0, 0);
		this.setBlock(world, i + 2, j + 7, k + 15, 0, 0);
		this.setBlock(world, i + 2, j + 7, k + 16, 0, 0);
		this.setBlock(world, i + 2, j + 7, k + 17, 0, 0);
		this.setBlock(world, i + 2, j + 8, k + 0, 0, 0);
		this.setBlock(world, i + 2, j + 8, k + 1, 0, 0);
		this.setBlock(world, i + 2, j + 8, k + 2, 0, 0);
		this.setBlock(world, i + 2, j + 8, k + 3, 0, 0);
		this.setBlock(world, i + 2, j + 8, k + 4, KCore.WeatheredRockBricks, 0);
		this.setBlock(world, i + 2, j + 8, k + 5, KCore.WeatheredRockBricks, 0);
		this.setBlock(world, i + 2, j + 8, k + 6, KCore.WeatheredRockBricks, 0);
		this.setBlock(world, i + 2, j + 8, k + 7, KCore.WeatheredRockBricks, 0);
		this.setBlock(world, i + 2, j + 8, k + 8, KCore.HardenedWeatheredRockStairs, 0);
		this.setBlock(world, i + 2, j + 8, k + 9, KCore.HardenedWeatheredRockStairs, 0);
		this.setBlock(world, i + 2, j + 8, k + 10, KCore.HardenedWeatheredRockStairs, 0);
		this.setBlock(world, i + 2, j + 8, k + 11, KCore.HardenedWeatheredRockStairs, 0);
		this.setBlock(world, i + 2, j + 8, k + 12, 0, 0);
		this.setBlock(world, i + 2, j + 8, k + 13, 0, 0);
		this.setBlock(world, i + 2, j + 8, k + 14, 0, 0);
		this.setBlock(world, i + 2, j + 8, k + 15, 0, 0);
		this.setBlock(world, i + 2, j + 8, k + 16, 0, 0);
		this.setBlock(world, i + 2, j + 8, k + 17, 0, 0);
		this.setBlock(world, i + 2, j + 9, k + 0, 0, 0);
		this.setBlock(world, i + 2, j + 9, k + 1, 0, 0);
		this.setBlock(world, i + 2, j + 9, k + 2, 0, 0);
		this.setBlock(world, i + 2, j + 9, k + 3, 0, 0);
		this.setBlock(world, i + 2, j + 9, k + 4, 0, 0);
		this.setBlock(world, i + 2, j + 9, k + 5, 0, 0);
		this.setBlock(world, i + 2, j + 9, k + 6, 0, 0);
		this.setBlock(world, i + 2, j + 9, k + 7, 0, 0);
		this.setBlock(world, i + 2, j + 9, k + 8, 0, 0);
		this.setBlock(world, i + 2, j + 9, k + 9, 0, 0);
		this.setBlock(world, i + 2, j + 9, k + 10, 0, 0);
		this.setBlock(world, i + 2, j + 9, k + 11, 0, 0);
		this.setBlock(world, i + 2, j + 9, k + 12, 0, 0);
		this.setBlock(world, i + 2, j + 9, k + 13, 0, 0);
		this.setBlock(world, i + 2, j + 9, k + 14, 0, 0);
		this.setBlock(world, i + 2, j + 9, k + 15, 0, 0);
		this.setBlock(world, i + 2, j + 9, k + 16, 0, 0);
		this.setBlock(world, i + 2, j + 9, k + 17, 0, 0);
		this.setBlock(world, i + 3, j + 0, k + 0, 0, 0);
		this.setBlock(world, i + 3, j + 0, k + 1, 0, 0);
		this.setBlock(world, i + 3, j + 0, k + 2, KCore.WeatheredRockBricks, 0);
		this.setBlock(world, i + 3, j + 0, k + 3, KCore.WeatheredRockBricks, 0);
		this.setBlock(world, i + 3, j + 0, k + 4, KCore.WeatheredRockBricks, 0);
		this.setBlock(world, i + 3, j + 0, k + 5, KCore.WeatheredRockBricks, 0);
		this.setBlock(world, i + 3, j + 0, k + 6, KCore.WeatheredRockBricks, 0);
		this.setBlock(world, i + 3, j + 0, k + 7, KCore.WeatheredRockBricks, 0);
		this.setBlock(world, i + 3, j + 0, k + 8, KCore.WeatheredRockBricks, 0);
		this.setBlock(world, i + 3, j + 0, k + 9, KCore.WeatheredRockBricks, 0);
		this.setBlock(world, i + 3, j + 0, k + 10, KCore.WeatheredRockBricks, 0);
		this.setBlock(world, i + 3, j + 0, k + 11, KCore.WeatheredRockBricks, 0);
		this.setBlock(world, i + 3, j + 0, k + 12, KCore.WeatheredRockBricks, 0);
		this.setBlock(world, i + 3, j + 0, k + 13, KCore.WeatheredRockBricks, 0);
		this.setBlock(world, i + 3, j + 0, k + 14, 0, 0);
		this.setBlock(world, i + 3, j + 0, k + 15, 0, 0);
		this.setBlock(world, i + 3, j + 0, k + 16, 0, 0);
		this.setBlock(world, i + 3, j + 0, k + 17, 0, 0);
		this.setBlock(world, i + 3, j + 1, k + 0, 0, 0);
		this.setBlock(world, i + 3, j + 1, k + 1, 0, 0);
		this.setBlock(world, i + 3, j + 1, k + 2, KCore.WeatheredRockBricks, 0);
		this.setBlock(world, i + 3, j + 1, k + 3, Blocks.BOOKSHELF, 0);
		this.setBlock(world, i + 3, j + 1, k + 4, 0, 0);
		this.setBlock(world, i + 3, j + 1, k + 5, Blocks.BOOKSHELF, 0);
		this.setBlock(world, i + 3, j + 1, k + 6, Blocks.BOOKSHELF, 0);
		this.setBlock(world, i + 3, j + 1, k + 7, Blocks.BOOKSHELF, 0);
		this.setBlock(world, i + 3, j + 1, k + 8, Blocks.BOOKSHELF, 0);
		this.setBlock(world, i + 3, j + 1, k + 9, Blocks.BOOKSHELF, 0);
		this.setBlock(world, i + 3, j + 1, k + 10, Blocks.BOOKSHELF, 0);
		this.setBlock(world, i + 3, j + 1, k + 11, Blocks.BOOKSHELF, 0);
		this.setBlock(world, i + 3, j + 1, k + 12, Blocks.WEB, 0);
		this.setBlock(world, i + 3, j + 1, k + 13, KCore.WeatheredRockBricks, 0);
		this.setBlock(world, i + 3, j + 1, k + 14, 0, 0);
		this.setBlock(world, i + 3, j + 1, k + 15, 0, 0);
		this.setBlock(world, i + 3, j + 1, k + 16, 0, 0);
		this.setBlock(world, i + 3, j + 1, k + 17, 0, 0);
		this.setBlock(world, i + 3, j + 2, k + 0, 0, 0);
		this.setBlock(world, i + 3, j + 2, k + 1, 0, 0);
		this.setBlock(world, i + 3, j + 2, k + 2, KCore.WeatheredRockBricks, 0);
		this.setBlock(world, i + 3, j + 2, k + 3, Blocks.BOOKSHELF, 0);
		this.setBlock(world, i + 3, j + 2, k + 4, 0, 0);
		this.setBlock(world, i + 3, j + 2, k + 5, Blocks.BOOKSHELF, 0);
		this.setBlock(world, i + 3, j + 2, k + 6, Blocks.BOOKSHELF, 0);
		this.setBlock(world, i + 3, j + 2, k + 7, Blocks.BOOKSHELF, 0);
		this.setBlock(world, i + 3, j + 2, k + 8, Blocks.BOOKSHELF, 0);
		this.setBlock(world, i + 3, j + 2, k + 9, Blocks.BOOKSHELF, 0);
		this.setBlock(world, i + 3, j + 2, k + 10, Blocks.BOOKSHELF, 0);
		this.setBlock(world, i + 3, j + 2, k + 11, Blocks.BOOKSHELF, 0);
		this.setBlock(world, i + 3, j + 2, k + 12, Blocks.WEB, 0);
		this.setBlock(world, i + 3, j + 2, k + 13, KCore.WeatheredRockBricks, 0);
		this.setBlock(world, i + 3, j + 2, k + 14, 0, 0);
		this.setBlock(world, i + 3, j + 2, k + 15, 0, 0);
		this.setBlock(world, i + 3, j + 2, k + 16, 0, 0);
		this.setBlock(world, i + 3, j + 2, k + 17, 0, 0);
		this.setBlock(world, i + 3, j + 3, k + 0, 0, 0);
		this.setBlock(world, i + 3, j + 3, k + 1, 0, 0);
		this.setBlock(world, i + 3, j + 3, k + 2, KCore.WeatheredRockBricks, 0);
		this.setBlock(world, i + 3, j + 3, k + 3, KCore.WeatheredRockBricks, 0);
		this.setBlock(world, i + 3, j + 3, k + 4, KCore.WeatheredRockBricks, 0);
		this.setBlock(world, i + 3, j + 3, k + 5, KCore.WeatheredRockBricks, 0);
		this.setBlock(world, i + 3, j + 3, k + 6, KCore.WeatheredRockBricks, 0);
		this.setBlock(world, i + 3, j + 3, k + 7, KCore.WeatheredRockBricks, 0);
		this.setBlock(world, i + 3, j + 3, k + 8, KCore.WeatheredRockBricks, 0);
		this.setBlock(world, i + 3, j + 3, k + 9, KCore.WeatheredRockBricks, 0);
		this.setBlock(world, i + 3, j + 3, k + 10, KCore.WeatheredRockBricks, 0);
		this.setBlock(world, i + 3, j + 3, k + 11, KCore.WeatheredRockBricks, 0);
		this.setBlock(world, i + 3, j + 3, k + 12, KCore.WeatheredRockBricks, 0);
		this.setBlock(world, i + 3, j + 3, k + 13, KCore.WeatheredRockBricks, 0);
		this.setBlock(world, i + 3, j + 3, k + 14, 0, 0);
		this.setBlock(world, i + 3, j + 3, k + 15, 0, 0);
		this.setBlock(world, i + 3, j + 3, k + 16, 0, 0);
		this.setBlock(world, i + 3, j + 3, k + 17, 0, 0);
		this.setBlock(world, i + 3, j + 4, k + 0, 0, 0);
		this.setBlock(world, i + 3, j + 4, k + 1, 0, 0);
		this.setBlock(world, i + 3, j + 4, k + 2, KCore.WeatheredRockBricks, 0);
		if(rand.nextInt(3)==0) {
			this.setBlock(world, i + 3, j + 4, k + 3, Blocks.CHEST, 3);
			TileEntity te=world.getTileEntity(new BlockPos(i+3,j+4,k+3));
			if(te!=null) {
			if(te instanceof TileEntityChest) {
				te= world.getTileEntity(new BlockPos(i+3,j+4,k+3));
				for(int c=0;c<=rand.nextInt(10);c++) {
					ItemStack is=KCore.functionHelper.getRandomReward1();
					((TileEntityChest) te).setInventorySlotContents(1+rand.nextInt(9), is);
				}
			}
			}
		}
		this.setBlock(world, i + 3, j + 4, k + 4, Blocks.WEB, 0);
		this.setBlock(world, i + 3, j + 4, k + 5, Blocks.WEB, 0);
		this.setBlock(world, i + 3, j + 4, k + 6, Blocks.BOOKSHELF, 0);
		this.setBlock(world, i + 3, j + 4, k + 7, Blocks.WEB, 0);
		this.setBlock(world, i + 3, j + 4, k + 8, 0, 0);
		this.setBlock(world, i + 3, j + 4, k + 9, 0, 0);
		this.setBlock(world, i + 3, j + 4, k + 10, Blocks.WEB, 0);
		this.setBlock(world, i + 3, j + 4, k + 11, Blocks.WEB, 0);
		this.setBlock(world, i + 3, j + 4, k + 12, Blocks.WEB, 0);
		this.setBlock(world, i + 3, j + 4, k + 13, KCore.WeatheredRockBricks, 0);
		this.setBlock(world, i + 3, j + 4, k + 14, 0, 0);
		this.setBlock(world, i + 3, j + 4, k + 15, 0, 0);
		this.setBlock(world, i + 3, j + 4, k + 16, 0, 0);
		this.setBlock(world, i + 3, j + 4, k + 17, 0, 0);
		this.setBlock(world, i + 3, j + 5, k + 0, 0, 0);
		this.setBlock(world, i + 3, j + 5, k + 1, 0, 0);
		this.setBlock(world, i + 3, j + 5, k + 2, KCore.WeatheredRockBricks, 0);
		this.setBlock(world, i + 3, j + 5, k + 3, Blocks.WEB, 0);
		this.setBlock(world, i + 3, j + 5, k + 4, Blocks.WEB, 0);
		this.setBlock(world, i + 3, j + 5, k + 5, Blocks.WEB, 0);
		this.setBlock(world, i + 3, j + 5, k + 6, Blocks.BOOKSHELF, 0);
		this.setBlock(world, i + 3, j + 5, k + 7, Blocks.WEB, 0);
		this.setBlock(world, i + 3, j + 5, k + 8, Blocks.WEB, 0);
		this.setBlock(world, i + 3, j + 5, k + 9, Blocks.WEB, 0);
		this.setBlock(world, i + 3, j + 5, k + 10, Blocks.WEB, 0);
		this.setBlock(world, i + 3, j + 5, k + 11, 0, 0);
		this.setBlock(world, i + 3, j + 5, k + 12, Blocks.WEB, 0);
		this.setBlock(world, i + 3, j + 5, k + 13, KCore.WeatheredRockBricks, 0);
		this.setBlock(world, i + 3, j + 5, k + 14, 0, 0);
		this.setBlock(world, i + 3, j + 5, k + 15, 0, 0);
		this.setBlock(world, i + 3, j + 5, k + 16, 0, 0);
		this.setBlock(world, i + 3, j + 5, k + 17, 0, 0);
		this.setBlock(world, i + 3, j + 6, k + 0, 0, 0);
		this.setBlock(world, i + 3, j + 6, k + 1, 0, 0);
		this.setBlock(world, i + 3, j + 6, k + 2, KCore.WeatheredRockBricks, 0);
		this.setBlock(world, i + 3, j + 6, k + 3, Blocks.WEB, 0);
		this.setBlock(world, i + 3, j + 6, k + 4, Blocks.WEB, 0);
		this.setBlock(world, i + 3, j + 6, k + 5, 0, 0);
		this.setBlock(world, i + 3, j + 6, k + 6, Blocks.BOOKSHELF, 0);
		this.setBlock(world, i + 3, j + 6, k + 7, Blocks.WEB, 0);
		this.setBlock(world, i + 3, j + 6, k + 8, 0, 0);
		this.setBlock(world, i + 3, j + 6, k + 9, 0, 0);
		this.setBlock(world, i + 3, j + 6, k + 10, Blocks.WEB, 0);
		this.setBlock(world, i + 3, j + 6, k + 11, Blocks.WEB, 0);
		this.setBlock(world, i + 3, j + 6, k + 12, Blocks.WEB, 0);
		this.setBlock(world, i + 3, j + 6, k + 13, KCore.WeatheredRockBricks, 0);
		this.setBlock(world, i + 3, j + 6, k + 14, 0, 0);
		this.setBlock(world, i + 3, j + 6, k + 15, 0, 0);
		this.setBlock(world, i + 3, j + 6, k + 16, 0, 0);
		this.setBlock(world, i + 3, j + 6, k + 17, 0, 0);
		this.setBlock(world, i + 3, j + 7, k + 0, 0, 0);
		this.setBlock(world, i + 3, j + 7, k + 1, 0, 0);
		this.setBlock(world, i + 3, j + 7, k + 2, 0, 0);
		this.setBlock(world, i + 3, j + 7, k + 3, KCore.HardenedWeatheredRockStairs, 2);
		this.setBlock(world, i + 3, j + 7, k + 4, KCore.HardenedWeatheredRockStairs, 1);
		this.setBlock(world, i + 3, j + 7, k + 5, KCore.HardenedWeatheredRockStairs, 1);
		this.setBlock(world, i + 3, j + 7, k + 6, KCore.HardenedWeatheredRockStairs, 1);
		this.setBlock(world, i + 3, j + 7, k + 7, KCore.HardenedWeatheredRockStairs, 1);
		this.setBlock(world, i + 3, j + 7, k + 8, 0, 0);
		this.setBlock(world, i + 3, j + 7, k + 9, 0, 0);
		this.setBlock(world, i + 3, j + 7, k + 10, Blocks.WEB, 0);
		this.setBlock(world, i + 3, j + 7, k + 11, Blocks.WEB, 0);
		this.setBlock(world, i + 3, j + 7, k + 12, KCore.HardenedWeatheredRockStairs, 3);
		this.setBlock(world, i + 3, j + 7, k + 13, 0, 0);
		this.setBlock(world, i + 3, j + 7, k + 14, 0, 0);
		this.setBlock(world, i + 3, j + 7, k + 15, 0, 0);
		this.setBlock(world, i + 3, j + 7, k + 16, 0, 0);
		this.setBlock(world, i + 3, j + 7, k + 17, 0, 0);
		this.setBlock(world, i + 3, j + 8, k + 0, 0, 0);
		this.setBlock(world, i + 3, j + 8, k + 1, 0, 0);
		this.setBlock(world, i + 3, j + 8, k + 2, 0, 0);
		this.setBlock(world, i + 3, j + 8, k + 3, 0, 0);
		this.setBlock(world, i + 3, j + 8, k + 4, 0, 0);
		this.setBlock(world, i + 3, j + 8, k + 5, 0, 0);
		this.setBlock(world, i + 3, j + 8, k + 6, 0, 0);
		this.setBlock(world, i + 3, j + 8, k + 7, 0, 0);
		this.setBlock(world, i + 3, j + 8, k + 8, KCore.HardenedWeatheredRockStairs, 2);
		this.setBlock(world, i + 3, j + 8, k + 9, 0, 0);
		this.setBlock(world, i + 3, j + 8, k + 10, 0, 0);
		this.setBlock(world, i + 3, j + 8, k + 11, KCore.HardenedWeatheredRockStairs, 3);
		this.setBlock(world, i + 3, j + 8, k + 12, 0, 0);
		this.setBlock(world, i + 3, j + 8, k + 13, 0, 0);
		this.setBlock(world, i + 3, j + 8, k + 14, 0, 0);
		this.setBlock(world, i + 3, j + 8, k + 15, 0, 0);
		this.setBlock(world, i + 3, j + 8, k + 16, 0, 0);
		this.setBlock(world, i + 3, j + 8, k + 17, 0, 0);
		this.setBlock(world, i + 3, j + 9, k + 0, 0, 0);
		this.setBlock(world, i + 3, j + 9, k + 1, 0, 0);
		this.setBlock(world, i + 3, j + 9, k + 2, 0, 0);
		this.setBlock(world, i + 3, j + 9, k + 3, 0, 0);
		this.setBlock(world, i + 3, j + 9, k + 4, 0, 0);
		this.setBlock(world, i + 3, j + 9, k + 5, 0, 0);
		this.setBlock(world, i + 3, j + 9, k + 6, 0, 0);
		this.setBlock(world, i + 3, j + 9, k + 7, 0, 0);
		this.setBlock(world, i + 3, j + 9, k + 8, 0, 0);
		this.setBlock(world, i + 3, j + 9, k + 9, KCore.HardenedWeatheredRockStairs, 2);
		this.setBlock(world, i + 3, j + 9, k + 10, KCore.HardenedWeatheredRockStairs, 3);
		this.setBlock(world, i + 3, j + 9, k + 11, 0, 0);
		this.setBlock(world, i + 3, j + 9, k + 12, 0, 0);
		this.setBlock(world, i + 3, j + 9, k + 13, 0, 0);
		this.setBlock(world, i + 3, j + 9, k + 14, 0, 0);
		this.setBlock(world, i + 3, j + 9, k + 15, 0, 0);
		this.setBlock(world, i + 3, j + 9, k + 16, 0, 0);
		this.setBlock(world, i + 3, j + 9, k + 17, 0, 0);
		this.setBlock(world, i + 4, j + 0, k + 0, 0, 0);
		this.setBlock(world, i + 4, j + 0, k + 1, KCore.WeatheredRockBricks, 0);
		this.setBlock(world, i + 4, j + 0, k + 2, KCore.WeatheredRockBricks, 0);
		this.setBlock(world, i + 4, j + 0, k + 3, KCore.WeatheredRockBricks, 0);
		this.setBlock(world, i + 4, j + 0, k + 4, KCore.WeatheredRockBricks, 0);
		this.setBlock(world, i + 4, j + 0, k + 5, KCore.WeatheredRockBricks, 0);
		this.setBlock(world, i + 4, j + 0, k + 6, KCore.WeatheredRockBricks, 0);
		this.setBlock(world, i + 4, j + 0, k + 7, KCore.WeatheredRockBricks, 0);
		this.setBlock(world, i + 4, j + 0, k + 8, KCore.WeatheredRockBricks, 0);
		this.setBlock(world, i + 4, j + 0, k + 9, KCore.WeatheredRockBricks, 0);
		this.setBlock(world, i + 4, j + 0, k + 10, KCore.WeatheredRockBricks, 0);
		this.setBlock(world, i + 4, j + 0, k + 11, KCore.WeatheredRockBricks, 0);
		this.setBlock(world, i + 4, j + 0, k + 12, KCore.WeatheredRockBricks, 0);
		this.setBlock(world, i + 4, j + 0, k + 13, KCore.WeatheredRockBricks, 0);
		this.setBlock(world, i + 4, j + 0, k + 14, 0, 0);
		this.setBlock(world, i + 4, j + 0, k + 15, 0, 0);
		this.setBlock(world, i + 4, j + 0, k + 16, 0, 0);
		this.setBlock(world, i + 4, j + 0, k + 17, 0, 0);
		this.setBlock(world, i + 4, j + 1, k + 0, 0, 0);
		this.setBlock(world, i + 4, j + 1, k + 1, KCore.WeatheredRockBricks, 0);
		this.setBlock(world, i + 4, j + 1, k + 2, KCore.WeatheredRockBricks, 0);
		this.setBlock(world, i + 4, j + 1, k + 3, 0, 0);
		this.setBlock(world, i + 4, j + 1, k + 4, 0, 0);
		this.setBlock(world, i + 4, j + 1, k + 5, KCore.WeatheredRockBricks, 0);
		this.setBlock(world, i + 4, j + 1, k + 6, KCore.WeatheredRockBricks, 0);
		if(rand.nextInt(3)==0) {
		this.setBlock(world, i + 4, j + 1, k + 7, Blocks.CHEST, 3);
		TileEntity te=world.getTileEntity(new BlockPos(i+4,j+1,k+7));
		if(te!=null) {
		if(te instanceof TileEntityChest) {
			te= world.getTileEntity(new BlockPos(i+4,j+1,k+7));
			for(int c=0;c<=rand.nextInt(10);c++) {
				ItemStack is=KCore.functionHelper.getRandomReward1();
				((TileEntityChest) te).setInventorySlotContents(1+rand.nextInt(9), is);
			}
		}
		}
		}
		this.setBlock(world, i + 4, j + 1, k + 8, Blocks.WEB, 0);
		this.setBlock(world, i + 4, j + 1, k + 9, 0, 0);
		this.setBlock(world, i + 4, j + 1, k + 10, Blocks.WEB, 0);
		this.setBlock(world, i + 4, j + 1, k + 11, 0, 0);
		this.setBlock(world, i + 4, j + 1, k + 12, Blocks.WEB, 0);
		this.setBlock(world, i + 4, j + 1, k + 13, KCore.WeatheredRockBricks, 0);
		this.setBlock(world, i + 4, j + 1, k + 14, 0, 0);
		this.setBlock(world, i + 4, j + 1, k + 15, 0, 0);
		this.setBlock(world, i + 4, j + 1, k + 16, 0, 0);
		this.setBlock(world, i + 4, j + 1, k + 17, 0, 0);
		this.setBlock(world, i + 4, j + 2, k + 0, 0, 0);
		this.setBlock(world, i + 4, j + 2, k + 1, KCore.WeatheredRockBricks, 0);
		this.setBlock(world, i + 4, j + 2, k + 2, KCore.WeatheredRockBricks, 0);
		this.setBlock(world, i + 4, j + 2, k + 3, 0, 0);
		this.setBlock(world, i + 4, j + 2, k + 4, 0, 0);
		this.setBlock(world, i + 4, j + 2, k + 5, KCore.WeatheredRockBricks, 0);
		this.setBlock(world, i + 4, j + 2, k + 6, KCore.WeatheredRockBricks, 0);
		this.setBlock(world, i + 4, j + 2, k + 7, Blocks.WEB, 0);
		this.setBlock(world, i + 4, j + 2, k + 8, Blocks.WEB, 0);
		this.setBlock(world, i + 4, j + 2, k + 9, 0, 0);
		this.setBlock(world, i + 4, j + 2, k + 10, Blocks.WEB, 0);
		this.setBlock(world, i + 4, j + 2, k + 11, 0, 0);
		this.setBlock(world, i + 4, j + 2, k + 12, 0, 0);
		this.setBlock(world, i + 4, j + 2, k + 13, KCore.WeatheredRockBricks, 0);
		this.setBlock(world, i + 4, j + 2, k + 14, 0, 0);
		this.setBlock(world, i + 4, j + 2, k + 15, 0, 0);
		this.setBlock(world, i + 4, j + 2, k + 16, 0, 0);
		this.setBlock(world, i + 4, j + 2, k + 17, 0, 0);
		this.setBlock(world, i + 4, j + 3, k + 0, 0, 0);
		this.setBlock(world, i + 4, j + 3, k + 1, KCore.WeatheredRockBricks, 0);
		this.setBlock(world, i + 4, j + 3, k + 2, KCore.WeatheredRockBricks, 0);
		this.setBlock(world, i + 4, j + 3, k + 3, KCore.HardenedWeatheredRockStairs, 0);
		this.setBlock(world, i + 4, j + 3, k + 4, KCore.HardenedWeatheredRockStairs, 0);
		this.setBlock(world, i + 4, j + 3, k + 5, KCore.WeatheredRockBricks, 0);
		this.setBlock(world, i + 4, j + 3, k + 6, KCore.WeatheredRockBricks, 0);
		this.setBlock(world, i + 4, j + 3, k + 7, KCore.WeatheredRockBricks, 0);
		this.setBlock(world, i + 4, j + 3, k + 8, KCore.WeatheredRockBricks, 0);
		this.setBlock(world, i + 4, j + 3, k + 9, KCore.WeatheredRockBricks, 0);
		this.setBlock(world, i + 4, j + 3, k + 10, KCore.WeatheredRockBricks, 0);
		this.setBlock(world, i + 4, j + 3, k + 11, KCore.WeatheredRockBricks, 0);
		this.setBlock(world, i + 4, j + 3, k + 12, KCore.WeatheredRockBricks, 0);
		this.setBlock(world, i + 4, j + 3, k + 13, KCore.WeatheredRockBricks, 0);
		this.setBlock(world, i + 4, j + 3, k + 14, 0, 0);
		this.setBlock(world, i + 4, j + 3, k + 15, 0, 0);
		this.setBlock(world, i + 4, j + 3, k + 16, 0, 0);
		this.setBlock(world, i + 4, j + 3, k + 17, 0, 0);
		this.setBlock(world, i + 4, j + 4, k + 0, 0, 0);
		this.setBlock(world, i + 4, j + 4, k + 1, 0, 0);
		this.setBlock(world, i + 4, j + 4, k + 2, KCore.WeatheredRockBricks, 0);
		this.setBlock(world, i + 4, j + 4, k + 3, KCore.WeatheredRockBricks, 0);
		this.setBlock(world, i + 4, j + 4, k + 4, KCore.WeatheredRockBricks, 0);
		this.setBlock(world, i + 4, j + 4, k + 5, KCore.WeatheredRockBricks, 0);
		this.setBlock(world, i + 4, j + 4, k + 6, KCore.WeatheredRockBricks, 0);
		this.setBlock(world, i + 4, j + 4, k + 7, Blocks.WEB, 0);
		this.setBlock(world, i + 4, j + 4, k + 8, Blocks.BOOKSHELF, 0);
		this.setBlock(world, i + 4, j + 4, k + 9, Blocks.BOOKSHELF, 0);
		this.setBlock(world, i + 4, j + 4, k + 10, Blocks.BOOKSHELF, 0);
		this.setBlock(world, i + 4, j + 4, k + 11, Blocks.BOOKSHELF, 0);
		this.setBlock(world, i + 4, j + 4, k + 12, Blocks.BOOKSHELF, 0);
		this.setBlock(world, i + 4, j + 4, k + 13, KCore.WeatheredRockBricks, 0);
		this.setBlock(world, i + 4, j + 4, k + 14, 0, 0);
		this.setBlock(world, i + 4, j + 4, k + 15, 0, 0);
		this.setBlock(world, i + 4, j + 4, k + 16, 0, 0);
		this.setBlock(world, i + 4, j + 4, k + 17, 0, 0);
		this.setBlock(world, i + 4, j + 5, k + 0, 0, 0);
		this.setBlock(world, i + 4, j + 5, k + 1, 0, 0);
		this.setBlock(world, i + 4, j + 5, k + 2, KCore.WeatheredRockBricks, 0);
		this.setBlock(world, i + 4, j + 5, k + 3, KCore.WeatheredRockBricks, 0);
		this.setBlock(world, i + 4, j + 5, k + 4, KCore.WeatheredRockBricks, 0);
		this.setBlock(world, i + 4, j + 5, k + 5, KCore.WeatheredRockBricks, 0);
		this.setBlock(world, i + 4, j + 5, k + 6, KCore.WeatheredRockBricks, 0);
		this.setBlock(world, i + 4, j + 5, k + 7, 0, 0);
		this.setBlock(world, i + 4, j + 5, k + 8, Blocks.BOOKSHELF, 0);
		this.setBlock(world, i + 4, j + 5, k + 9, Blocks.BOOKSHELF, 0);
		this.setBlock(world, i + 4, j + 5, k + 10, Blocks.BOOKSHELF, 0);
		this.setBlock(world, i + 4, j + 5, k + 11, Blocks.BOOKSHELF, 0);
		this.setBlock(world, i + 4, j + 5, k + 12, Blocks.BOOKSHELF, 0);
		this.setBlock(world, i + 4, j + 5, k + 13, KCore.WeatheredRockBricks, 0);
		this.setBlock(world, i + 4, j + 5, k + 14, 0, 0);
		this.setBlock(world, i + 4, j + 5, k + 15, 0, 0);
		this.setBlock(world, i + 4, j + 5, k + 16, 0, 0);
		this.setBlock(world, i + 4, j + 5, k + 17, 0, 0);
		this.setBlock(world, i + 4, j + 6, k + 0, 0, 0);
		this.setBlock(world, i + 4, j + 6, k + 1, 0, 0);
		this.setBlock(world, i + 4, j + 6, k + 2, KCore.WeatheredRockBricks, 0);
		this.setBlock(world, i + 4, j + 6, k + 3, KCore.WeatheredRockBricks, 0);
		this.setBlock(world, i + 4, j + 6, k + 4, KCore.WeatheredRockBricks, 0);
		this.setBlock(world, i + 4, j + 6, k + 5, KCore.WeatheredRockBricks, 0);
		this.setBlock(world, i + 4, j + 6, k + 6, KCore.WeatheredRockBricks, 0);
		this.setBlock(world, i + 4, j + 6, k + 7, 0, 0);
		this.setBlock(world, i + 4, j + 6, k + 8, Blocks.BOOKSHELF, 0);
		this.setBlock(world, i + 4, j + 6, k + 9, Blocks.BOOKSHELF, 0);
		this.setBlock(world, i + 4, j + 6, k + 10, Blocks.BOOKSHELF, 0);
		this.setBlock(world, i + 4, j + 6, k + 11, Blocks.BOOKSHELF, 0);
		this.setBlock(world, i + 4, j + 6, k + 12, Blocks.BOOKSHELF, 0);
		this.setBlock(world, i + 4, j + 6, k + 13, KCore.WeatheredRockBricks, 0);
		this.setBlock(world, i + 4, j + 6, k + 14, 0, 0);
		this.setBlock(world, i + 4, j + 6, k + 15, 0, 0);
		this.setBlock(world, i + 4, j + 6, k + 16, 0, 0);
		this.setBlock(world, i + 4, j + 6, k + 17, 0, 0);
		this.setBlock(world, i + 4, j + 7, k + 0, 0, 0);
		this.setBlock(world, i + 4, j + 7, k + 1, 0, 0);
		this.setBlock(world, i + 4, j + 7, k + 2, 0, 0);
		this.setBlock(world, i + 4, j + 7, k + 3, 0, 0);
		this.setBlock(world, i + 4, j + 7, k + 4, 0, 0);
		this.setBlock(world, i + 4, j + 7, k + 5, 0, 0);
		this.setBlock(world, i + 4, j + 7, k + 6, 0, 0);
		this.setBlock(world, i + 4, j + 7, k + 7, KCore.HardenedWeatheredRockStairs, 2);
		this.setBlock(world, i + 4, j + 7, k + 8, 0, 0);
		this.setBlock(world, i + 4, j + 7, k + 9, 0, 0);
		this.setBlock(world, i + 4, j + 7, k + 10, 0, 0);
		this.setBlock(world, i + 4, j + 7, k + 11, 0, 0);
		this.setBlock(world, i + 4, j + 7, k + 12, KCore.HardenedWeatheredRockStairs, 3);
		this.setBlock(world, i + 4, j + 7, k + 13, 0, 0);
		this.setBlock(world, i + 4, j + 7, k + 14, 0, 0);
		this.setBlock(world, i + 4, j + 7, k + 15, 0, 0);
		this.setBlock(world, i + 4, j + 7, k + 16, 0, 0);
		this.setBlock(world, i + 4, j + 7, k + 17, 0, 0);
		this.setBlock(world, i + 4, j + 8, k + 0, 0, 0);
		this.setBlock(world, i + 4, j + 8, k + 1, 0, 0);
		this.setBlock(world, i + 4, j + 8, k + 2, 0, 0);
		this.setBlock(world, i + 4, j + 8, k + 3, 0, 0);
		this.setBlock(world, i + 4, j + 8, k + 4, 0, 0);
		this.setBlock(world, i + 4, j + 8, k + 5, 0, 0);
		this.setBlock(world, i + 4, j + 8, k + 6, 0, 0);
		this.setBlock(world, i + 4, j + 8, k + 7, 0, 0);
		this.setBlock(world, i + 4, j + 8, k + 8, KCore.HardenedWeatheredRockStairs, 2);
		this.setBlock(world, i + 4, j + 8, k + 9, 0, 0);
		this.setBlock(world, i + 4, j + 8, k + 10, 0, 0);
		this.setBlock(world, i + 4, j + 8, k + 11, KCore.HardenedWeatheredRockStairs, 3);
		this.setBlock(world, i + 4, j + 8, k + 12, 0, 0);
		this.setBlock(world, i + 4, j + 8, k + 13, 0, 0);
		this.setBlock(world, i + 4, j + 8, k + 14, 0, 0);
		this.setBlock(world, i + 4, j + 8, k + 15, 0, 0);
		this.setBlock(world, i + 4, j + 8, k + 16, 0, 0);
		this.setBlock(world, i + 4, j + 8, k + 17, 0, 0);
		this.setBlock(world, i + 4, j + 9, k + 0, 0, 0);
		this.setBlock(world, i + 4, j + 9, k + 1, 0, 0);
		this.setBlock(world, i + 4, j + 9, k + 2, 0, 0);
		this.setBlock(world, i + 4, j + 9, k + 3, 0, 0);
		this.setBlock(world, i + 4, j + 9, k + 4, 0, 0);
		this.setBlock(world, i + 4, j + 9, k + 5, 0, 0);
		this.setBlock(world, i + 4, j + 9, k + 6, 0, 0);
		this.setBlock(world, i + 4, j + 9, k + 7, 0, 0);
		this.setBlock(world, i + 4, j + 9, k + 8, 0, 0);
		this.setBlock(world, i + 4, j + 9, k + 9, KCore.HardenedWeatheredRockStairs, 2);
		this.setBlock(world, i + 4, j + 9, k + 10, KCore.HardenedWeatheredRockStairs, 3);
		this.setBlock(world, i + 4, j + 9, k + 11, 0, 0);
		this.setBlock(world, i + 4, j + 9, k + 12, 0, 0);
		this.setBlock(world, i + 4, j + 9, k + 13, 0, 0);
		this.setBlock(world, i + 4, j + 9, k + 14, 0, 0);
		this.setBlock(world, i + 4, j + 9, k + 15, 0, 0);
		this.setBlock(world, i + 4, j + 9, k + 16, 0, 0);
		this.setBlock(world, i + 4, j + 9, k + 17, 0, 0);
		this.setBlock(world, i + 5, j + 0, k + 0, 0, 0);
		this.setBlock(world, i + 5, j + 0, k + 1, KCore.WeatheredRockBricks, 0);
		this.setBlock(world, i + 5, j + 0, k + 2, KCore.WeatheredRockBricks, 0);
		this.setBlock(world, i + 5, j + 0, k + 3, KCore.WeatheredRockBricks, 0);
		this.setBlock(world, i + 5, j + 0, k + 4, KCore.WeatheredRockBricks, 0);
		this.setBlock(world, i + 5, j + 0, k + 5, KCore.WeatheredRockBricks, 0);
		this.setBlock(world, i + 5, j + 0, k + 6, KCore.WeatheredRockBricks, 0);
		this.setBlock(world, i + 5, j + 0, k + 7, KCore.WeatheredRockBricks, 0);
		this.setBlock(world, i + 5, j + 0, k + 8, KCore.WeatheredRockBricks, 0);
		this.setBlock(world, i + 5, j + 0, k + 9, KCore.WeatheredRockBricks, 0);
		this.setBlock(world, i + 5, j + 0, k + 10, KCore.WeatheredRockBricks, 0);
		this.setBlock(world, i + 5, j + 0, k + 11, KCore.WeatheredRockBricks, 0);
		this.setBlock(world, i + 5, j + 0, k + 12, KCore.WeatheredRockBricks, 0);
		this.setBlock(world, i + 5, j + 0, k + 13, KCore.WeatheredRockBricks, 0);
		this.setBlock(world, i + 5, j + 0, k + 14, KCore.WeatheredRockBricks, 0);
		this.setBlock(world, i + 5, j + 0, k + 15, KCore.WeatheredRockBricks, 0);
		this.setBlock(world, i + 5, j + 0, k + 16, KCore.WeatheredRockBricks, 0);
		this.setBlock(world, i + 5, j + 0, k + 17, KCore.WeatheredRockBricks, 0);
		this.setBlock(world, i + 5, j + 1, k + 0, 0, 0);
		this.setBlock(world, i + 5, j + 1, k + 1, KCore.WeatheredRockBricks, 0);
		this.setBlock(world, i + 5, j + 1, k + 2, 0, 0);
		this.setBlock(world, i + 5, j + 1, k + 3, 0, 0);
		this.setBlock(world, i + 5, j + 1, k + 4, 0, 0);
		this.setBlock(world, i + 5, j + 1, k + 5, 0, 0);
		this.setBlock(world, i + 5, j + 1, k + 6, KCore.WeatheredRockBricks, 0);
		this.setBlock(world, i + 5, j + 1, k + 7, Blocks.BOOKSHELF, 0);
		this.setBlock(world, i + 5, j + 1, k + 8, Blocks.BOOKSHELF, 0);
		this.setBlock(world, i + 5, j + 1, k + 9, Blocks.BOOKSHELF, 0);
		this.setBlock(world, i + 5, j + 1, k + 10, Blocks.BOOKSHELF, 0);
		this.setBlock(world, i + 5, j + 1, k + 11, Blocks.BOOKSHELF, 0);
		this.setBlock(world, i + 5, j + 1, k + 12, Blocks.BOOKSHELF, 0);
		this.setBlock(world, i + 5, j + 1, k + 13, KCore.WeatheredRockBricks, 0);
		this.setBlock(world, i + 5, j + 1, k + 14, KCore.WeatheredRockBricks, 0);
		this.setBlock(world, i + 5, j + 1, k + 15, KCore.WeatheredRockBricks, 0);
		this.setBlock(world, i + 5, j + 1, k + 16, KCore.WeatheredRockBricks, 0);
		this.setBlock(world, i + 5, j + 1, k + 17, KCore.WeatheredRockBricks, 0);
		this.setBlock(world, i + 5, j + 2, k + 0, 0, 0);
		this.setBlock(world, i + 5, j + 2, k + 1, KCore.WeatheredRockBricks, 0);
		this.setBlock(world, i + 5, j + 2, k + 2, 0, 0);
		this.setBlock(world, i + 5, j + 2, k + 3, 0, 0);
		this.setBlock(world, i + 5, j + 2, k + 4, 0, 0);
		this.setBlock(world, i + 5, j + 2, k + 5, 0, 0);
		this.setBlock(world, i + 5, j + 2, k + 6, KCore.WeatheredRockBricks, 0);
		this.setBlock(world, i + 5, j + 2, k + 7, Blocks.BOOKSHELF, 0);
		this.setBlock(world, i + 5, j + 2, k + 8, Blocks.BOOKSHELF, 0);
		this.setBlock(world, i + 5, j + 2, k + 9, Blocks.BOOKSHELF, 0);
		this.setBlock(world, i + 5, j + 2, k + 10, Blocks.BOOKSHELF, 0);
		this.setBlock(world, i + 5, j + 2, k + 11, Blocks.BOOKSHELF, 0);
		this.setBlock(world, i + 5, j + 2, k + 12, Blocks.BOOKSHELF, 0);
		this.setBlock(world, i + 5, j + 2, k + 13, KCore.WeatheredRockBricks, 0);
		this.setBlock(world, i + 5, j + 2, k + 14, KCore.WeatheredRockBricks, 0);
		this.setBlock(world, i + 5, j + 2, k + 15, KCore.WeatheredRockBricks, 0);
		this.setBlock(world, i + 5, j + 2, k + 16, KCore.WeatheredRockBricks, 0);
		this.setBlock(world, i + 5, j + 2, k + 17, KCore.WeatheredRockBricks, 0);
		this.setBlock(world, i + 5, j + 3, k + 0, 0, 0);
		this.setBlock(world, i + 5, j + 3, k + 1, KCore.WeatheredRockBricks, 0);
		this.setBlock(world, i + 5, j + 3, k + 2, 0, 0);
		this.setBlock(world, i + 5, j + 3, k + 3, 0, 0);
		this.setBlock(world, i + 5, j + 3, k + 4, 0, 0);
		this.setBlock(world, i + 5, j + 3, k + 5, 0, 0);
		this.setBlock(world, i + 5, j + 3, k + 6, KCore.WeatheredRockBricks, 0);
		this.setBlock(world, i + 5, j + 3, k + 7, KCore.WeatheredRockBricks, 0);
		this.setBlock(world, i + 5, j + 3, k + 8, KCore.WeatheredRockBricks, 0);
		this.setBlock(world, i + 5, j + 3, k + 9, KCore.WeatheredRockBricks, 0);
		this.setBlock(world, i + 5, j + 3, k + 10, KCore.WeatheredRockBricks, 0);
		this.setBlock(world, i + 5, j + 3, k + 11, KCore.WeatheredRockBricks, 0);
		this.setBlock(world, i + 5, j + 3, k + 12, KCore.WeatheredRockBricks, 0);
		this.setBlock(world, i + 5, j + 3, k + 13, KCore.WeatheredRockBricks, 0);
		this.setBlock(world, i + 5, j + 3, k + 14, KCore.WeatheredRockBricks, 0);
		this.setBlock(world, i + 5, j + 3, k + 15, KCore.WeatheredRockBricks, 0);
		this.setBlock(world, i + 5, j + 3, k + 16, KCore.WeatheredRockBricks, 0);
		this.setBlock(world, i + 5, j + 3, k + 17, KCore.WeatheredRockBricks, 0);
		this.setBlock(world, i + 5, j + 4, k + 0, 0, 0);
		this.setBlock(world, i + 5, j + 4, k + 1, 0, 0);
		this.setBlock(world, i + 5, j + 4, k + 2, KCore.HardenedWeatheredRockStairs, 2);
		this.setBlock(world, i + 5, j + 4, k + 3, KCore.HardenedWeatheredRockStairs, 0);
		this.setBlock(world, i + 5, j + 4, k + 4, KCore.HardenedWeatheredRockStairs, 0);
		this.setBlock(world, i + 5, j + 4, k + 5, KCore.HardenedWeatheredRockStairs, 0);
		this.setBlock(world, i + 5, j + 4, k + 6, KCore.WeatheredRockBricks, 0);
		this.setBlock(world, i + 5, j + 4, k + 7, Blocks.WEB, 0);
		this.setBlock(world, i + 5, j + 4, k + 8, 0, 0);
		this.setBlock(world, i + 5, j + 4, k + 9, 0, 0);
		this.setBlock(world, i + 5, j + 4, k + 10, 0, 0);
		this.setBlock(world, i + 5, j + 4, k + 11, 0, 0);
		this.setBlock(world, i + 5, j + 4, k + 12, Blocks.WEB, 0);
		this.setBlock(world, i + 5, j + 4, k + 13, KCore.WeatheredRockBricks, 0);
		this.setBlock(world, i + 5, j + 4, k + 14, KCore.WeatheredRockBricks, 0);
		this.setBlock(world, i + 5, j + 4, k + 15, KCore.WeatheredRockBricks, 0);
		this.setBlock(world, i + 5, j + 4, k + 16, KCore.WeatheredRockBricks, 0);
		this.setBlock(world, i + 5, j + 4, k + 17, KCore.WeatheredRockBricks, 0);
		this.setBlock(world, i + 5, j + 5, k + 0, 0, 0);
		this.setBlock(world, i + 5, j + 5, k + 1, 0, 0);
		this.setBlock(world, i + 5, j + 5, k + 2, 0, 0);
		this.setBlock(world, i + 5, j + 5, k + 3, 0, 0);
		this.setBlock(world, i + 5, j + 5, k + 4, 0, 0);
		this.setBlock(world, i + 5, j + 5, k + 5, 0, 0);
		this.setBlock(world, i + 5, j + 5, k + 6, KCore.WeatheredRockBricks, 0);
		this.setBlock(world, i + 5, j + 5, k + 7, Blocks.WEB, 0);
		this.setBlock(world, i + 5, j + 5, k + 8, 0, 0);
		this.setBlock(world, i + 5, j + 5, k + 9, 0, 0);
		this.setBlock(world, i + 5, j + 5, k + 10, 0, 0);
		this.setBlock(world, i + 5, j + 5, k + 11, 0, 0);
		this.setBlock(world, i + 5, j + 5, k + 12, Blocks.WEB, 0);
		this.setBlock(world, i + 5, j + 5, k + 13, KCore.WeatheredRockBricks, 0);
		this.setBlock(world, i + 5, j + 5, k + 14, KCore.WeatheredRockBricks, 0);
		this.setBlock(world, i + 5, j + 5, k + 15, KCore.WeatheredRockBricks, 0);
		this.setBlock(world, i + 5, j + 5, k + 16, KCore.WeatheredRockBricks, 0);
		this.setBlock(world, i + 5, j + 5, k + 17, KCore.WeatheredRockBricks, 0);
		this.setBlock(world, i + 5, j + 6, k + 0, 0, 0);
		this.setBlock(world, i + 5, j + 6, k + 1, 0, 0);
		this.setBlock(world, i + 5, j + 6, k + 2, 0, 0);
		this.setBlock(world, i + 5, j + 6, k + 3, 0, 0);
		this.setBlock(world, i + 5, j + 6, k + 4, 0, 0);
		this.setBlock(world, i + 5, j + 6, k + 5, 0, 0);
		this.setBlock(world, i + 5, j + 6, k + 6, KCore.WeatheredRockBricks, 0);
		this.setBlock(world, i + 5, j + 6, k + 7, Blocks.WEB, 0);
		this.setBlock(world, i + 5, j + 6, k + 8, 0, 0);
		this.setBlock(world, i + 5, j + 6, k + 9, 0, 0);
		this.setBlock(world, i + 5, j + 6, k + 10, 0, 0);
		this.setBlock(world, i + 5, j + 6, k + 11, 0, 0);
		this.setBlock(world, i + 5, j + 6, k + 12, Blocks.WEB, 0);
		this.setBlock(world, i + 5, j + 6, k + 13, KCore.WeatheredRockBricks, 0);
		this.setBlock(world, i + 5, j + 6, k + 14, KCore.WeatheredRockBricks, 0);
		this.setBlock(world, i + 5, j + 6, k + 15, KCore.WeatheredRockBricks, 0);
		this.setBlock(world, i + 5, j + 6, k + 16, KCore.WeatheredRockBricks, 0);
		this.setBlock(world, i + 5, j + 6, k + 17, KCore.WeatheredRockBricks, 0);
		this.setBlock(world, i + 5, j + 7, k + 0, 0, 0);
		this.setBlock(world, i + 5, j + 7, k + 1, 0, 0);
		this.setBlock(world, i + 5, j + 7, k + 2, 0, 0);
		this.setBlock(world, i + 5, j + 7, k + 3, 0, 0);
		this.setBlock(world, i + 5, j + 7, k + 4, 0, 0);
		this.setBlock(world, i + 5, j + 7, k + 5, 0, 0);
		this.setBlock(world, i + 5, j + 7, k + 6, 0, 0);
		this.setBlock(world, i + 5, j + 7, k + 7, KCore.HardenedWeatheredRockStairs, 2);
		this.setBlock(world, i + 5, j + 7, k + 8, 0, 0);
		this.setBlock(world, i + 5, j + 7, k + 9, 0, 0);
		this.setBlock(world, i + 5, j + 7, k + 10, 0, 0);
		this.setBlock(world, i + 5, j + 7, k + 11, 0, 0);
		this.setBlock(world, i + 5, j + 7, k + 12, KCore.HardenedWeatheredRockStairs, 3);
		this.setBlock(world, i + 5, j + 7, k + 13, 0, 0);
		this.setBlock(world, i + 5, j + 7, k + 14, 0, 0);
		this.setBlock(world, i + 5, j + 7, k + 15, 0, 0);
		this.setBlock(world, i + 5, j + 7, k + 16, 0, 0);
		this.setBlock(world, i + 5, j + 7, k + 17, 0, 0);
		this.setBlock(world, i + 5, j + 8, k + 0, 0, 0);
		this.setBlock(world, i + 5, j + 8, k + 1, 0, 0);
		this.setBlock(world, i + 5, j + 8, k + 2, 0, 0);
		this.setBlock(world, i + 5, j + 8, k + 3, 0, 0);
		this.setBlock(world, i + 5, j + 8, k + 4, 0, 0);
		this.setBlock(world, i + 5, j + 8, k + 5, 0, 0);
		this.setBlock(world, i + 5, j + 8, k + 6, 0, 0);
		this.setBlock(world, i + 5, j + 8, k + 7, 0, 0);
		this.setBlock(world, i + 5, j + 8, k + 8, KCore.HardenedWeatheredRockStairs, 2);
		this.setBlock(world, i + 5, j + 8, k + 9, 0, 0);
		this.setBlock(world, i + 5, j + 8, k + 10, 0, 0);
		this.setBlock(world, i + 5, j + 8, k + 11, KCore.HardenedWeatheredRockStairs, 3);
		this.setBlock(world, i + 5, j + 8, k + 12, 0, 0);
		this.setBlock(world, i + 5, j + 8, k + 13, 0, 0);
		this.setBlock(world, i + 5, j + 8, k + 14, 0, 0);
		this.setBlock(world, i + 5, j + 8, k + 15, 0, 0);
		this.setBlock(world, i + 5, j + 8, k + 16, 0, 0);
		this.setBlock(world, i + 5, j + 8, k + 17, 0, 0);
		this.setBlock(world, i + 5, j + 9, k + 0, 0, 0);
		this.setBlock(world, i + 5, j + 9, k + 1, 0, 0);
		this.setBlock(world, i + 5, j + 9, k + 2, 0, 0);
		this.setBlock(world, i + 5, j + 9, k + 3, 0, 0);
		this.setBlock(world, i + 5, j + 9, k + 4, 0, 0);
		this.setBlock(world, i + 5, j + 9, k + 5, 0, 0);
		this.setBlock(world, i + 5, j + 9, k + 6, 0, 0);
		this.setBlock(world, i + 5, j + 9, k + 7, 0, 0);
		this.setBlock(world, i + 5, j + 9, k + 8, 0, 0);
		this.setBlock(world, i + 5, j + 9, k + 9, KCore.HardenedWeatheredRockStairs, 2);
		this.setBlock(world, i + 5, j + 9, k + 10, KCore.HardenedWeatheredRockStairs, 3);
		this.setBlock(world, i + 5, j + 9, k + 11, 0, 0);
		this.setBlock(world, i + 5, j + 9, k + 12, 0, 0);
		this.setBlock(world, i + 5, j + 9, k + 13, 0, 0);
		this.setBlock(world, i + 5, j + 9, k + 14, 0, 0);
		this.setBlock(world, i + 5, j + 9, k + 15, 0, 0);
		this.setBlock(world, i + 5, j + 9, k + 16, 0, 0);
		this.setBlock(world, i + 5, j + 9, k + 17, 0, 0);
		this.setBlock(world, i + 6, j + 0, k + 0, 0, 0);
		this.setBlock(world, i + 6, j + 0, k + 1, KCore.WeatheredRockBricks, 0);
		this.setBlock(world, i + 6, j + 0, k + 2, KCore.WeatheredRockBricks, 0);
		this.setBlock(world, i + 6, j + 0, k + 3, KCore.WeatheredRockBricks, 0);
		this.setBlock(world, i + 6, j + 0, k + 4, KCore.WeatheredRockBricks, 0);
		this.setBlock(world, i + 6, j + 0, k + 5, KCore.WeatheredRockBricks, 0);
		this.setBlock(world, i + 6, j + 0, k + 6, KCore.WeatheredRockBricks, 0);
		this.setBlock(world, i + 6, j + 0, k + 7, 0, 0);
		this.setBlock(world, i + 6, j + 0, k + 8, 0, 0);
		this.setBlock(world, i + 6, j + 0, k + 9, 0, 0);
		this.setBlock(world, i + 6, j + 0, k + 10, 0, 0);
		this.setBlock(world, i + 6, j + 0, k + 11, 0, 0);
		this.setBlock(world, i + 6, j + 0, k + 12, 0, 0);
		this.setBlock(world, i + 6, j + 0, k + 13, KCore.WeatheredRockBricks, 0);
		this.setBlock(world, i + 6, j + 0, k + 14, KCore.WeatheredRockBricks, 0);
		this.setBlock(world, i + 6, j + 0, k + 15, KCore.WeatheredRockBricks, 0);
		this.setBlock(world, i + 6, j + 0, k + 16, KCore.WeatheredRockBricks, 0);
		this.setBlock(world, i + 6, j + 0, k + 17, KCore.WeatheredRockBricks, 0);
		this.setBlock(world, i + 6, j + 1, k + 0, 0, 0);
		this.setBlock(world, i + 6, j + 1, k + 1, KCore.WeatheredRockBricks, 0);
		this.setBlock(world, i + 6, j + 1, k + 2, 0, 0);
		this.setBlock(world, i + 6, j + 1, k + 3, 0, 0);
		this.setBlock(world, i + 6, j + 1, k + 4, 0, 0);
		this.setBlock(world, i + 6, j + 1, k + 5, 0, 0);
		this.setBlock(world, i + 6, j + 1, k + 6, KCore.WeatheredRockBricks, 0);
		this.setBlock(world, i + 6, j + 1, k + 7, KCore.WeatheredRockBricks, 0);
		this.setBlock(world, i + 6, j + 1, k + 8, KCore.WeatheredRockBricks, 0);
		this.setBlock(world, i + 6, j + 1, k + 9, KCore.WeatheredRockBricks, 0);
		this.setBlock(world, i + 6, j + 1, k + 10, KCore.WeatheredRockBricks, 0);
		this.setBlock(world, i + 6, j + 1, k + 11, KCore.WeatheredRockBricks, 0);
		this.setBlock(world, i + 6, j + 1, k + 12, KCore.WeatheredRockBricks, 0);
		this.setBlock(world, i + 6, j + 1, k + 13, 0, 0);
		this.setBlock(world, i + 6, j + 1, k + 14, 0, 0);
		this.setBlock(world, i + 6, j + 1, k + 15, 0, 0);
		this.setBlock(world, i + 6, j + 1, k + 16, Blocks.WEB, 0);
		this.setBlock(world, i + 6, j + 1, k + 17, KCore.WeatheredRockBricks, 0);
		this.setBlock(world, i + 6, j + 2, k + 0, 0, 0);
		this.setBlock(world, i + 6, j + 2, k + 1, KCore.WeatheredRockBricks, 0);
		this.setBlock(world, i + 6, j + 2, k + 2, 0, 0);
		this.setBlock(world, i + 6, j + 2, k + 3, 0, 0);
		this.setBlock(world, i + 6, j + 2, k + 4, 0, 0);
		this.setBlock(world, i + 6, j + 2, k + 5, 0, 0);
		this.setBlock(world, i + 6, j + 2, k + 6, KCore.WeatheredRockBricks, 0);
		this.setBlock(world, i + 6, j + 2, k + 7, KCore.WeatheredRockBricks, 0);
		this.setBlock(world, i + 6, j + 2, k + 8, KCore.WeatheredRockBricks, 0);
		this.setBlock(world, i + 6, j + 2, k + 9, KCore.WeatheredRockBricks, 0);
		this.setBlock(world, i + 6, j + 2, k + 10, KCore.WeatheredRockBricks, 0);
		this.setBlock(world, i + 6, j + 2, k + 11, KCore.WeatheredRockBricks, 0);
		this.setBlock(world, i + 6, j + 2, k + 12, KCore.WeatheredRockBricks, 0);
		this.setBlock(world, i + 6, j + 2, k + 13, 0, 0);
		this.setBlock(world, i + 6, j + 2, k + 14, 0, 0);
		this.setBlock(world, i + 6, j + 2, k + 15, 0, 0);
		this.setBlock(world, i + 6, j + 2, k + 16, Blocks.BOOKSHELF, 0);
		this.setBlock(world, i + 6, j + 2, k + 17, KCore.WeatheredRockBricks, 0);
		this.setBlock(world, i + 6, j + 3, k + 0, 0, 0);
		this.setBlock(world, i + 6, j + 3, k + 1, KCore.WeatheredRockBricks, 0);
		this.setBlock(world, i + 6, j + 3, k + 2, 0, 0);
		this.setBlock(world, i + 6, j + 3, k + 3, 0, 0);
		this.setBlock(world, i + 6, j + 3, k + 4, 0, 0);
		this.setBlock(world, i + 6, j + 3, k + 5, 0, 0);
		this.setBlock(world, i + 6, j + 3, k + 6, KCore.WeatheredRockBricks, 0);
		this.setBlock(world, i + 6, j + 3, k + 7, KCore.WeatheredRockBricks, 0);
		this.setBlock(world, i + 6, j + 3, k + 8, KCore.WeatheredRockBricks, 0);
		this.setBlock(world, i + 6, j + 3, k + 9, KCore.WeatheredRockBricks, 0);
		this.setBlock(world, i + 6, j + 3, k + 10, KCore.WeatheredRockBricks, 0);
		this.setBlock(world, i + 6, j + 3, k + 11, KCore.WeatheredRockBricks, 0);
		this.setBlock(world, i + 6, j + 3, k + 12, KCore.WeatheredRockBricks, 0);
		this.setBlock(world, i + 6, j + 3, k + 13, KCore.WeatheredRockBricks, 0);
		this.setBlock(world, i + 6, j + 3, k + 14, KCore.WeatheredRockBricks, 0);
		this.setBlock(world, i + 6, j + 3, k + 15, KCore.WeatheredRockBricks, 0);
		this.setBlock(world, i + 6, j + 3, k + 16, KCore.WeatheredRockBricks, 0);
		this.setBlock(world, i + 6, j + 3, k + 17, KCore.WeatheredRockBricks, 0);
		this.setBlock(world, i + 6, j + 4, k + 0, 0, 0);
		this.setBlock(world, i + 6, j + 4, k + 1, 0, 0);
		this.setBlock(world, i + 6, j + 4, k + 2, KCore.HardenedWeatheredRockStairs, 2);
		this.setBlock(world, i + 6, j + 4, k + 3, 0, 0);
		this.setBlock(world, i + 6, j + 4, k + 4, 0, 0);
		this.setBlock(world, i + 6, j + 4, k + 5, KCore.HardenedWeatheredRockStairs, 3);
		this.setBlock(world, i + 6, j + 4, k + 6, KCore.WeatheredRockBricks, 0);
		this.setBlock(world, i + 6, j + 4, k + 7, 0, 0);
		this.setBlock(world, i + 6, j + 4, k + 8, Blocks.BOOKSHELF, 0);
		this.setBlock(world, i + 6, j + 4, k + 9, 0, 0);
		this.setBlock(world, i + 6, j + 4, k + 10, Blocks.BOOKSHELF, 0);
		this.setBlock(world, i + 6, j + 4, k + 11, 0, 0);
		this.setBlock(world, i + 6, j + 4, k + 12, Blocks.BOOKSHELF, 0);
		this.setBlock(world, i + 6, j + 4, k + 13, Blocks.BOOKSHELF, 0);
		this.setBlock(world, i + 6, j + 4, k + 14, Blocks.BOOKSHELF, 0);
		this.setBlock(world, i + 6, j + 4, k + 15, Blocks.BOOKSHELF, 0);
		this.setBlock(world, i + 6, j + 4, k + 16, Blocks.BOOKSHELF, 0);
		this.setBlock(world, i + 6, j + 4, k + 17, KCore.WeatheredRockBricks, 0);
		this.setBlock(world, i + 6, j + 5, k + 0, 0, 0);
		this.setBlock(world, i + 6, j + 5, k + 1, 0, 0);
		this.setBlock(world, i + 6, j + 5, k + 2, 0, 0);
		this.setBlock(world, i + 6, j + 5, k + 3, KCore.HardenedWeatheredRockStairs, 2);
		this.setBlock(world, i + 6, j + 5, k + 4, KCore.HardenedWeatheredRockStairs, 0);
		this.setBlock(world, i + 6, j + 5, k + 5, 0, 0);
		this.setBlock(world, i + 6, j + 5, k + 6, KCore.WeatheredRockBricks, 0);
		this.setBlock(world, i + 6, j + 5, k + 7, 0, 0);
		this.setBlock(world, i + 6, j + 5, k + 8, Blocks.BOOKSHELF, 0);
		this.setBlock(world, i + 6, j + 5, k + 9, 0, 0);
		this.setBlock(world, i + 6, j + 5, k + 10, Blocks.BOOKSHELF, 0);
		this.setBlock(world, i + 6, j + 5, k + 11, 0, 0);
		this.setBlock(world, i + 6, j + 5, k + 12, Blocks.BOOKSHELF, 0);
		this.setBlock(world, i + 6, j + 5, k + 13, Blocks.BOOKSHELF, 0);
		this.setBlock(world, i + 6, j + 5, k + 14, Blocks.BOOKSHELF, 0);
		this.setBlock(world, i + 6, j + 5, k + 15, Blocks.BOOKSHELF, 0);
		this.setBlock(world, i + 6, j + 5, k + 16, Blocks.BOOKSHELF, 0);
		this.setBlock(world, i + 6, j + 5, k + 17, KCore.WeatheredRockBricks, 0);
		this.setBlock(world, i + 6, j + 6, k + 0, 0, 0);
		this.setBlock(world, i + 6, j + 6, k + 1, 0, 0);
		this.setBlock(world, i + 6, j + 6, k + 2, 0, 0);
		this.setBlock(world, i + 6, j + 6, k + 3, 0, 0);
		this.setBlock(world, i + 6, j + 6, k + 4, 0, 0);
		this.setBlock(world, i + 6, j + 6, k + 5, 0, 0);
		this.setBlock(world, i + 6, j + 6, k + 6, KCore.WeatheredRockBricks, 0);
		this.setBlock(world, i + 6, j + 6, k + 7, 0, 0);
		this.setBlock(world, i + 6, j + 6, k + 8, Blocks.BOOKSHELF, 0);
		this.setBlock(world, i + 6, j + 6, k + 9, Blocks.WEB, 0);
		this.setBlock(world, i + 6, j + 6, k + 10, Blocks.BOOKSHELF, 0);
		this.setBlock(world, i + 6, j + 6, k + 11, 0, 0);
		this.setBlock(world, i + 6, j + 6, k + 12, Blocks.BOOKSHELF, 0);
		this.setBlock(world, i + 6, j + 6, k + 13, Blocks.BOOKSHELF, 0);
		this.setBlock(world, i + 6, j + 6, k + 14, Blocks.BOOKSHELF, 0);
		this.setBlock(world, i + 6, j + 6, k + 15, Blocks.BOOKSHELF, 0);
		this.setBlock(world, i + 6, j + 6, k + 16, Blocks.BOOKSHELF, 0);
		this.setBlock(world, i + 6, j + 6, k + 17, KCore.WeatheredRockBricks, 0);
		this.setBlock(world, i + 6, j + 7, k + 0, 0, 0);
		this.setBlock(world, i + 6, j + 7, k + 1, 0, 0);
		this.setBlock(world, i + 6, j + 7, k + 2, 0, 0);
		this.setBlock(world, i + 6, j + 7, k + 3, 0, 0);
		this.setBlock(world, i + 6, j + 7, k + 4, 0, 0);
		this.setBlock(world, i + 6, j + 7, k + 5, 0, 0);
		this.setBlock(world, i + 6, j + 7, k + 6, 0, 0);
		this.setBlock(world, i + 6, j + 7, k + 7, KCore.HardenedWeatheredRockStairs, 2);
		this.setBlock(world, i + 6, j + 7, k + 8, 0, 0);
		this.setBlock(world, i + 6, j + 7, k + 9, 0, 0);
		this.setBlock(world, i + 6, j + 7, k + 10, 0, 0);
		this.setBlock(world, i + 6, j + 7, k + 11, 0, 0);
		this.setBlock(world, i + 6, j + 7, k + 12, KCore.HardenedWeatheredRockStairs, 0);
		this.setBlock(world, i + 6, j + 7, k + 13, KCore.HardenedWeatheredRockStairs, 0);
		this.setBlock(world, i + 6, j + 7, k + 14, KCore.HardenedWeatheredRockStairs, 0);
		this.setBlock(world, i + 6, j + 7, k + 15, KCore.HardenedWeatheredRockStairs, 0);
		this.setBlock(world, i + 6, j + 7, k + 16, KCore.HardenedWeatheredRockStairs, 3);
		this.setBlock(world, i + 6, j + 7, k + 17, 0, 0);
		this.setBlock(world, i + 6, j + 8, k + 0, 0, 0);
		this.setBlock(world, i + 6, j + 8, k + 1, 0, 0);
		this.setBlock(world, i + 6, j + 8, k + 2, 0, 0);
		this.setBlock(world, i + 6, j + 8, k + 3, 0, 0);
		this.setBlock(world, i + 6, j + 8, k + 4, 0, 0);
		this.setBlock(world, i + 6, j + 8, k + 5, 0, 0);
		this.setBlock(world, i + 6, j + 8, k + 6, 0, 0);
		this.setBlock(world, i + 6, j + 8, k + 7, 0, 0);
		this.setBlock(world, i + 6, j + 8, k + 8, KCore.HardenedWeatheredRockStairs, 2);
		this.setBlock(world, i + 6, j + 8, k + 9, 0, 0);
		this.setBlock(world, i + 6, j + 8, k + 10, 0, 0);
		this.setBlock(world, i + 6, j + 8, k + 11, KCore.HardenedWeatheredRockStairs, 3);
		this.setBlock(world, i + 6, j + 8, k + 12, 0, 0);
		this.setBlock(world, i + 6, j + 8, k + 13, 0, 0);
		this.setBlock(world, i + 6, j + 8, k + 14, 0, 0);
		this.setBlock(world, i + 6, j + 8, k + 15, 0, 0);
		this.setBlock(world, i + 6, j + 8, k + 16, 0, 0);
		this.setBlock(world, i + 6, j + 8, k + 17, 0, 0);
		this.setBlock(world, i + 6, j + 9, k + 0, 0, 0);
		this.setBlock(world, i + 6, j + 9, k + 1, 0, 0);
		this.setBlock(world, i + 6, j + 9, k + 2, 0, 0);
		this.setBlock(world, i + 6, j + 9, k + 3, 0, 0);
		this.setBlock(world, i + 6, j + 9, k + 4, 0, 0);
		this.setBlock(world, i + 6, j + 9, k + 5, 0, 0);
		this.setBlock(world, i + 6, j + 9, k + 6, 0, 0);
		this.setBlock(world, i + 6, j + 9, k + 7, 0, 0);
		this.setBlock(world, i + 6, j + 9, k + 8, 0, 0);
		this.setBlock(world, i + 6, j + 9, k + 9, KCore.HardenedWeatheredRockStairs, 2);
		this.setBlock(world, i + 6, j + 9, k + 10, KCore.HardenedWeatheredRockStairs, 3);
		this.setBlock(world, i + 6, j + 9, k + 11, 0, 0);
		this.setBlock(world, i + 6, j + 9, k + 12, 0, 0);
		this.setBlock(world, i + 6, j + 9, k + 13, 0, 0);
		this.setBlock(world, i + 6, j + 9, k + 14, 0, 0);
		this.setBlock(world, i + 6, j + 9, k + 15, 0, 0);
		this.setBlock(world, i + 6, j + 9, k + 16, 0, 0);
		this.setBlock(world, i + 6, j + 9, k + 17, 0, 0);
		this.setBlock(world, i + 7, j + 0, k + 0, KCore.HardenedWeatheredRockStairs, 2);
		this.setBlock(world, i + 7, j + 0, k + 1, KCore.WeatheredRockBricks, 0);
		this.setBlock(world, i + 7, j + 0, k + 2, KCore.WeatheredRockBricks, 0);
		this.setBlock(world, i + 7, j + 0, k + 3, KCore.WeatheredRockBricks, 0);
		this.setBlock(world, i + 7, j + 0, k + 4, KCore.WeatheredRockBricks, 0);
		this.setBlock(world, i + 7, j + 0, k + 5, KCore.WeatheredRockBricks, 0);
		this.setBlock(world, i + 7, j + 0, k + 6, KCore.WeatheredRockBricks, 0);
		this.setBlock(world, i + 7, j + 0, k + 7, KCore.WeatheredRockBricks, 0);
		this.setBlock(world, i + 7, j + 0, k + 8, KCore.WeatheredRockBricks, 0);
		this.setBlock(world, i + 7, j + 0, k + 9, KCore.WeatheredRockBricks, 0);
		this.setBlock(world, i + 7, j + 0, k + 10, KCore.WeatheredRockBricks, 0);
		this.setBlock(world, i + 7, j + 0, k + 11, KCore.WeatheredRockBricks, 0);
		this.setBlock(world, i + 7, j + 0, k + 12, KCore.WeatheredRockBricks, 0);
		this.setBlock(world, i + 7, j + 0, k + 13, KCore.WeatheredRockBricks, 0);
		this.setBlock(world, i + 7, j + 0, k + 14, KCore.WeatheredRockBricks, 0);
		this.setBlock(world, i + 7, j + 0, k + 15, KCore.WeatheredRockBricks, 0);
		this.setBlock(world, i + 7, j + 0, k + 16, KCore.WeatheredRockBricks, 0);
		this.setBlock(world, i + 7, j + 0, k + 17, KCore.WeatheredRockBricks, 0);
		this.setBlock(world, i + 7, j + 1, k + 0, 0, 0);
		this.setBlock(world, i + 7, j + 1, k + 1, 0, 0);
		this.setBlock(world, i + 7, j + 1, k + 2, 0, 0);
		this.setBlock(world, i + 7, j + 1, k + 3, 0, 0);
		this.setBlock(world, i + 7, j + 1, k + 4, 0, 0);
		this.setBlock(world, i + 7, j + 1, k + 5, 0, 0);
		this.setBlock(world, i + 7, j + 1, k + 6, 0, 0);
		this.setBlock(world, i + 7, j + 1, k + 7, 0, 0);
		this.setBlock(world, i + 7, j + 1, k + 8, 0, 0);
		this.setBlock(world, i + 7, j + 1, k + 9, Blocks.BOOKSHELF, 0);
		this.setBlock(world, i + 7, j + 1, k + 10, 0, 0);
		this.setBlock(world, i + 7, j + 1, k + 11, 0, 0);
		this.setBlock(world, i + 7, j + 1, k + 12, 0, 0);
		this.setBlock(world, i + 7, j + 1, k + 13, 0, 0);
		this.setBlock(world, i + 7, j + 1, k + 14, KCore.HardenedWeatheredRockStairs, 2);
		this.setBlock(world, i + 7, j + 1, k + 15, KCore.WeatheredRockBricks, 0);
		this.setBlock(world, i + 7, j + 1, k + 16, KCore.WeatheredRockBricks, 0);
		this.setBlock(world, i + 7, j + 1, k + 17, KCore.WeatheredRockBricks, 0);
		this.setBlock(world, i + 7, j + 2, k + 0, 0, 0);
		this.setBlock(world, i + 7, j + 2, k + 1, 0, 0);
		this.setBlock(world, i + 7, j + 2, k + 2, 0, 0);
		this.setBlock(world, i + 7, j + 2, k + 3, 0, 0);
		this.setBlock(world, i + 7, j + 2, k + 4, 0, 0);
		this.setBlock(world, i + 7, j + 2, k + 5, 0, 0);
		this.setBlock(world, i + 7, j + 2, k + 6, 0, 0);
		this.setBlock(world, i + 7, j + 2, k + 7, 0, 0);
		this.setBlock(world, i + 7, j + 2, k + 8, 0, 0);
		this.setBlock(world, i + 7, j + 2, k + 9, Blocks.WEB, 0);
		this.setBlock(world, i + 7, j + 2, k + 10, 0, 0);
		this.setBlock(world, i + 7, j + 2, k + 11, 0, 0);
		this.setBlock(world, i + 7, j + 2, k + 12, 0, 0);
		this.setBlock(world, i + 7, j + 2, k + 13, 0, 0);
		this.setBlock(world, i + 7, j + 2, k + 14, 0, 0);
		this.setBlock(world, i + 7, j + 2, k + 15, KCore.HardenedWeatheredRockStairs, 2);
		this.setBlock(world, i + 7, j + 2, k + 16, KCore.WeatheredRockBricks, 0);
		this.setBlock(world, i + 7, j + 2, k + 17, KCore.WeatheredRockBricks, 0);
		this.setBlock(world, i + 7, j + 3, k + 0, 0, 0);
		this.setBlock(world, i + 7, j + 3, k + 1, KCore.HardenedWeatheredRockStairs, 2);
		this.setBlock(world, i + 7, j + 3, k + 2, 0, 0);
		this.setBlock(world, i + 7, j + 3, k + 3, 0, 0);
		this.setBlock(world, i + 7, j + 3, k + 4, 0, 0);
		this.setBlock(world, i + 7, j + 3, k + 5, 0, 0);
		this.setBlock(world, i + 7, j + 3, k + 6, KCore.HardenedWeatheredRockStairs, 3);
		this.setBlock(world, i + 7, j + 3, k + 7, KCore.WeatheredRockBricks, 0);
		this.setBlock(world, i + 7, j + 3, k + 8, KCore.WeatheredRockBricks, 0);
		this.setBlock(world, i + 7, j + 3, k + 9, KCore.WeatheredRockBricks, 0);
		this.setBlock(world, i + 7, j + 3, k + 10, KCore.WeatheredRockBricks, 0);
		this.setBlock(world, i + 7, j + 3, k + 11, KCore.WeatheredRockBricks, 0);
		this.setBlock(world, i + 7, j + 3, k + 12, KCore.WeatheredRockBricks, 0);
		this.setBlock(world, i + 7, j + 3, k + 13, 0, 0);
		this.setBlock(world, i + 7, j + 3, k + 14, 0, 0);
		this.setBlock(world, i + 7, j + 3, k + 15, 0, 0);
		this.setBlock(world, i + 7, j + 3, k + 16, 0, 0);
		this.setBlock(world, i + 7, j + 3, k + 17, KCore.WeatheredRockBricks, 0);
		this.setBlock(world, i + 7, j + 4, k + 0, 0, 0);
		this.setBlock(world, i + 7, j + 4, k + 1, 0, 0);
		this.setBlock(world, i + 7, j + 4, k + 2, KCore.HardenedWeatheredRockStairs, 2);
		this.setBlock(world, i + 7, j + 4, k + 3, 0, 0);
		this.setBlock(world, i + 7, j + 4, k + 4, 0, 0);
		this.setBlock(world, i + 7, j + 4, k + 5, KCore.HardenedWeatheredRockStairs, 3);
		this.setBlock(world, i + 7, j + 4, k + 6, KCore.WeatheredRockBricks, 0);
		this.setBlock(world, i + 7, j + 4, k + 7, 0, 0);
		this.setBlock(world, i + 7, j + 4, k + 8, Blocks.BOOKSHELF, 0);
		this.setBlock(world, i + 7, j + 4, k + 9, Blocks.WEB, 0);
		this.setBlock(world, i + 7, j + 4, k + 10, Blocks.BOOKSHELF, 0);
		this.setBlock(world, i + 7, j + 4, k + 11, 0, 0);
		this.setBlock(world, i + 7, j + 4, k + 12, Blocks.BOOKSHELF, 0);
		this.setBlock(world, i + 7, j + 4, k + 13, 0, 0);
		this.setBlock(world, i + 7, j + 4, k + 14, 0, 0);
		this.setBlock(world, i + 7, j + 4, k + 15, 0, 0);
		this.setBlock(world, i + 7, j + 4, k + 16, 0, 0);
		this.setBlock(world, i + 7, j + 4, k + 17, KCore.WeatheredRockBricks, 0);
		this.setBlock(world, i + 7, j + 5, k + 0, 0, 0);
		this.setBlock(world, i + 7, j + 5, k + 1, 0, 0);
		this.setBlock(world, i + 7, j + 5, k + 2, 0, 0);
		this.setBlock(world, i + 7, j + 5, k + 3, KCore.HardenedWeatheredRockStairs, 2);
		this.setBlock(world, i + 7, j + 5, k + 4, KCore.HardenedWeatheredRockStairs, 3);
		this.setBlock(world, i + 7, j + 5, k + 5, 0, 0);
		this.setBlock(world, i + 7, j + 5, k + 6, KCore.WeatheredRockBricks, 0);
		this.setBlock(world, i + 7, j + 5, k + 7, 0, 0);
		this.setBlock(world, i + 7, j + 5, k + 8, Blocks.BOOKSHELF, 0);
		this.setBlock(world, i + 7, j + 5, k + 9, Blocks.WEB, 0);
		this.setBlock(world, i + 7, j + 5, k + 10, Blocks.BOOKSHELF, 0);
		this.setBlock(world, i + 7, j + 5, k + 11, 0, 0);
		this.setBlock(world, i + 7, j + 5, k + 12, Blocks.BOOKSHELF, 0);
		this.setBlock(world, i + 7, j + 5, k + 13, 0, 0);
		this.setBlock(world, i + 7, j + 5, k + 14, 0, 0);
		this.setBlock(world, i + 7, j + 5, k + 15, 0, 0);
		this.setBlock(world, i + 7, j + 5, k + 16, 0, 0);
		this.setBlock(world, i + 7, j + 5, k + 17, KCore.WeatheredRockBricks, 0);
		this.setBlock(world, i + 7, j + 6, k + 0, 0, 0);
		this.setBlock(world, i + 7, j + 6, k + 1, 0, 0);
		this.setBlock(world, i + 7, j + 6, k + 2, 0, 0);
		this.setBlock(world, i + 7, j + 6, k + 3, 0, 0);
		this.setBlock(world, i + 7, j + 6, k + 4, 0, 0);
		this.setBlock(world, i + 7, j + 6, k + 5, 0, 0);
		this.setBlock(world, i + 7, j + 6, k + 6, KCore.WeatheredRockBricks, 0);
		this.setBlock(world, i + 7, j + 6, k + 7, 0, 0);
		this.setBlock(world, i + 7, j + 6, k + 8, Blocks.BOOKSHELF, 0);
		this.setBlock(world, i + 7, j + 6, k + 9, 0, 0);
		this.setBlock(world, i + 7, j + 6, k + 10, Blocks.BOOKSHELF, 0);
		this.setBlock(world, i + 7, j + 6, k + 11, 0, 0);
		this.setBlock(world, i + 7, j + 6, k + 12, Blocks.BOOKSHELF, 0);
		this.setBlock(world, i + 7, j + 6, k + 13, 0, 0);
		this.setBlock(world, i + 7, j + 6, k + 14, 0, 0);
		this.setBlock(world, i + 7, j + 6, k + 15, 0, 0);
		this.setBlock(world, i + 7, j + 6, k + 16, 0, 0);
		this.setBlock(world, i + 7, j + 6, k + 17, KCore.WeatheredRockBricks, 0);
		this.setBlock(world, i + 7, j + 7, k + 0, 0, 0);
		this.setBlock(world, i + 7, j + 7, k + 1, 0, 0);
		this.setBlock(world, i + 7, j + 7, k + 2, 0, 0);
		this.setBlock(world, i + 7, j + 7, k + 3, 0, 0);
		this.setBlock(world, i + 7, j + 7, k + 4, 0, 0);
		this.setBlock(world, i + 7, j + 7, k + 5, 0, 0);
		this.setBlock(world, i + 7, j + 7, k + 6, 0, 0);
		this.setBlock(world, i + 7, j + 7, k + 7, KCore.HardenedWeatheredRockStairs, 2);
		this.setBlock(world, i + 7, j + 7, k + 8, 0, 0);
		this.setBlock(world, i + 7, j + 7, k + 9, 0, 0);
		this.setBlock(world, i + 7, j + 7, k + 10, 0, 0);
		this.setBlock(world, i + 7, j + 7, k + 11, 0, 0);
		this.setBlock(world, i + 7, j + 7, k + 12, 0, 0);
		this.setBlock(world, i + 7, j + 7, k + 13, 0, 0);
		this.setBlock(world, i + 7, j + 7, k + 14, 0, 0);
		this.setBlock(world, i + 7, j + 7, k + 15, 0, 0);
		this.setBlock(world, i + 7, j + 7, k + 16, KCore.HardenedWeatheredRockStairs, 3);
		this.setBlock(world, i + 7, j + 7, k + 17, 0, 0);
		this.setBlock(world, i + 7, j + 8, k + 0, 0, 0);
		this.setBlock(world, i + 7, j + 8, k + 1, 0, 0);
		this.setBlock(world, i + 7, j + 8, k + 2, 0, 0);
		this.setBlock(world, i + 7, j + 8, k + 3, 0, 0);
		this.setBlock(world, i + 7, j + 8, k + 4, 0, 0);
		this.setBlock(world, i + 7, j + 8, k + 5, 0, 0);
		this.setBlock(world, i + 7, j + 8, k + 6, 0, 0);
		this.setBlock(world, i + 7, j + 8, k + 7, 0, 0);
		this.setBlock(world, i + 7, j + 8, k + 8, KCore.HardenedWeatheredRockStairs, 2);
		this.setBlock(world, i + 7, j + 8, k + 9, 0, 0);
		this.setBlock(world, i + 7, j + 8, k + 10, 0, 0);
		this.setBlock(world, i + 7, j + 8, k + 11, KCore.HardenedWeatheredRockStairs, 3);
		this.setBlock(world, i + 7, j + 8, k + 12, KCore.HardenedWeatheredRockStairs, 0);
		this.setBlock(world, i + 7, j + 8, k + 13, KCore.HardenedWeatheredRockStairs, 0);
		this.setBlock(world, i + 7, j + 8, k + 14, KCore.HardenedWeatheredRockStairs, 0);
		this.setBlock(world, i + 7, j + 8, k + 15, KCore.HardenedWeatheredRockStairs, 0);
		this.setBlock(world, i + 7, j + 8, k + 16, 0, 0);
		this.setBlock(world, i + 7, j + 8, k + 17, 0, 0);
		this.setBlock(world, i + 7, j + 9, k + 0, 0, 0);
		this.setBlock(world, i + 7, j + 9, k + 1, 0, 0);
		this.setBlock(world, i + 7, j + 9, k + 2, 0, 0);
		this.setBlock(world, i + 7, j + 9, k + 3, 0, 0);
		this.setBlock(world, i + 7, j + 9, k + 4, 0, 0);
		this.setBlock(world, i + 7, j + 9, k + 5, 0, 0);
		this.setBlock(world, i + 7, j + 9, k + 6, 0, 0);
		this.setBlock(world, i + 7, j + 9, k + 7, 0, 0);
		this.setBlock(world, i + 7, j + 9, k + 8, 0, 0);
		this.setBlock(world, i + 7, j + 9, k + 9, KCore.HardenedWeatheredRockStairs, 2);
		this.setBlock(world, i + 7, j + 9, k + 10, KCore.HardenedWeatheredRockStairs, 3);
		this.setBlock(world, i + 7, j + 9, k + 11, 0, 0);
		this.setBlock(world, i + 7, j + 9, k + 12, 0, 0);
		this.setBlock(world, i + 7, j + 9, k + 13, 0, 0);
		this.setBlock(world, i + 7, j + 9, k + 14, 0, 0);
		this.setBlock(world, i + 7, j + 9, k + 15, 0, 0);
		this.setBlock(world, i + 7, j + 9, k + 16, 0, 0);
		this.setBlock(world, i + 7, j + 9, k + 17, 0, 0);
		this.setBlock(world, i + 8, j + 0, k + 0, KCore.HardenedWeatheredRockStairs, 2);
		this.setBlock(world, i + 8, j + 0, k + 1, KCore.WeatheredRockBricks, 0);
		this.setBlock(world, i + 8, j + 0, k + 2, KCore.WeatheredRockBricks, 0);
		this.setBlock(world, i + 8, j + 0, k + 3, KCore.WeatheredRockBricks, 0);
		this.setBlock(world, i + 8, j + 0, k + 4, KCore.WeatheredRockBricks, 0);
		this.setBlock(world, i + 8, j + 0, k + 5, KCore.WeatheredRockBricks, 0);
		this.setBlock(world, i + 8, j + 0, k + 6, KCore.WeatheredRockBricks, 0);
		this.setBlock(world, i + 8, j + 0, k + 7, KCore.WeatheredRockBricks, 0);
		this.setBlock(world, i + 8, j + 0, k + 8, KCore.WeatheredRockBricks, 0);
		this.setBlock(world, i + 8, j + 0, k + 9, KCore.WeatheredRockBricks, 0);
		this.setBlock(world, i + 8, j + 0, k + 10, KCore.WeatheredRockBricks, 0);
		this.setBlock(world, i + 8, j + 0, k + 11, KCore.WeatheredRockBricks, 0);
		this.setBlock(world, i + 8, j + 0, k + 12, KCore.WeatheredRockBricks, 0);
		this.setBlock(world, i + 8, j + 0, k + 13, KCore.WeatheredRockBricks, 0);
		this.setBlock(world, i + 8, j + 0, k + 14, KCore.WeatheredRockBricks, 0);
		this.setBlock(world, i + 8, j + 0, k + 15, KCore.WeatheredRockBricks, 0);
		this.setBlock(world, i + 8, j + 0, k + 16, KCore.WeatheredRockBricks, 0);
		this.setBlock(world, i + 8, j + 0, k + 17, KCore.WeatheredRockBricks, 0);
		this.setBlock(world, i + 8, j + 1, k + 0, 0, 0);
		this.setBlock(world, i + 8, j + 1, k + 1, 0, 0);
		this.setBlock(world, i + 8, j + 1, k + 2, 0, 0);
		this.setBlock(world, i + 8, j + 1, k + 3, 0, 0);
		this.setBlock(world, i + 8, j + 1, k + 4, 0, 0);
		this.setBlock(world, i + 8, j + 1, k + 5, 0, 0);
		this.setBlock(world, i + 8, j + 1, k + 6, Blocks.BOOKSHELF, 0);
		this.setBlock(world, i + 8, j + 1, k + 7, 0, 0);
		this.setBlock(world, i + 8, j + 1, k + 8, 0, 0);
		this.setBlock(world, i + 8, j + 1, k + 9, 0, 0);
		this.setBlock(world, i + 8, j + 1, k + 10, 0, 0);
		this.setBlock(world, i + 8, j + 1, k + 11, 0, 0);
		this.setBlock(world, i + 8, j + 1, k + 12, Blocks.WEB, 0);
		this.setBlock(world, i + 8, j + 1, k + 13, 0, 0);
		this.setBlock(world, i + 8, j + 1, k + 14, Blocks.WEB, 0);
		this.setBlock(world, i + 8, j + 1, k + 15, 0, 0);
		this.setBlock(world, i + 8, j + 1, k + 16, KCore.WeatheredRockBricks, 0);
		this.setBlock(world, i + 8, j + 1, k + 17, KCore.WeatheredRockBricks, 0);
		this.setBlock(world, i + 8, j + 2, k + 0, 0, 0);
		this.setBlock(world, i + 8, j + 2, k + 1, 0, 0);
		this.setBlock(world, i + 8, j + 2, k + 2, 0, 0);
		this.setBlock(world, i + 8, j + 2, k + 3, 0, 0);
		this.setBlock(world, i + 8, j + 2, k + 4, 0, 0);
		this.setBlock(world, i + 8, j + 2, k + 5, 0, 0);
		this.setBlock(world, i + 8, j + 2, k + 6, Blocks.WEB, 0);
		this.setBlock(world, i + 8, j + 2, k + 7, 0, 0);
		this.setBlock(world, i + 8, j + 2, k + 8, 0, 0);
		this.setBlock(world, i + 8, j + 2, k + 9, 0, 0);
		this.setBlock(world, i + 8, j + 2, k + 10, 0, 0);
		this.setBlock(world, i + 8, j + 2, k + 11, 0, 0);
		this.setBlock(world, i + 8, j + 2, k + 12, 0, 0);
		this.setBlock(world, i + 8, j + 2, k + 13, 0, 0);
		this.setBlock(world, i + 8, j + 2, k + 14, 0, 0);
		this.setBlock(world, i + 8, j + 2, k + 15, Blocks.BOOKSHELF, 0);
		this.setBlock(world, i + 8, j + 2, k + 16, KCore.WeatheredRockBricks, 0);
		this.setBlock(world, i + 8, j + 2, k + 17, KCore.WeatheredRockBricks, 0);
		this.setBlock(world, i + 8, j + 3, k + 0, 0, 0);
		this.setBlock(world, i + 8, j + 3, k + 1, KCore.HardenedWeatheredRockStairs, 2);
		this.setBlock(world, i + 8, j + 3, k + 2, 0, 0);
		this.setBlock(world, i + 8, j + 3, k + 3, 0, 0);
		this.setBlock(world, i + 8, j + 3, k + 4, 0, 0);
		this.setBlock(world, i + 8, j + 3, k + 5, 0, 0);

		generate2(world, rand, i, j, k);
		return true;
		}else {
			return false;
		}
	}

	public boolean generate2(World world, Random rand, int i, int j, int k) {
		this.setBlock(world, i + 8, j + 3, k + 6, KCore.HardenedWeatheredRockStairs, 3);
		this.setBlock(world, i + 8, j + 3, k + 7, KCore.WeatheredRockBricks, 0);
		this.setBlock(world, i + 8, j + 3, k + 8, KCore.WeatheredRockBricks, 0);
		this.setBlock(world, i + 8, j + 3, k + 9, KCore.WeatheredRockBricks, 0);
		this.setBlock(world, i + 8, j + 3, k + 10, KCore.WeatheredRockBricks, 0);
		this.setBlock(world, i + 8, j + 3, k + 11, KCore.WeatheredRockBricks, 0);
		this.setBlock(world, i + 8, j + 3, k + 12, KCore.WeatheredRockBricks, 0);
		this.setBlock(world, i + 8, j + 3, k + 13, KCore.WeatheredRockBricks, 0);
		this.setBlock(world, i + 8, j + 3, k + 14, KCore.WeatheredRockBricks, 0);
		this.setBlock(world, i + 8, j + 3, k + 15, KCore.WeatheredRockBricks, 0);
		this.setBlock(world, i + 8, j + 3, k + 16, KCore.HardenedWeatheredRockStairs, 0);
		this.setBlock(world, i + 8, j + 3, k + 17, KCore.WeatheredRockBricks, 0);
		this.setBlock(world, i + 8, j + 4, k + 0, 0, 0);
		this.setBlock(world, i + 8, j + 4, k + 1, 0, 0);
		this.setBlock(world, i + 8, j + 4, k + 2, KCore.HardenedWeatheredRockStairs, 2);
		this.setBlock(world, i + 8, j + 4, k + 3, 0, 0);
		this.setBlock(world, i + 8, j + 4, k + 4, 0, 0);
		this.setBlock(world, i + 8, j + 4, k + 5, KCore.HardenedWeatheredRockStairs, 3);
		this.setBlock(world, i + 8, j + 4, k + 6, KCore.WeatheredRockBricks, 0);
		this.setBlock(world, i + 8, j + 4, k + 7, 0, 0);
		this.setBlock(world, i + 8, j + 4, k + 8, Blocks.BOOKSHELF, 0);
		this.setBlock(world, i + 8, j + 4, k + 9, Blocks.WEB, 0);
		this.setBlock(world, i + 8, j + 4, k + 10, Blocks.BOOKSHELF, 0);
		this.setBlock(world, i + 8, j + 4, k + 11, 0, 0);
		this.setBlock(world, i + 8, j + 4, k + 12, 0, 0);
		this.setBlock(world, i + 8, j + 4, k + 13, 0, 0);
		this.setBlock(world, i + 8, j + 4, k + 14, 0, 0);
		this.setBlock(world, i + 8, j + 4, k + 15, 0, 0);
		this.setBlock(world, i + 8, j + 4, k + 16, 0, 0);
		this.setBlock(world, i + 8, j + 4, k + 17, KCore.WeatheredRockBricks, 0);
		this.setBlock(world, i + 8, j + 5, k + 0, 0, 0);
		this.setBlock(world, i + 8, j + 5, k + 1, 0, 0);
		this.setBlock(world, i + 8, j + 5, k + 2, 0, 0);
		this.setBlock(world, i + 8, j + 5, k + 3, KCore.HardenedWeatheredRockStairs, 2);
		this.setBlock(world, i + 8, j + 5, k + 4, KCore.HardenedWeatheredRockStairs, 3);
		this.setBlock(world, i + 8, j + 5, k + 5, 0, 0);
		this.setBlock(world, i + 8, j + 5, k + 6, KCore.WeatheredRockBricks, 0);
		this.setBlock(world, i + 8, j + 5, k + 7, 0, 0);
		this.setBlock(world, i + 8, j + 5, k + 8, Blocks.BOOKSHELF, 0);
		this.setBlock(world, i + 8, j + 5, k + 9, Blocks.WEB, 0);
		this.setBlock(world, i + 8, j + 5, k + 10, Blocks.BOOKSHELF, 0);
		this.setBlock(world, i + 8, j + 5, k + 11, 0, 0);
		this.setBlock(world, i + 8, j + 5, k + 12, 0, 0);
		this.setBlock(world, i + 8, j + 5, k + 13, 0, 0);
		this.setBlock(world, i + 8, j + 5, k + 14, 0, 0);
		this.setBlock(world, i + 8, j + 5, k + 15, 0, 0);
		this.setBlock(world, i + 8, j + 5, k + 16, 0, 0);
		this.setBlock(world, i + 8, j + 5, k + 17, KCore.WeatheredRockBricks, 0);
		this.setBlock(world, i + 8, j + 6, k + 0, 0, 0);
		this.setBlock(world, i + 8, j + 6, k + 1, 0, 0);
		this.setBlock(world, i + 8, j + 6, k + 2, 0, 0);
		this.setBlock(world, i + 8, j + 6, k + 3, 0, 0);
		this.setBlock(world, i + 8, j + 6, k + 4, 0, 0);
		this.setBlock(world, i + 8, j + 6, k + 5, 0, 0);
		this.setBlock(world, i + 8, j + 6, k + 6, KCore.WeatheredRockBricks, 0);
		this.setBlock(world, i + 8, j + 6, k + 7, 0, 0);
		this.setBlock(world, i + 8, j + 6, k + 8, Blocks.BOOKSHELF, 0);
		this.setBlock(world, i + 8, j + 6, k + 9, Blocks.WEB, 0);
		this.setBlock(world, i + 8, j + 6, k + 10, Blocks.BOOKSHELF, 0);
		this.setBlock(world, i + 8, j + 6, k + 11, 0, 0);
		this.setBlock(world, i + 8, j + 6, k + 12, 0, 0);
		this.setBlock(world, i + 8, j + 6, k + 13, 0, 0);
		this.setBlock(world, i + 8, j + 6, k + 14, 0, 0);
		this.setBlock(world, i + 8, j + 6, k + 15, 0, 0);
		this.setBlock(world, i + 8, j + 6, k + 16, 0, 0);
		this.setBlock(world, i + 8, j + 6, k + 17, KCore.WeatheredRockBricks, 0);
		this.setBlock(world, i + 8, j + 7, k + 0, 0, 0);
		this.setBlock(world, i + 8, j + 7, k + 1, 0, 0);
		this.setBlock(world, i + 8, j + 7, k + 2, 0, 0);
		this.setBlock(world, i + 8, j + 7, k + 3, 0, 0);
		this.setBlock(world, i + 8, j + 7, k + 4, 0, 0);
		this.setBlock(world, i + 8, j + 7, k + 5, 0, 0);
		this.setBlock(world, i + 8, j + 7, k + 6, 0, 0);
		this.setBlock(world, i + 8, j + 7, k + 7, KCore.HardenedWeatheredRockStairs, 2);
		this.setBlock(world, i + 8, j + 7, k + 8, 0, 0);
		this.setBlock(world, i + 8, j + 7, k + 9, 0, 0);
		this.setBlock(world, i + 8, j + 7, k + 10, 0, 0);
		this.setBlock(world, i + 8, j + 7, k + 11, 0, 0);
		this.setBlock(world, i + 8, j + 7, k + 12, 0, 0);
		this.setBlock(world, i + 8, j + 7, k + 13, 0, 0);
		this.setBlock(world, i + 8, j + 7, k + 14, 0, 0);
		this.setBlock(world, i + 8, j + 7, k + 15, 0, 0);
		this.setBlock(world, i + 8, j + 7, k + 16, KCore.HardenedWeatheredRockStairs, 3);
		this.setBlock(world, i + 8, j + 7, k + 17, 0, 0);
		this.setBlock(world, i + 8, j + 8, k + 0, 0, 0);
		this.setBlock(world, i + 8, j + 8, k + 1, 0, 0);
		this.setBlock(world, i + 8, j + 8, k + 2, 0, 0);
		this.setBlock(world, i + 8, j + 8, k + 3, 0, 0);
		this.setBlock(world, i + 8, j + 8, k + 4, 0, 0);
		this.setBlock(world, i + 8, j + 8, k + 5, 0, 0);
		this.setBlock(world, i + 8, j + 8, k + 6, 0, 0);
		this.setBlock(world, i + 8, j + 8, k + 7, 0, 0);
