package mod.krevik.world.gen;

import java.util.Random;

import mod.krevik.KCore;

import net.minecraft.block.state.IBlockState;
import net.minecraft.init.Blocks;
import net.minecraft.item.ItemStack;
import net.minecraft.tileentity.TileEntity;
import net.minecraft.tileentity.TileEntityChest;
import net.minecraft.util.math.BlockPos;
import net.minecraft.world.World;
import net.minecraft.world.gen.feature.WorldGenerator;

public class WorldGenCloudTemple extends WorldGenerator
{
	public WorldGenCloudTemple() { }

Random random = new Random();
	public void setBlock(World world, int x, int y, int z, IBlockState state, int metadata)
	{
		if(world.isAirBlock(new BlockPos(x, y, z)))
		{
			setBlockAndNotifyAdequately(world,new BlockPos(x, y, z), state.getBlock().getStateFromMeta(metadata));
			if(state==Blocks.WATER.getDefaultState()) {
				world.neighborChanged(new BlockPos(x,y,z), world.getBlockState(new BlockPos(x,y,z)).getBlock(), new BlockPos(x,y+1,z));
			}
		}
	}
    protected void setBlockAndNotifyAdequately(World worldIn, BlockPos pos, IBlockState state)
    {
            worldIn.setBlockState(pos, state, 2);
    }

	public boolean generate(World world, Random rand, int i, int j, int k) {
		this.setBlock(world, i + 0, j + 0, k + 12, KCore.BlueCloud.getDefaultState(), 0);
		this.setBlock(world, i + 0, j + 0, k + 13, KCore.BlueCloud.getDefaultState(), 0);
		this.setBlock(world, i + 0, j + 0, k + 14, KCore.BlueCloud.getDefaultState(), 0);
		this.setBlock(world, i + 0, j + 0, k + 15, KCore.BlueCloud.getDefaultState(), 0);
		this.setBlock(world, i + 0, j + 0, k + 16, KCore.BlueCloud.getDefaultState(), 0);
		this.setBlock(world, i + 0, j + 0, k + 17, KCore.BlueCloud.getDefaultState(), 0);
		this.setBlock(world, i + 0, j + 0, k + 18, KCore.BlueCloud.getDefaultState(), 0);
		this.setBlock(world, i + 0, j + 0, k + 19, KCore.BlueCloud.getDefaultState(), 0);
		this.setBlock(world, i + 0, j + 1, k + 13, KCore.BlueCloud.getDefaultState(), 0);
		this.setBlock(world, i + 0, j + 1, k + 14, KCore.BlueCloud.getDefaultState(), 0);
		this.setBlock(world, i + 0, j + 1, k + 15, KCore.BlueCloud.getDefaultState(), 0);
		this.setBlock(world, i + 0, j + 1, k + 16, KCore.BlueCloud.getDefaultState(), 0);
		this.setBlock(world, i + 0, j + 1, k + 17, KCore.BlueCloud.getDefaultState(), 0);
		this.setBlock(world, i + 0, j + 1, k + 18, KCore.BlueCloud.getDefaultState(), 0);
		this.setBlock(world, i + 0, j + 1, k + 19, KCore.BlueCloud.getDefaultState(), 0);
		this.setBlock(world, i + 0, j + 2, k + 16, KCore.BlueCondensedCloud.getDefaultState(), 0);
		this.setBlock(world, i + 0, j + 2, k + 17, KCore.BlueCondensedCloud.getDefaultState(), 0);
		this.setBlock(world, i + 0, j + 2, k + 18, KCore.BlueCondensedCloud.getDefaultState(), 0);
		this.setBlock(world, i + 1, j + 0, k + 11, KCore.BlueCloud.getDefaultState(), 0);
		this.setBlock(world, i + 1, j + 0, k + 12, KCore.BlueCloud.getDefaultState(), 0);
		this.setBlock(world, i + 1, j + 0, k + 13, KCore.BlueCloud.getDefaultState(), 0);
		this.setBlock(world, i + 1, j + 0, k + 14, KCore.BlueCloud.getDefaultState(), 0);
		this.setBlock(world, i + 1, j + 0, k + 15, KCore.BlueCloud.getDefaultState(), 0);
		this.setBlock(world, i + 1, j + 0, k + 16, KCore.BlueCloud.getDefaultState(), 0);
		this.setBlock(world, i + 1, j + 0, k + 17, KCore.BlueCloud.getDefaultState(), 0);
		this.setBlock(world, i + 1, j + 0, k + 18, KCore.BlueCloud.getDefaultState(), 0);
		this.setBlock(world, i + 1, j + 0, k + 19, KCore.BlueCloud.getDefaultState(), 0);
		this.setBlock(world, i + 1, j + 1, k + 12, KCore.BlueCloud.getDefaultState(), 0);
		this.setBlock(world, i + 1, j + 1, k + 13, KCore.BlueCloud.getDefaultState(), 0);
		this.setBlock(world, i + 1, j + 1, k + 14, KCore.BlueCloud.getDefaultState(), 0);
		this.setBlock(world, i + 1, j + 1, k + 15, KCore.BlueCloud.getDefaultState(), 0);
		this.setBlock(world, i + 1, j + 1, k + 16, KCore.BlueCloud.getDefaultState(), 0);
		this.setBlock(world, i + 1, j + 1, k + 17, KCore.BlueCloud.getDefaultState(), 0);
		this.setBlock(world, i + 1, j + 1, k + 18, KCore.BlueCloud.getDefaultState(), 0);
		this.setBlock(world, i + 1, j + 1, k + 19, KCore.BlueCloud.getDefaultState(), 0);
		this.setBlock(world, i + 1, j + 2, k + 13, KCore.BlueCondensedCloud.getDefaultState(), 0);
		this.setBlock(world, i + 1, j + 2, k + 14, KCore.BlueCondensedCloud.getDefaultState(), 0);
		this.setBlock(world, i + 1, j + 2, k + 15, KCore.BlueCondensedCloud.getDefaultState(), 0);
		this.setBlock(world, i + 1, j + 2, k + 16, KCore.BlueCondensedCloud.getDefaultState(), 0);
		this.setBlock(world, i + 1, j + 2, k + 17, KCore.BlueCondensedCloud.getDefaultState(), 0);
		this.setBlock(world, i + 1, j + 2, k + 18, KCore.BlueCondensedCloud.getDefaultState(), 0);
		this.setBlock(world, i + 1, j + 3, k + 14, KCore.BlueCloudBricks.getDefaultState(), 0);
		this.setBlock(world, i + 1, j + 7, k + 11, KCore.BlueCloudBricks.getDefaultState(), 0);
		this.setBlock(world, i + 1, j + 7, k + 12, KCore.BlueCloudBricks.getDefaultState(), 0);
		this.setBlock(world, i + 1, j + 7, k + 13, KCore.BlueCloudBricks.getDefaultState(), 0);
		this.setBlock(world, i + 1, j + 7, k + 14, KCore.BlueCloudBricks.getDefaultState(), 0);
		this.setBlock(world, i + 2, j + 0, k + 4, KCore.BlueCloud.getDefaultState(), 0);
		this.setBlock(world, i + 2, j + 0, k + 5, KCore.BlueCloud.getDefaultState(), 0);
		this.setBlock(world, i + 2, j + 0, k + 6, KCore.BlueCloud.getDefaultState(), 0);
		this.setBlock(world, i + 2, j + 0, k + 10, KCore.BlueCloud.getDefaultState(), 0);
		this.setBlock(world, i + 2, j + 0, k + 11, KCore.BlueCloud.getDefaultState(), 0);
		this.setBlock(world, i + 2, j + 0, k + 12, KCore.BlueCloud.getDefaultState(), 0);
		this.setBlock(world, i + 2, j + 0, k + 13, KCore.BlueCloud.getDefaultState(), 0);
		this.setBlock(world, i + 2, j + 0, k + 14, KCore.BlueCloud.getDefaultState(), 0);
		this.setBlock(world, i + 2, j + 0, k + 15, KCore.BlueCloud.getDefaultState(), 0);
		this.setBlock(world, i + 2, j + 0, k + 16, KCore.BlueCloud.getDefaultState(), 0);
		this.setBlock(world, i + 2, j + 0, k + 17, KCore.BlueCloud.getDefaultState(), 0);
		this.setBlock(world, i + 2, j + 0, k + 18, KCore.BlueCloud.getDefaultState(), 0);
		this.setBlock(world, i + 2, j + 0, k + 19, KCore.BlueCloud.getDefaultState(), 0);
		this.setBlock(world, i + 2, j + 1, k + 5, KCore.BlueCloud.getDefaultState(), 0);
		this.setBlock(world, i + 2, j + 1, k + 11, KCore.BlueCloud.getDefaultState(), 0);
		this.setBlock(world, i + 2, j + 1, k + 12, KCore.BlueCloud.getDefaultState(), 0);
		this.setBlock(world, i + 2, j + 1, k + 13, KCore.BlueCloud.getDefaultState(), 0);
		this.setBlock(world, i + 2, j + 1, k + 14, KCore.BlueCloud.getDefaultState(), 0);
		this.setBlock(world, i + 2, j + 1, k + 15, KCore.BlueCloud.getDefaultState(), 0);
		this.setBlock(world, i + 2, j + 1, k + 16, KCore.BlueCloud.getDefaultState(), 0);
		this.setBlock(world, i + 2, j + 1, k + 17, KCore.BlueCloud.getDefaultState(), 0);
		this.setBlock(world, i + 2, j + 1, k + 18, KCore.BlueCloud.getDefaultState(), 0);
		this.setBlock(world, i + 2, j + 2, k + 11, KCore.BlueCondensedCloud.getDefaultState(), 0);
		this.setBlock(world, i + 2, j + 2, k + 12, KCore.BlueCondensedCloud.getDefaultState(), 0);
		this.setBlock(world, i + 2, j + 2, k + 13, KCore.BlueCondensedCloud.getDefaultState(), 0);
		this.setBlock(world, i + 2, j + 2, k + 14, KCore.BlueCondensedCloud.getDefaultState(), 0);
		this.setBlock(world, i + 2, j + 2, k + 15, KCore.BlueCondensedCloud.getDefaultState(), 0);
		this.setBlock(world, i + 2, j + 2, k + 16, KCore.BlueCondensedCloud.getDefaultState(), 0);
		this.setBlock(world, i + 2, j + 2, k + 17, KCore.BlueCondensedCloud.getDefaultState(), 0);
		this.setBlock(world, i + 2, j + 3, k + 11, KCore.BlueCloudBricks.getDefaultState(), 0);
		this.setBlock(world, i + 2, j + 3, k + 12, KCore.BlueCloudBricks.getDefaultState(), 0);
		this.setBlock(world, i + 2, j + 3, k + 13, KCore.BlueCloudBricks.getDefaultState(), 0);
		this.setBlock(world, i + 2, j + 3, k + 14, KCore.YellowCloudBlock.getDefaultState(), 0);
		this.setBlock(world, i + 2, j + 3, k + 15, KCore.BlueCloudBricks.getDefaultState(), 0);
		this.setBlock(world, i + 2, j + 4, k + 13, KCore.BlueCloudBricks.getDefaultState(), 0);
		this.setBlock(world, i + 2, j + 5, k + 13, KCore.BlueCloudBricks.getDefaultState(), 0);
		this.setBlock(world, i + 2, j + 6, k + 13, KCore.BlueCloudBricks.getDefaultState(), 0);
		this.setBlock(world, i + 2, j + 7, k + 10, KCore.BlueCloudBricks.getDefaultState(), 0);
		this.setBlock(world, i + 2, j + 7, k + 11, KCore.BlueCloudBricks.getDefaultState(), 0);
		this.setBlock(world, i + 2, j + 7, k + 12, KCore.BlueCloudBricks.getDefaultState(), 0);
		this.setBlock(world, i + 2, j + 7, k + 13, KCore.BlueCloudBricks.getDefaultState(), 0);
		this.setBlock(world, i + 2, j + 7, k + 14, KCore.BlueCloudBricks.getDefaultState(), 0);
		this.setBlock(world, i + 2, j + 7, k + 15, KCore.BlueCloudBricks.getDefaultState(), 0);
		this.setBlock(world, i + 2, j + 8, k + 11, KCore.BlueCloudBricks.getDefaultState(), 0);
		this.setBlock(world, i + 2, j + 8, k + 12, KCore.BlueCloudBricks.getDefaultState(), 0);
		this.setBlock(world, i + 2, j + 8, k + 13, KCore.BlueCloudBricks.getDefaultState(), 0);
		this.setBlock(world, i + 2, j + 8, k + 14, KCore.BlueCloudBricks.getDefaultState(), 0);
		this.setBlock(world, i + 3, j + 0, k + 3, KCore.BlueCloud.getDefaultState(), 0);
		this.setBlock(world, i + 3, j + 0, k + 4, KCore.BlueCloud.getDefaultState(), 0);
		this.setBlock(world, i + 3, j + 0, k + 5, KCore.BlueCloud.getDefaultState(), 0);
		this.setBlock(world, i + 3, j + 0, k + 6, KCore.BlueCloud.getDefaultState(), 0);
		this.setBlock(world, i + 3, j + 0, k + 7, KCore.BlueCloud.getDefaultState(), 0);
		this.setBlock(world, i + 3, j + 0, k + 9, KCore.BlueCloud.getDefaultState(), 0);
		this.setBlock(world, i + 3, j + 0, k + 10, KCore.BlueCloud.getDefaultState(), 0);
		this.setBlock(world, i + 3, j + 0, k + 11, KCore.BlueCloud.getDefaultState(), 0);
		this.setBlock(world, i + 3, j + 0, k + 12, KCore.BlueCloud.getDefaultState(), 0);
		this.setBlock(world, i + 3, j + 0, k + 13, KCore.BlueCloud.getDefaultState(), 0);
		this.setBlock(world, i + 3, j + 0, k + 14, KCore.BlueCloud.getDefaultState(), 0);
		this.setBlock(world, i + 3, j + 0, k + 15, KCore.BlueCloud.getDefaultState(), 0);
		this.setBlock(world, i + 3, j + 0, k + 16, KCore.BlueCloud.getDefaultState(), 0);
		this.setBlock(world, i + 3, j + 0, k + 17, KCore.BlueCloud.getDefaultState(), 0);
		this.setBlock(world, i + 3, j + 0, k + 18, KCore.BlueCloud.getDefaultState(), 0);
		this.setBlock(world, i + 3, j + 1, k + 4, KCore.BlueCloud.getDefaultState(), 0);
		this.setBlock(world, i + 3, j + 1, k + 5, KCore.BlueCloud.getDefaultState(), 0);
		this.setBlock(world, i + 3, j + 1, k + 6, KCore.BlueCloud.getDefaultState(), 0);
		this.setBlock(world, i + 3, j + 1, k + 9, KCore.BlueCloud.getDefaultState(), 0);
		this.setBlock(world, i + 3, j + 1, k + 10, KCore.BlueCloud.getDefaultState(), 0);
		this.setBlock(world, i + 3, j + 1, k + 11, KCore.BlueCloud.getDefaultState(), 0);
		this.setBlock(world, i + 3, j + 1, k + 12, KCore.BlueCloud.getDefaultState(), 0);
		this.setBlock(world, i + 3, j + 1, k + 13, KCore.BlueCloud.getDefaultState(), 0);
		this.setBlock(world, i + 3, j + 1, k + 14, KCore.BlueCloud.getDefaultState(), 0);
		this.setBlock(world, i + 3, j + 1, k + 15, KCore.BlueCloud.getDefaultState(), 0);
		this.setBlock(world, i + 3, j + 1, k + 16, KCore.BlueCloud.getDefaultState(), 0);
		this.setBlock(world, i + 3, j + 1, k + 17, KCore.BlueCloud.getDefaultState(), 0);
		this.setBlock(world, i + 3, j + 1, k + 18, KCore.BlueCloud.getDefaultState(), 0);
		this.setBlock(world, i + 3, j + 2, k + 5, KCore.BlueCondensedCloud.getDefaultState(), 0);
		this.setBlock(world, i + 3, j + 2, k + 11, KCore.BlueCondensedCloud.getDefaultState(), 0);
		this.setBlock(world, i + 3, j + 2, k + 12, KCore.BlueCondensedCloud.getDefaultState(), 0);
		this.setBlock(world, i + 3, j + 2, k + 13, KCore.BlueCondensedCloud.getDefaultState(), 0);
		this.setBlock(world, i + 3, j + 2, k + 14, KCore.BlueCondensedCloud.getDefaultState(), 0);
		this.setBlock(world, i + 3, j + 2, k + 15, KCore.BlueCondensedCloud.getDefaultState(), 0);
		this.setBlock(world, i + 3, j + 2, k + 16, KCore.BlueCondensedCloud.getDefaultState(), 0);
		this.setBlock(world, i + 3, j + 3, k + 11, KCore.BlueCloudBricks.getDefaultState(), 0);
		this.setBlock(world, i + 3, j + 3, k + 12, KCore.YellowCloudBlock.getDefaultState(), 0);
		this.setBlock(world, i + 3, j + 3, k + 13, KCore.YellowCloudBlock.getDefaultState(), 0);
		this.setBlock(world, i + 3, j + 3, k + 14, KCore.YellowCloudBlock.getDefaultState(), 0);
		this.setBlock(world, i + 3, j + 3, k + 15, KCore.BlueCloudBricks.getDefaultState(), 0);
		this.setBlock(world, i + 3, j + 4, k + 11, KCore.BlueCloudBricks.getDefaultState(), 0);
		this.setBlock(world, i + 3, j + 4, k + 13, Blocks.CHEST.getDefaultState(), 5);
			TileEntity te=world.getTileEntity(new BlockPos(i+3,j+4,k+13));
			if(te!=null) {
			if(te instanceof TileEntityChest) {
				te=(TileEntityChest)world.getTileEntity(new BlockPos(i+3,j+4,k+13));
				for(int c=0;c<=rand.nextInt(10);c++) {
					ItemStack is=KCore.functionHelper.getCloudTempleReward();
					((TileEntityChest) te).setInventorySlotContents(1+rand.nextInt(9), is);
				}
			}
			}
		this.setBlock(world, i + 3, j + 4, k + 14, KCore.BlueCloudBricks.getDefaultState(), 0);
		this.setBlock(world, i + 3, j + 5, k + 11, KCore.BlueCloudBricks.getDefaultState(), 0);
		this.setBlock(world, i + 3, j + 5, k + 14, KCore.BlueCloudBricks.getDefaultState(), 0);
		this.setBlock(world, i + 3, j + 6, k + 11, KCore.BlueCloudBricks.getDefaultState(), 0);
		this.setBlock(world, i + 3, j + 6, k + 14, KCore.BlueCloudBricks.getDefaultState(), 0);
		this.setBlock(world, i + 3, j + 7, k + 9, KCore.BlueCloudBricks.getDefaultState(), 0);
		this.setBlock(world, i + 3, j + 7, k + 10, KCore.BlueCloudBricks.getDefaultState(), 0);
		this.setBlock(world, i + 3, j + 7, k + 11, KCore.BlueCloudBricks.getDefaultState(), 0);
		this.setBlock(world, i + 3, j + 7, k + 14, KCore.BlueCloudBricks.getDefaultState(), 0);
		this.setBlock(world, i + 3, j + 7, k + 15, KCore.BlueCloudBricks.getDefaultState(), 0);
		this.setBlock(world, i + 3, j + 8, k + 10, KCore.BlueCloudBricks.getDefaultState(), 0);
		this.setBlock(world, i + 3, j + 8, k + 11, KCore.BlueCloudBricks.getDefaultState(), 0);
		this.setBlock(world, i + 3, j + 8, k + 14, KCore.BlueCloudBricks.getDefaultState(), 0);
		this.setBlock(world, i + 3, j + 9, k + 12, KCore.BlueCloudBricks.getDefaultState(), 0);
		this.setBlock(world, i + 3, j + 9, k + 13, KCore.BlueCloudBricks.getDefaultState(), 0);
		this.setBlock(world, i + 4, j + 0, k + 2, KCore.BlueCloud.getDefaultState(), 0);
		this.setBlock(world, i + 4, j + 0, k + 3, KCore.BlueCloud.getDefaultState(), 0);
		this.setBlock(world, i + 4, j + 0, k + 4, KCore.BlueCloud.getDefaultState(), 0);
		this.setBlock(world, i + 4, j + 0, k + 5, KCore.BlueCloud.getDefaultState(), 0);
		this.setBlock(world, i + 4, j + 0, k + 6, KCore.BlueCloud.getDefaultState(), 0);
		this.setBlock(world, i + 4, j + 0, k + 7, KCore.BlueCloud.getDefaultState(), 0);
		this.setBlock(world, i + 4, j + 0, k + 8, KCore.BlueCloud.getDefaultState(), 0);
		this.setBlock(world, i + 4, j + 0, k + 9, KCore.BlueCloud.getDefaultState(), 0);
		this.setBlock(world, i + 4, j + 0, k + 10, KCore.BlueCloud.getDefaultState(), 0);
		this.setBlock(world, i + 4, j + 0, k + 11, KCore.BlueCloud.getDefaultState(), 0);
		this.setBlock(world, i + 4, j + 0, k + 12, KCore.BlueCloud.getDefaultState(), 0);
		this.setBlock(world, i + 4, j + 0, k + 13, KCore.BlueCloud.getDefaultState(), 0);
		this.setBlock(world, i + 4, j + 0, k + 14, KCore.BlueCloud.getDefaultState(), 0);
		this.setBlock(world, i + 4, j + 0, k + 15, KCore.BlueCloud.getDefaultState(), 0);
		this.setBlock(world, i + 4, j + 0, k + 16, KCore.BlueCloud.getDefaultState(), 0);
		this.setBlock(world, i + 4, j + 0, k + 17, KCore.BlueCloud.getDefaultState(), 0);
		this.setBlock(world, i + 4, j + 0, k + 18, KCore.BlueCloud.getDefaultState(), 0);
		this.setBlock(world, i + 4, j + 1, k + 3, KCore.BlueCloud.getDefaultState(), 0);
		this.setBlock(world, i + 4, j + 1, k + 4, KCore.BlueCloud.getDefaultState(), 0);
		this.setBlock(world, i + 4, j + 1, k + 5, KCore.BlueCloud.getDefaultState(), 0);
		this.setBlock(world, i + 4, j + 1, k + 6, KCore.BlueCloud.getDefaultState(), 0);
		this.setBlock(world, i + 4, j + 1, k + 7, KCore.BlueCloud.getDefaultState(), 0);
		this.setBlock(world, i + 4, j + 1, k + 9, KCore.BlueCloud.getDefaultState(), 0);
		this.setBlock(world, i + 4, j + 1, k + 10, KCore.BlueCloud.getDefaultState(), 0);
		this.setBlock(world, i + 4, j + 1, k + 11, KCore.BlueCloud.getDefaultState(), 0);
		this.setBlock(world, i + 4, j + 1, k + 12, KCore.BlueCloud.getDefaultState(), 0);
		this.setBlock(world, i + 4, j + 1, k + 13, KCore.BlueCloud.getDefaultState(), 0);
		this.setBlock(world, i + 4, j + 1, k + 14, KCore.BlueCloud.getDefaultState(), 0);
		this.setBlock(world, i + 4, j + 1, k + 15, KCore.BlueCloud.getDefaultState(), 0);
		this.setBlock(world, i + 4, j + 1, k + 16, KCore.BlueCloud.getDefaultState(), 0);
		this.setBlock(world, i + 4, j + 1, k + 17, KCore.BlueCloud.getDefaultState(), 0);
		this.setBlock(world, i + 4, j + 2, k + 4, KCore.BlueCondensedCloud.getDefaultState(), 0);
		this.setBlock(world, i + 4, j + 2, k + 5, KCore.BlueCondensedCloud.getDefaultState(), 0);
		this.setBlock(world, i + 4, j + 2, k + 6, KCore.BlueCondensedCloud.getDefaultState(), 0);
		this.setBlock(world, i + 4, j + 2, k + 9, KCore.BlueCondensedCloud.getDefaultState(), 0);
		this.setBlock(world, i + 4, j + 2, k + 10, KCore.BlueCondensedCloud.getDefaultState(), 0);
		this.setBlock(world, i + 4, j + 2, k + 11, KCore.BlueCondensedCloud.getDefaultState(), 0);
		this.setBlock(world, i + 4, j + 2, k + 12, KCore.BlueCondensedCloud.getDefaultState(), 0);
		this.setBlock(world, i + 4, j + 2, k + 13, KCore.BlueCondensedCloud.getDefaultState(), 0);
		this.setBlock(world, i + 4, j + 2, k + 14, KCore.BlueCondensedCloud.getDefaultState(), 0);
		this.setBlock(world, i + 4, j + 2, k + 15, KCore.BlueCondensedCloud.getDefaultState(), 0);
		this.setBlock(world, i + 4, j + 3, k + 5, KCore.BlueCloudBricks.getDefaultState(), 0);
		this.setBlock(world, i + 4, j + 3, k + 10, KCore.BlueCloudBricks.getDefaultState(), 0);
		this.setBlock(world, i + 4, j + 3, k + 11, KCore.YellowCloudBlock.getDefaultState(), 0);
		this.setBlock(world, i + 4, j + 3, k + 12, KCore.YellowCloudBlock.getDefaultState(), 0);
		this.setBlock(world, i + 4, j + 3, k + 13, KCore.YellowCloudBlock.getDefaultState(), 0);
		this.setBlock(world, i + 4, j + 3, k + 14, KCore.BlueCloudBricks.getDefaultState(), 0);
		this.setBlock(world, i + 4, j + 7, k + 3, KCore.BlueCloudBricks.getDefaultState(), 0);
		this.setBlock(world, i + 4, j + 7, k + 4, KCore.BlueCloudBricks.getDefaultState(), 0);
		this.setBlock(world, i + 4, j + 7, k + 5, KCore.BlueCloudBricks.getDefaultState(), 0);
		this.setBlock(world, i + 4, j + 7, k + 6, KCore.BlueCloudBricks.getDefaultState(), 0);
		this.setBlock(world, i + 4, j + 7, k + 7, KCore.BlueCloudBricks.getDefaultState(), 0);
		this.setBlock(world, i + 4, j + 7, k + 8, KCore.BlueCloudBricks.getDefaultState(), 0);
		this.setBlock(world, i + 4, j + 7, k + 9, KCore.BlueCloudBricks.getDefaultState(), 0);
		this.setBlock(world, i + 4, j + 7, k + 10, KCore.BlueCloudBricks.getDefaultState(), 0);
		this.setBlock(world, i + 4, j + 7, k + 13, KCore.BlueCloudBricks.getDefaultState(), 0);
		this.setBlock(world, i + 4, j + 7, k + 14, KCore.BlueCloudBricks.getDefaultState(), 0);
		this.setBlock(world, i + 4, j + 7, k + 15, KCore.BlueCloudBricks.getDefaultState(), 0);
		this.setBlock(world, i + 4, j + 8, k + 10, KCore.BlueCloudBricks.getDefaultState(), 0);
		this.setBlock(world, i + 4, j + 8, k + 13, KCore.BlueCloudBricks.getDefaultState(), 0);
		this.setBlock(world, i + 4, j + 8, k + 14, KCore.BlueCloudBricks.getDefaultState(), 0);
		this.setBlock(world, i + 4, j + 9, k + 11, KCore.BlueCloudBricks.getDefaultState(), 0);
		this.setBlock(world, i + 4, j + 9, k + 12, KCore.BlueCloudBricks.getDefaultState(), 0);
		this.setBlock(world, i + 5, j + 0, k + 1, KCore.BlueCloud.getDefaultState(), 0);
		this.setBlock(world, i + 5, j + 0, k + 2, KCore.BlueCloud.getDefaultState(), 0);
		this.setBlock(world, i + 5, j + 0, k + 3, KCore.BlueCloud.getDefaultState(), 0);
		this.setBlock(world, i + 5, j + 0, k + 4, KCore.BlueCloud.getDefaultState(), 0);
		this.setBlock(world, i + 5, j + 0, k + 5, KCore.BlueCloud.getDefaultState(), 0);
		this.setBlock(world, i + 5, j + 0, k + 6, KCore.BlueCloud.getDefaultState(), 0);
		this.setBlock(world, i + 5, j + 0, k + 7, KCore.BlueCloud.getDefaultState(), 0);
		this.setBlock(world, i + 5, j + 0, k + 8, KCore.BlueCloud.getDefaultState(), 0);
		this.setBlock(world, i + 5, j + 0, k + 9, KCore.BlueCloud.getDefaultState(), 0);
		this.setBlock(world, i + 5, j + 0, k + 10, KCore.BlueCloud.getDefaultState(), 0);
		this.setBlock(world, i + 5, j + 0, k + 11, KCore.BlueCloud.getDefaultState(), 0);
		this.setBlock(world, i + 5, j + 0, k + 12, KCore.BlueCloud.getDefaultState(), 0);
		this.setBlock(world, i + 5, j + 0, k + 13, KCore.BlueCloud.getDefaultState(), 0);
		this.setBlock(world, i + 5, j + 0, k + 14, KCore.BlueCloud.getDefaultState(), 0);
		this.setBlock(world, i + 5, j + 0, k + 15, KCore.BlueCloud.getDefaultState(), 0);
		this.setBlock(world, i + 5, j + 0, k + 16, KCore.BlueCloud.getDefaultState(), 0);
		this.setBlock(world, i + 5, j + 0, k + 17, KCore.BlueCloud.getDefaultState(), 0);
		this.setBlock(world, i + 5, j + 1, k + 1, KCore.BlueCloud.getDefaultState(), 0);
		this.setBlock(world, i + 5, j + 1, k + 2, KCore.BlueCloud.getDefaultState(), 0);
		this.setBlock(world, i + 5, j + 1, k + 3, KCore.BlueCloud.getDefaultState(), 0);
		this.setBlock(world, i + 5, j + 1, k + 4, KCore.BlueCloud.getDefaultState(), 0);
		this.setBlock(world, i + 5, j + 1, k + 5, KCore.BlueCloud.getDefaultState(), 0);
		this.setBlock(world, i + 5, j + 1, k + 6, KCore.BlueCloud.getDefaultState(), 0);
		this.setBlock(world, i + 5, j + 1, k + 7, KCore.BlueCloud.getDefaultState(), 0);
		this.setBlock(world, i + 5, j + 1, k + 8, Blocks.WATER.getDefaultState(), 0);
		this.setBlock(world, i + 5, j + 1, k + 9, KCore.BlueCloud.getDefaultState(), 0);
		this.setBlock(world, i + 5, j + 1, k + 10, KCore.BlueCloud.getDefaultState(), 0);
		this.setBlock(world, i + 5, j + 1, k + 11, KCore.BlueCloud.getDefaultState(), 0);
		this.setBlock(world, i + 5, j + 1, k + 12, KCore.BlueCloud.getDefaultState(), 0);
		this.setBlock(world, i + 5, j + 1, k + 13, KCore.BlueCloud.getDefaultState(), 0);
		this.setBlock(world, i + 5, j + 1, k + 14, KCore.BlueCloud.getDefaultState(), 0);
		this.setBlock(world, i + 5, j + 1, k + 15, KCore.BlueCloud.getDefaultState(), 0);
		this.setBlock(world, i + 5, j + 1, k + 16, KCore.BlueCloud.getDefaultState(), 0);
		this.setBlock(world, i + 5, j + 2, k + 3, KCore.BlueCondensedCloud.getDefaultState(), 0);
		this.setBlock(world, i + 5, j + 2, k + 4, KCore.BlueCondensedCloud.getDefaultState(), 0);
		this.setBlock(world, i + 5, j + 2, k + 5, KCore.BlueCondensedCloud.getDefaultState(), 0);
		this.setBlock(world, i + 5, j + 2, k + 6, KCore.BlueCondensedCloud.getDefaultState(), 0);
		this.setBlock(world, i + 5, j + 2, k + 7, KCore.BlueCondensedCloud.getDefaultState(), 0);
		this.setBlock(world, i + 5, j + 2, k + 8, KCore.BlueCondensedCloud.getDefaultState(), 0);
		this.setBlock(world, i + 5, j + 2, k + 9, KCore.BlueCondensedCloud.getDefaultState(), 0);
		this.setBlock(world, i + 5, j + 2, k + 10, KCore.BlueCondensedCloud.getDefaultState(), 0);
		this.setBlock(world, i + 5, j + 2, k + 11, KCore.BlueCondensedCloud.getDefaultState(), 0);
		this.setBlock(world, i + 5, j + 2, k + 12, KCore.BlueCondensedCloud.getDefaultState(), 0);
		this.setBlock(world, i + 5, j + 2, k + 13, KCore.BlueCondensedCloud.getDefaultState(), 0);
		this.setBlock(world, i + 5, j + 2, k + 14, KCore.BlueCondensedCloud.getDefaultState(), 0);
		this.setBlock(world, i + 5, j + 2, k + 15, KCore.BlueCondensedCloud.getDefaultState(), 0);
		this.setBlock(world, i + 5, j + 3, k + 4, KCore.BlueCloudBricks.getDefaultState(), 0);
		this.setBlock(world, i + 5, j + 3, k + 5, KCore.YellowCloudBlock.getDefaultState(), 0);
		this.setBlock(world, i + 5, j + 3, k + 6, KCore.BlueCloudBricks.getDefaultState(), 0);
		this.setBlock(world, i + 5, j + 3, k + 7, KCore.BlueCloudBricks.getDefaultState(), 0);
		this.setBlock(world, i + 5, j + 3, k + 8, KCore.BlueCloudBricks.getDefaultState(), 0);
		this.setBlock(world, i + 5, j + 3, k + 9, KCore.BlueCloudBricks.getDefaultState(), 0);
		this.setBlock(world, i + 5, j + 3, k + 10, KCore.YellowCloudBlock.getDefaultState(), 0);
		this.setBlock(world, i + 5, j + 3, k + 11, KCore.YellowCloudBlock.getDefaultState(), 0);
		this.setBlock(world, i + 5, j + 3, k + 12, KCore.YellowCloudBlock.getDefaultState(), 0);
		this.setBlock(world, i + 5, j + 3, k + 13, KCore.BlueCloudBricks.getDefaultState(), 0);
		this.setBlock(world, i + 5, j + 3, k + 14, Blocks.WATER.getDefaultState(), 0);
		this.setBlock(world, i + 5, j + 4, k + 4, KCore.BlueCloudBricks.getDefaultState(), 0);
		this.setBlock(world, i + 5, j + 4, k + 6, KCore.BlueCloudBricks.getDefaultState(), 0);
		this.setBlock(world, i + 5, j + 4, k + 8, KCore.BlueCloudBricks.getDefaultState(), 0);
		this.setBlock(world, i + 5, j + 4, k + 10, KCore.BlueCloudBricks.getDefaultState(), 0);
		this.setBlock(world, i + 5, j + 4, k + 13, KCore.BlueCloudBricks.getDefaultState(), 0);
		this.setBlock(world, i + 5, j + 5, k + 4, KCore.BlueCloudBricks.getDefaultState(), 0);
		this.setBlock(world, i + 5, j + 5, k + 6, KCore.BlueCloudBricks.getDefaultState(), 0);
		this.setBlock(world, i + 5, j + 5, k + 8, KCore.BlueCloudBricks.getDefaultState(), 0);
		this.setBlock(world, i + 5, j + 5, k + 10, KCore.BlueCloudBricks.getDefaultState(), 0);
		this.setBlock(world, i + 5, j + 5, k + 13, KCore.BlueCloudBricks.getDefaultState(), 0);
		this.setBlock(world, i + 5, j + 6, k + 4, KCore.BlueCloudBricks.getDefaultState(), 0);
		this.setBlock(world, i + 5, j + 6, k + 6, KCore.BlueCloudBricks.getDefaultState(), 0);
		this.setBlock(world, i + 5, j + 6, k + 8, KCore.BlueCloudBricks.getDefaultState(), 0);
		this.setBlock(world, i + 5, j + 6, k + 10, KCore.BlueCloudBricks.getDefaultState(), 0);
		this.setBlock(world, i + 5, j + 6, k + 13, KCore.BlueCloudBricks.getDefaultState(), 0);
		this.setBlock(world, i + 5, j + 7, k + 3, KCore.BlueCloudBricks.getDefaultState(), 0);
		this.setBlock(world, i + 5, j + 7, k + 4, KCore.BlueCloudBricks.getDefaultState(), 0);
		this.setBlock(world, i + 5, j + 7, k + 5, KCore.BlueCloudBricks.getDefaultState(), 0);
		this.setBlock(world, i + 5, j + 7, k + 6, KCore.BlueCloudBricks.getDefaultState(), 0);
		this.setBlock(world, i + 5, j + 7, k + 7, KCore.BlueCloudBricks.getDefaultState(), 0);
		this.setBlock(world, i + 5, j + 7, k + 8, KCore.BlueCloudBricks.getDefaultState(), 0);
		this.setBlock(world, i + 5, j + 7, k + 9, KCore.BlueCloudBricks.getDefaultState(), 0);
		this.setBlock(world, i + 5, j + 7, k + 10, KCore.BlueCloudBricks.getDefaultState(), 0);
		this.setBlock(world, i + 5, j + 7, k + 13, KCore.BlueCloudBricks.getDefaultState(), 0);
		this.setBlock(world, i + 5, j + 7, k + 14, KCore.BlueCloudBricks.getDefaultState(), 0);
		this.setBlock(world, i + 5, j + 8, k + 4, KCore.BlueCloudBricks.getDefaultState(), 0);
		this.setBlock(world, i + 5, j + 8, k + 5, KCore.BlueCloudBricks.getDefaultState(), 0);
		this.setBlock(world, i + 5, j + 8, k + 6, KCore.BlueCloudBricks.getDefaultState(), 0);
		this.setBlock(world, i + 5, j + 8, k + 7, KCore.BlueCloudBricks.getDefaultState(), 0);
		this.setBlock(world, i + 5, j + 8, k + 8, KCore.BlueCloudBricks.getDefaultState(), 0);
		this.setBlock(world, i + 5, j + 8, k + 9, KCore.BlueCloudBricks.getDefaultState(), 0);
		this.setBlock(world, i + 5, j + 8, k + 10, KCore.BlueCloudBricks.getDefaultState(), 0);
		this.setBlock(world, i + 5, j + 8, k + 13, KCore.BlueCloudBricks.getDefaultState(), 0);
		this.setBlock(world, i + 5, j + 9, k + 11, KCore.BlueCloudBricks.getDefaultState(), 0);
		this.setBlock(world, i + 5, j + 9, k + 12, KCore.BlueCloudBricks.getDefaultState(), 0);
		this.setBlock(world, i + 6, j + 0, k + 1, KCore.BlueCloud.getDefaultState(), 0);
		this.setBlock(world, i + 6, j + 0, k + 2, KCore.BlueCloud.getDefaultState(), 0);
		this.setBlock(world, i + 6, j + 0, k + 3, KCore.BlueCloud.getDefaultState(), 0);
		this.setBlock(world, i + 6, j + 0, k + 4, KCore.BlueCloud.getDefaultState(), 0);
		this.setBlock(world, i + 6, j + 0, k + 5, KCore.BlueCloud.getDefaultState(), 0);
		this.setBlock(world, i + 6, j + 0, k + 6, KCore.BlueCloud.getDefaultState(), 0);
		this.setBlock(world, i + 6, j + 0, k + 7, KCore.BlueCloud.getDefaultState(), 0);
		this.setBlock(world, i + 6, j + 0, k + 8, KCore.BlueCloud.getDefaultState(), 0);
		this.setBlock(world, i + 6, j + 0, k + 9, KCore.BlueCloud.getDefaultState(), 0);
		this.setBlock(world, i + 6, j + 0, k + 10, KCore.BlueCloud.getDefaultState(), 0);
		this.setBlock(world, i + 6, j + 0, k + 11, KCore.BlueCloud.getDefaultState(), 0);
		this.setBlock(world, i + 6, j + 0, k + 12, KCore.BlueCloud.getDefaultState(), 0);
		this.setBlock(world, i + 6, j + 0, k + 13, KCore.BlueCloud.getDefaultState(), 0);
		this.setBlock(world, i + 6, j + 0, k + 14, KCore.BlueCloud.getDefaultState(), 0);
		this.setBlock(world, i + 6, j + 0, k + 15, KCore.BlueCloud.getDefaultState(), 0);
		this.setBlock(world, i + 6, j + 0, k + 16, KCore.BlueCloud.getDefaultState(), 0);
		this.setBlock(world, i + 6, j + 0, k + 17, KCore.BlueCloud.getDefaultState(), 0);
		this.setBlock(world, i + 6, j + 1, k + 1, KCore.BlueCloud.getDefaultState(), 0);
		this.setBlock(world, i + 6, j + 1, k + 2, KCore.BlueCloud.getDefaultState(), 0);
		this.setBlock(world, i + 6, j + 1, k + 3, KCore.BlueCloud.getDefaultState(), 0);
		this.setBlock(world, i + 6, j + 1, k + 4, KCore.BlueCloud.getDefaultState(), 0);
		this.setBlock(world, i + 6, j + 1, k + 5, KCore.BlueCloud.getDefaultState(), 0);
		this.setBlock(world, i + 6, j + 1, k + 6, KCore.BlueCloud.getDefaultState(), 0);
		this.setBlock(world, i + 6, j + 1, k + 7, KCore.BlueCloud.getDefaultState(), 0);
		this.setBlock(world, i + 6, j + 1, k + 8, KCore.BlueCloud.getDefaultState(), 0);
		this.setBlock(world, i + 6, j + 1, k + 9, KCore.BlueCloud.getDefaultState(), 0);
		this.setBlock(world, i + 6, j + 1, k + 10, KCore.BlueCloud.getDefaultState(), 0);
		this.setBlock(world, i + 6, j + 1, k + 11, KCore.BlueCloud.getDefaultState(), 0);
		this.setBlock(world, i + 6, j + 1, k + 12, KCore.BlueCloud.getDefaultState(), 0);
		this.setBlock(world, i + 6, j + 1, k + 13, KCore.BlueCloud.getDefaultState(), 0);
		this.setBlock(world, i + 6, j + 1, k + 14, KCore.BlueCloud.getDefaultState(), 0);
		this.setBlock(world, i + 6, j + 1, k + 15, KCore.BlueCloud.getDefaultState(), 0);
		this.setBlock(world, i + 6, j + 2, k + 3, KCore.BlueCondensedCloud.getDefaultState(), 0);
		this.setBlock(world, i + 6, j + 2, k + 4, KCore.BlueCondensedCloud.getDefaultState(), 0);
		this.setBlock(world, i + 6, j + 2, k + 5, KCore.BlueCondensedCloud.getDefaultState(), 0);
		this.setBlock(world, i + 6, j + 2, k + 6, KCore.BlueCondensedCloud.getDefaultState(), 0);
		this.setBlock(world, i + 6, j + 2, k + 7, KCore.BlueCondensedCloud.getDefaultState(), 0);
		this.setBlock(world, i + 6, j + 2, k + 8, KCore.BlueCondensedCloud.getDefaultState(), 0);
		this.setBlock(world, i + 6, j + 2, k + 9, KCore.BlueCondensedCloud.getDefaultState(), 0);
		this.setBlock(world, i + 6, j + 2, k + 10, KCore.BlueCondensedCloud.getDefaultState(), 0);
		this.setBlock(world, i + 6, j + 2, k + 11, KCore.BlueCondensedCloud.getDefaultState(), 0);
		this.setBlock(world, i + 6, j + 2, k + 12, KCore.BlueCondensedCloud.getDefaultState(), 0);
		this.setBlock(world, i + 6, j + 2, k + 13, KCore.BlueCondensedCloud.getDefaultState(), 0);
		this.setBlock(world, i + 6, j + 2, k + 14, KCore.BlueCondensedCloud.getDefaultState(), 0);
		this.setBlock(world, i + 6, j + 3, k + 3, KCore.BlueCloudBricks.getDefaultState(), 0);
		this.setBlock(world, i + 6, j + 3, k + 4, KCore.YellowCloudBlock.getDefaultState(), 0);
		this.setBlock(world, i + 6, j + 3, k + 5, KCore.YellowCloudBlock.getDefaultState(), 0);
		this.setBlock(world, i + 6, j + 3, k + 6, KCore.YellowCloudBlock.getDefaultState(), 0);
		this.setBlock(world, i + 6, j + 3, k + 7, KCore.YellowCloudBlock.getDefaultState(), 0);
		this.setBlock(world, i + 6, j + 3, k + 8, KCore.YellowCloudBlock.getDefaultState(), 0);
		this.setBlock(world, i + 6, j + 3, k + 9, KCore.YellowCloudBlock.getDefaultState(), 0);
		this.setBlock(world, i + 6, j + 3, k + 10, KCore.YellowCloudBlock.getDefaultState(), 0);
		this.setBlock(world, i + 6, j + 3, k + 11, KCore.YellowCloudBlock.getDefaultState(), 0);
		this.setBlock(world, i + 6, j + 3, k + 12, KCore.YellowCloudBlock.getDefaultState(), 0);
		this.setBlock(world, i + 6, j + 3, k + 13, KCore.BlueCloudBricks.getDefaultState(), 0);
		this.setBlock(world, i + 6, j + 7, k + 3, KCore.BlueCloudBricks.getDefaultState(), 0);
		this.setBlock(world, i + 6, j + 7, k + 4, KCore.BlueCloudBricks.getDefaultState(), 0);
		this.setBlock(world, i + 6, j + 7, k + 13, KCore.BlueCloudBricks.getDefaultState(), 0);
		this.setBlock(world, i + 6, j + 7, k + 14, KCore.BlueCloudBricks.getDefaultState(), 0);
		this.setBlock(world, i + 6, j + 8, k + 4, KCore.BlueCloudBricks.getDefaultState(), 0);
		this.setBlock(world, i + 6, j + 8, k + 13, KCore.BlueCloudBricks.getDefaultState(), 0);
		this.setBlock(world, i + 6, j + 9, k + 5, KCore.BlueCloudBricks.getDefaultState(), 0);
		this.setBlock(world, i + 6, j + 9, k + 6, KCore.BlueCloudBricks.getDefaultState(), 0);
		this.setBlock(world, i + 6, j + 9, k + 7, KCore.BlueCloudBricks.getDefaultState(), 0);
		this.setBlock(world, i + 6, j + 9, k + 8, KCore.BlueCloudBricks.getDefaultState(), 0);
		this.setBlock(world, i + 6, j + 9, k + 9, KCore.BlueCloudBricks.getDefaultState(), 0);
		this.setBlock(world, i + 6, j + 9, k + 10, KCore.BlueCloudBricks.getDefaultState(), 0);
		this.setBlock(world, i + 6, j + 9, k + 11, KCore.BlueCloudBricks.getDefaultState(), 0);
		this.setBlock(world, i + 6, j + 9, k + 12, KCore.BlueCloudBricks.getDefaultState(), 0);
		this.setBlock(world, i + 7, j + 0, k + 1, KCore.BlueCloud.getDefaultState(), 0);
		this.setBlock(world, i + 7, j + 0, k + 2, KCore.BlueCloud.getDefaultState(), 0);
		this.setBlock(world, i + 7, j + 0, k + 3, KCore.BlueCloud.getDefaultState(), 0);
		this.setBlock(world, i + 7, j + 0, k + 4, KCore.BlueCloud.getDefaultState(), 0);
		this.setBlock(world, i + 7, j + 0, k + 5, KCore.BlueCloud.getDefaultState(), 0);
		this.setBlock(world, i + 7, j + 0, k + 6, KCore.BlueCloud.getDefaultState(), 0);
		this.setBlock(world, i + 7, j + 0, k + 7, KCore.BlueCloud.getDefaultState(), 0);
		this.setBlock(world, i + 7, j + 0, k + 8, KCore.BlueCloud.getDefaultState(), 0);
		this.setBlock(world, i + 7, j + 0, k + 9, KCore.BlueCloud.getDefaultState(), 0);
		this.setBlock(world, i + 7, j + 0, k + 10, KCore.BlueCloud.getDefaultState(), 0);
		this.setBlock(world, i + 7, j + 0, k + 11, KCore.BlueCloud.getDefaultState(), 0);
		this.setBlock(world, i + 7, j + 0, k + 12, KCore.BlueCloud.getDefaultState(), 0);
		this.setBlock(world, i + 7, j + 0, k + 13, KCore.BlueCloud.getDefaultState(), 0);
		this.setBlock(world, i + 7, j + 0, k + 14, KCore.BlueCloud.getDefaultState(), 0);
		this.setBlock(world, i + 7, j + 0, k + 15, KCore.BlueCloud.getDefaultState(), 0);
		this.setBlock(world, i + 7, j + 0, k + 16, KCore.BlueCloud.getDefaultState(), 0);
		this.setBlock(world, i + 7, j + 1, k + 2, KCore.BlueCloud.getDefaultState(), 0);
		this.setBlock(world, i + 7, j + 1, k + 3, KCore.BlueCloud.getDefaultState(), 0);
		this.setBlock(world, i + 7, j + 1, k + 4, KCore.BlueCloud.getDefaultState(), 0);
		this.setBlock(world, i + 7, j + 1, k + 5, KCore.BlueCloud.getDefaultState(), 0);
		this.setBlock(world, i + 7, j + 1, k + 6, KCore.BlueCloud.getDefaultState(), 0);
		this.setBlock(world, i + 7, j + 1, k + 7, KCore.BlueCloud.getDefaultState(), 0);
		this.setBlock(world, i + 7, j + 1, k + 8, KCore.BlueCloud.getDefaultState(), 0);
		this.setBlock(world, i + 7, j + 1, k + 9, KCore.BlueCloud.getDefaultState(), 0);
		this.setBlock(world, i + 7, j + 1, k + 10, KCore.BlueCloud.getDefaultState(), 0);
		this.setBlock(world, i + 7, j + 1, k + 11, KCore.BlueCloud.getDefaultState(), 0);
		this.setBlock(world, i + 7, j + 1, k + 12, KCore.BlueCloud.getDefaultState(), 0);
		this.setBlock(world, i + 7, j + 1, k + 13, KCore.BlueCloud.getDefaultState(), 0);
		this.setBlock(world, i + 7, j + 1, k + 14, KCore.BlueCloud.getDefaultState(), 0);
		this.setBlock(world, i + 7, j + 1, k + 15, KCore.BlueCloud.getDefaultState(), 0);
		this.setBlock(world, i + 7, j + 1, k + 16, KCore.BlueCloud.getDefaultState(), 0);
		this.setBlock(world, i + 7, j + 2, k + 3, KCore.BlueCondensedCloud.getDefaultState(), 0);
		this.setBlock(world, i + 7, j + 2, k + 4, KCore.BlueCondensedCloud.getDefaultState(), 0);
		this.setBlock(world, i + 7, j + 2, k + 5, KCore.BlueCondensedCloud.getDefaultState(), 0);
		this.setBlock(world, i + 7, j + 2, k + 6, KCore.BlueCondensedCloud.getDefaultState(), 0);
		this.setBlock(world, i + 7, j + 2, k + 7, KCore.BlueCondensedCloud.getDefaultState(), 0);
		this.setBlock(world, i + 7, j + 2, k + 8, KCore.BlueCondensedCloud.getDefaultState(), 0);
		this.setBlock(world, i + 7, j + 2, k + 9, KCore.BlueCondensedCloud.getDefaultState(), 0);
		this.setBlock(world, i + 7, j + 2, k + 10, KCore.BlueCondensedCloud.getDefaultState(), 0);
		this.setBlock(world, i + 7, j + 2, k + 11, KCore.BlueCondensedCloud.getDefaultState(), 0);
		this.setBlock(world, i + 7, j + 2, k + 12, KCore.BlueCondensedCloud.getDefaultState(), 0);
		this.setBlock(world, i + 7, j + 2, k + 13, KCore.BlueCondensedCloud.getDefaultState(), 0);
		this.setBlock(world, i + 7, j + 2, k + 14, KCore.BlueCondensedCloud.getDefaultState(), 0);
		this.setBlock(world, i + 7, j + 2, k + 15, KCore.BlueCondensedCloud.getDefaultState(), 0);
		this.setBlock(world, i + 7, j + 3, k + 4, KCore.BlueCloudBricks.getDefaultState(), 0);
		this.setBlock(world, i + 7, j + 3, k + 5, KCore.YellowCloudBlock.getDefaultState(), 0);
		this.setBlock(world, i + 7, j + 3, k + 6, KCore.YellowCloudBlock.getDefaultState(), 0);
		this.setBlock(world, i + 7, j + 3, k + 7, KCore.YellowCloudBlock.getDefaultState(), 0);
		this.setBlock(world, i + 7, j + 3, k + 8, KCore.YellowCloudBlock.getDefaultState(), 0);
		this.setBlock(world, i + 7, j + 3, k + 9, KCore.YellowCloudBlock.getDefaultState(), 0);
		this.setBlock(world, i + 7, j + 3, k + 10, KCore.YellowCloudBlock.getDefaultState(), 0);
		this.setBlock(world, i + 7, j + 3, k + 11, KCore.YellowCloudBlock.getDefaultState(), 0);
		this.setBlock(world, i + 7, j + 3, k + 12, KCore.YellowCloudBlock.getDefaultState(), 0);
		this.setBlock(world, i + 7, j + 3, k + 13, KCore.BlueCloudBricks.getDefaultState(), 0);
		this.setBlock(world, i + 7, j + 4, k + 4, KCore.BlueCloudBricks.getDefaultState(), 0);
		this.setBlock(world, i + 7, j + 4, k + 5, Blocks.CHEST.getDefaultState(), 3);
		te=world.getTileEntity(new BlockPos(i+7,j+4,k+5));
		if(te!=null) {
		if(te instanceof TileEntityChest) {
			te=(TileEntityChest)world.getTileEntity(new BlockPos(i+7,j+4,k+5));
			for(int c=0;c<=rand.nextInt(10);c++) {
				ItemStack is=KCore.functionHelper.getCloudTempleReward();
				((TileEntityChest) te).setInventorySlotContents(1+rand.nextInt(9), is);
			}
		}
		}
		this.setBlock(world, i + 7, j + 4, k + 13, KCore.BlueCloudBricks.getDefaultState(), 0);
		this.setBlock(world, i + 7, j + 5, k + 4, KCore.BlueCloudBricks.getDefaultState(), 0);
		this.setBlock(world, i + 7, j + 5, k + 13, KCore.BlueCloudBricks.getDefaultState(), 0);
		this.setBlock(world, i + 7, j + 6, k + 4, KCore.BlueCloudBricks.getDefaultState(), 0);
		this.setBlock(world, i + 7, j + 6, k + 13, KCore.BlueCloudBricks.getDefaultState(), 0);
		this.setBlock(world, i + 7, j + 7, k + 3, KCore.BlueCloudBricks.getDefaultState(), 0);
		this.setBlock(world, i + 7, j + 7, k + 4, KCore.BlueCloudBricks.getDefaultState(), 0);
		this.setBlock(world, i + 7, j + 7, k + 13, KCore.BlueCloudBricks.getDefaultState(), 0);
		this.setBlock(world, i + 7, j + 7, k + 14, KCore.BlueCloudBricks.getDefaultState(), 0);
		this.setBlock(world, i + 7, j + 8, k + 4, KCore.BlueCloudBricks.getDefaultState(), 0);
		this.setBlock(world, i + 7, j + 8, k + 13, KCore.BlueCloudBricks.getDefaultState(), 0);
		this.setBlock(world, i + 7, j + 9, k + 5, KCore.BlueCloudBricks.getDefaultState(), 0);
		this.setBlock(world, i + 7, j + 9, k + 12, KCore.BlueCloudBricks.getDefaultState(), 0);
		this.setBlock(world, i + 7, j + 10, k + 6, KCore.BlueCloudBricks.getDefaultState(), 0);
		this.setBlock(world, i + 7, j + 10, k + 7, KCore.BlueCloudBricks.getDefaultState(), 0);
		this.setBlock(world, i + 7, j + 10, k + 8, KCore.BlueCloudBricks.getDefaultState(), 0);
		this.setBlock(world, i + 7, j + 10, k + 9, KCore.BlueCloudBricks.getDefaultState(), 0);
		this.setBlock(world, i + 7, j + 10, k + 10, KCore.BlueCloudBricks.getDefaultState(), 0);
		this.setBlock(world, i + 7, j + 10, k + 11, KCore.BlueCloudBricks.getDefaultState(), 0);
		this.setBlock(world, i + 8, j + 0, k + 1, KCore.BlueCloud.getDefaultState(), 0);
		this.setBlock(world, i + 8, j + 0, k + 2, KCore.BlueCloud.getDefaultState(), 0);
		this.setBlock(world, i + 8, j + 0, k + 3, KCore.BlueCloud.getDefaultState(), 0);
		this.setBlock(world, i + 8, j + 0, k + 4, KCore.BlueCloud.getDefaultState(), 0);
		this.setBlock(world, i + 8, j + 0, k + 5, KCore.BlueCloud.getDefaultState(), 0);
		this.setBlock(world, i + 8, j + 0, k + 6, KCore.BlueCloud.getDefaultState(), 0);
		this.setBlock(world, i + 8, j + 0, k + 7, KCore.BlueCloud.getDefaultState(), 0);
		this.setBlock(world, i + 8, j + 0, k + 8, KCore.BlueCloud.getDefaultState(), 0);
		this.setBlock(world, i + 8, j + 0, k + 9, KCore.BlueCloud.getDefaultState(), 0);
		this.setBlock(world, i + 8, j + 0, k + 10, KCore.BlueCloud.getDefaultState(), 0);
		this.setBlock(world, i + 8, j + 0, k + 11, KCore.BlueCloud.getDefaultState(), 0);
		this.setBlock(world, i + 8, j + 0, k + 12, KCore.BlueCloud.getDefaultState(), 0);
		this.setBlock(world, i + 8, j + 0, k + 13, KCore.BlueCloud.getDefaultState(), 0);
		this.setBlock(world, i + 8, j + 0, k + 14, KCore.BlueCloud.getDefaultState(), 0);
		this.setBlock(world, i + 8, j + 0, k + 15, KCore.BlueCloud.getDefaultState(), 0);
		this.setBlock(world, i + 8, j + 1, k + 2, KCore.BlueCloud.getDefaultState(), 0);
		this.setBlock(world, i + 8, j + 1, k + 3, KCore.BlueCloud.getDefaultState(), 0);
		this.setBlock(world, i + 8, j + 1, k + 4, KCore.BlueCloud.getDefaultState(), 0);
		this.setBlock(world, i + 8, j + 1, k + 5, KCore.BlueCloud.getDefaultState(), 0);
		this.setBlock(world, i + 8, j + 1, k + 6, KCore.BlueCloud.getDefaultState(), 0);
		this.setBlock(world, i + 8, j + 1, k + 7, KCore.BlueCloud.getDefaultState(), 0);
		this.setBlock(world, i + 8, j + 1, k + 8, KCore.BlueCloud.getDefaultState(), 0);
		this.setBlock(world, i + 8, j + 1, k + 9, KCore.BlueCloud.getDefaultState(), 0);
		this.setBlock(world, i + 8, j + 1, k + 10, KCore.BlueCloud.getDefaultState(), 0);
		this.setBlock(world, i + 8, j + 1, k + 11, KCore.BlueCloud.getDefaultState(), 0);
		this.setBlock(world, i + 8, j + 1, k + 12, KCore.BlueCloud.getDefaultState(), 0);
		this.setBlock(world, i + 8, j + 1, k + 13, KCore.BlueCloud.getDefaultState(), 0);
		this.setBlock(world, i + 8, j + 1, k + 14, KCore.BlueCloud.getDefaultState(), 0);
		this.setBlock(world, i + 8, j + 1, k + 15, KCore.BlueCloud.getDefaultState(), 0);
		this.setBlock(world, i + 8, j + 2, k + 3, KCore.BlueCondensedCloud.getDefaultState(), 0);
		this.setBlock(world, i + 8, j + 2, k + 4, KCore.BlueCondensedCloud.getDefaultState(), 0);
		this.setBlock(world, i + 8, j + 2, k + 5, KCore.BlueCondensedCloud.getDefaultState(), 0);
		this.setBlock(world, i + 8, j + 2, k + 6, KCore.BlueCondensedCloud.getDefaultState(), 0);
		this.setBlock(world, i + 8, j + 2, k + 7, KCore.BlueCondensedCloud.getDefaultState(), 0);
		this.setBlock(world, i + 8, j + 2, k + 8, KCore.ShinyRock.getDefaultState(), 0);
		this.setBlock(world, i + 8, j + 2, k + 9, KCore.ShinyRock.getDefaultState(), 0);
		this.setBlock(world, i + 8, j + 2, k + 10, KCore.ShinyRock.getDefaultState(), 0);
		this.setBlock(world, i + 8, j + 2, k + 11, KCore.BlueCondensedCloud.getDefaultState(), 0);
		this.setBlock(world, i + 8, j + 2, k + 12, KCore.BlueCondensedCloud.getDefaultState(), 0);
		this.setBlock(world, i + 8, j + 2, k + 13, KCore.BlueCondensedCloud.getDefaultState(), 0);
		this.setBlock(world, i + 8, j + 2, k + 14, KCore.BlueCondensedCloud.getDefaultState(), 0);
		this.setBlock(world, i + 8, j + 2, k + 15, KCore.BlueCondensedCloud.getDefaultState(), 0);
		this.setBlock(world, i + 8, j + 3, k + 4, KCore.BlueCloudBricks.getDefaultState(), 0);
		this.setBlock(world, i + 8, j + 3, k + 5, KCore.YellowCloudBlock.getDefaultState(), 0);
		this.setBlock(world, i + 8, j + 3, k + 6, KCore.YellowCloudBlock.getDefaultState(), 0);
		this.setBlock(world, i + 8, j + 3, k + 7, KCore.YellowCloudBlock.getDefaultState(), 0);
		this.setBlock(world, i + 8, j + 3, k + 8, Blocks.WATER.getDefaultState(), 0);
		this.setBlock(world, i + 8, j + 3, k + 9, Blocks.WATER.getDefaultState(), 0);
		this.setBlock(world, i + 8, j + 3, k + 10, Blocks.WATER.getDefaultState(), 0);
		this.setBlock(world, i + 8, j + 3, k + 11, KCore.YellowCloudBlock.getDefaultState(), 0);
		this.setBlock(world, i + 8, j + 3, k + 12, KCore.YellowCloudBlock.getDefaultState(), 0);
		this.setBlock(world, i + 8, j + 3, k + 13, KCore.BlueCloudBricks.getDefaultState(), 0);
		this.setBlock(world, i + 8, j + 7, k + 3, KCore.BlueCloudBricks.getDefaultState(), 0);
		this.setBlock(world, i + 8, j + 7, k + 4, KCore.BlueCloudBricks.getDefaultState(), 0);
		this.setBlock(world, i + 8, j + 7, k + 13, KCore.BlueCloudBricks.getDefaultState(), 0);
		this.setBlock(world, i + 8, j + 7, k + 14, KCore.BlueCloudBricks.getDefaultState(), 0);
		this.setBlock(world, i + 8, j + 8, k + 4, KCore.BlueCloudBricks.getDefaultState(), 0);
		this.setBlock(world, i + 8, j + 8, k + 13, KCore.BlueCloudBricks.getDefaultState(), 0);
		this.setBlock(world, i + 8, j + 9, k + 5, KCore.BlueCloudBricks.getDefaultState(), 0);
		this.setBlock(world, i + 8, j + 9, k + 12, KCore.BlueCloudBricks.getDefaultState(), 0);
		this.setBlock(world, i + 8, j + 10, k + 6, KCore.BlueCloudBricks.getDefaultState(), 0);
		this.setBlock(world, i + 8, j + 10, k + 7, KCore.BlueCloudBricks.getDefaultState(), 0);
		this.setBlock(world, i + 8, j + 10, k + 8, KCore.BlueCloudBricks.getDefaultState(), 0);
		this.setBlock(world, i + 8, j + 10, k + 9, KCore.BlueCloudBricks.getDefaultState(), 0);
		this.setBlock(world, i + 8, j + 10, k + 10, KCore.BlueCloudBricks.getDefaultState(), 0);
		this.setBlock(world, i + 8, j + 10, k + 11, KCore.BlueCloudBricks.getDefaultState(), 0);
		this.setBlock(world, i + 9, j + 0, k + 2, KCore.BlueCloud.getDefaultState(), 0);
		this.setBlock(world, i + 9, j + 0, k + 3, KCore.BlueCloud.getDefaultState(), 0);
		this.setBlock(world, i + 9, j + 0, k + 4, KCore.BlueCloud.getDefaultState(), 0);
		this.setBlock(world, i + 9, j + 0, k + 5, KCore.BlueCloud.getDefaultState(), 0);
		this.setBlock(world, i + 9, j + 0, k + 6, KCore.BlueCloud.getDefaultState(), 0);
		this.setBlock(world, i + 9, j + 0, k + 7, KCore.BlueCloud.getDefaultState(), 0);
		this.setBlock(world, i + 9, j + 0, k + 8, KCore.BlueCloud.getDefaultState(), 0);
		this.setBlock(world, i + 9, j + 0, k + 9, KCore.BlueCloud.getDefaultState(), 0);
		this.setBlock(world, i + 9, j + 0, k + 10, KCore.BlueCloud.getDefaultState(), 0);
		this.setBlock(world, i + 9, j + 0, k + 11, KCore.BlueCloud.getDefaultState(), 0);
		this.setBlock(world, i + 9, j + 0, k + 12, KCore.BlueCloud.getDefaultState(), 0);
		this.setBlock(world, i + 9, j + 0, k + 13, KCore.BlueCloud.getDefaultState(), 0);
		this.setBlock(world, i + 9, j + 0, k + 14, KCore.BlueCloud.getDefaultState(), 0);
		this.setBlock(world, i + 9, j + 0, k + 15, KCore.BlueCloud.getDefaultState(), 0);
		this.setBlock(world, i + 9, j + 0, k + 16, KCore.BlueCloud.getDefaultState(), 0);
		this.setBlock(world, i + 9, j + 1, k + 3, KCore.BlueCloud.getDefaultState(), 0);
		this.setBlock(world, i + 9, j + 1, k + 4, KCore.BlueCloud.getDefaultState(), 0);
		this.setBlock(world, i + 9, j + 1, k + 5, KCore.BlueCloud.getDefaultState(), 0);
		this.setBlock(world, i + 9, j + 1, k + 6, KCore.BlueCloud.getDefaultState(), 0);
		this.setBlock(world, i + 9, j + 1, k + 7, KCore.BlueCloud.getDefaultState(), 0);
		this.setBlock(world, i + 9, j + 1, k + 8, KCore.BlueCloud.getDefaultState(), 0);
		this.setBlock(world, i + 9, j + 1, k + 9, KCore.BlueCloud.getDefaultState(), 0);
		this.setBlock(world, i + 9, j + 1, k + 10, KCore.BlueCloud.getDefaultState(), 0);
		this.setBlock(world, i + 9, j + 1, k + 11, KCore.BlueCloud.getDefaultState(), 0);
		this.setBlock(world, i + 9, j + 1, k + 12, KCore.BlueCloud.getDefaultState(), 0);
		this.setBlock(world, i + 9, j + 1, k + 13, KCore.BlueCloud.getDefaultState(), 0);
		this.setBlock(world, i + 9, j + 1, k + 14, KCore.BlueCloud.getDefaultState(), 0);
		this.setBlock(world, i + 9, j + 1, k + 15, KCore.BlueCloud.getDefaultState(), 0);
		this.setBlock(world, i + 9, j + 2, k + 4, KCore.BlueCondensedCloud.getDefaultState(), 0);
		this.setBlock(world, i + 9, j + 2, k + 5, KCore.BlueCondensedCloud.getDefaultState(), 0);
		this.setBlock(world, i + 9, j + 2, k + 6, KCore.BlueCondensedCloud.getDefaultState(), 0);
		this.setBlock(world, i + 9, j + 2, k + 7, KCore.BlueCondensedCloud.getDefaultState(), 0);
		this.setBlock(world, i + 9, j + 2, k + 8, KCore.ShinyRock.getDefaultState(), 0);
		this.setBlock(world, i + 9, j + 2, k + 9, KCore.ShinyRock.getDefaultState(), 0);
		this.setBlock(world, i + 9, j + 2, k + 10, KCore.ShinyRock.getDefaultState(), 0);
		this.setBlock(world, i + 9, j + 2, k + 11, KCore.BlueCondensedCloud.getDefaultState(), 0);
		this.setBlock(world, i + 9, j + 2, k + 12, KCore.BlueCondensedCloud.getDefaultState(), 0);
		this.setBlock(world, i + 9, j + 2, k + 13, KCore.BlueCondensedCloud.getDefaultState(), 0);
		this.setBlock(world, i + 9, j + 2, k + 14, KCore.BlueCondensedCloud.getDefaultState(), 0);
		this.setBlock(world, i + 9, j + 2, k + 15, KCore.BlueCondensedCloud.getDefaultState(), 0);
		this.setBlock(world, i + 9, j + 3, k + 4, KCore.BlueCloudBricks.getDefaultState(), 0);
		this.setBlock(world, i + 9, j + 3, k + 5, KCore.YellowCloudBlock.getDefaultState(), 0);
		this.setBlock(world, i + 9, j + 3, k + 6, KCore.YellowCloudBlock.getDefaultState(), 0);
		this.setBlock(world, i + 9, j + 3, k + 7, KCore.YellowCloudBlock.getDefaultState(), 0);
		this.setBlock(world, i + 9, j + 3, k + 8, Blocks.WATER.getDefaultState(), 0);
		this.setBlock(world, i + 9, j + 3, k + 9, KCore.ShinyRock.getDefaultState(), 0);
		this.setBlock(world, i + 9, j + 3, k + 10, Blocks.WATER.getDefaultState(), 0);
		this.setBlock(world, i + 9, j + 3, k + 11, KCore.YellowCloudBlock.getDefaultState(), 0);
		this.setBlock(world, i + 9, j + 3, k + 12, KCore.YellowCloudBlock.getDefaultState(), 0);
		this.setBlock(world, i + 9, j + 3, k + 13, KCore.YellowCloudBlock.getDefaultState(), 0);
		this.setBlock(world, i + 9, j + 3, k + 14, KCore.BlueCloudBricks.getDefaultState(), 0);
		this.setBlock(world, i + 9, j + 4, k + 4, KCore.BlueCloudBricks.getDefaultState(), 0);
		this.setBlock(world, i + 9, j + 4, k + 9, KCore.ShinyRock.getDefaultState(), 0);
		this.setBlock(world, i + 9, j + 4, k + 13, KCore.BlueCloudBricks.getDefaultState(), 0);
		this.setBlock(world, i + 9, j + 5, k + 4, KCore.BlueCloudBricks.getDefaultState(), 0);
		this.setBlock(world, i + 9, j + 5, k + 9, KCore.ShinyRock.getDefaultState(), 0);
		this.setBlock(world, i + 9, j + 5, k + 13, KCore.BlueCloudBricks.getDefaultState(), 0);
		this.setBlock(world, i + 9, j + 6, k + 4, KCore.BlueCloudBricks.getDefaultState(), 0);
		this.setBlock(world, i + 9, j + 6, k + 9, KCore.ShinyRock.getDefaultState(), 0);
		this.setBlock(world, i + 9, j + 6, k + 13, KCore.BlueCloudBricks.getDefaultState(), 0);
		this.setBlock(world, i + 9, j + 7, k + 3, KCore.BlueCloudBricks.getDefaultState(), 0);
		this.setBlock(world, i + 9, j + 7, k + 4, KCore.BlueCloudBricks.getDefaultState(), 0);
		this.setBlock(world, i + 9, j + 7, k + 9, KCore.ShinyRock.getDefaultState(), 0);
		this.setBlock(world, i + 9, j + 7, k + 13, KCore.BlueCloudBricks.getDefaultState(), 0);
		this.setBlock(world, i + 9, j + 7, k + 14, KCore.BlueCloudBricks.getDefaultState(), 0);
		this.setBlock(world, i + 9, j + 8, k + 4, KCore.BlueCloudBricks.getDefaultState(), 0);
		this.setBlock(world, i + 9, j + 8, k + 9, Blocks.WATER.getDefaultState(), 0);
		this.setBlock(world, i + 9, j + 8, k + 13, KCore.BlueCloudBricks.getDefaultState(), 0);
		this.setBlock(world, i + 9, j + 9, k + 5, KCore.BlueCloudBricks.getDefaultState(), 0);
		this.setBlock(world, i + 9, j + 9, k + 6, KCore.BlueCloudBricks.getDefaultState(), 0);
		this.setBlock(world, i + 9, j + 9, k + 7, KCore.BlueCloudBricks.getDefaultState(), 0);
		this.setBlock(world, i + 9, j + 9, k + 12, KCore.BlueCloudBricks.getDefaultState(), 0);
		this.setBlock(world, i + 9, j + 10, k + 8, KCore.BlueCloudBricks.getDefaultState(), 0);
		this.setBlock(world, i + 9, j + 10, k + 9, KCore.BlueCloudBricks.getDefaultState(), 0);
		this.setBlock(world, i + 9, j + 10, k + 10, KCore.BlueCloudBricks.getDefaultState(), 0);
		this.setBlock(world, i + 9, j + 10, k + 11, KCore.BlueCloudBricks.getDefaultState(), 0);
		this.setBlock(world, i + 10, j + 0, k + 3, KCore.BlueCloud.getDefaultState(), 0);
		this.setBlock(world, i + 10, j + 0, k + 4, KCore.BlueCloud.getDefaultState(), 0);
		this.setBlock(world, i + 10, j + 0, k + 5, KCore.BlueCloud.getDefaultState(), 0);
		this.setBlock(world, i + 10, j + 0, k + 6, KCore.BlueCloud.getDefaultState(), 0);
		this.setBlock(world, i + 10, j + 0, k + 7, KCore.BlueCloud.getDefaultState(), 0);
		this.setBlock(world, i + 10, j + 0, k + 8, KCore.BlueCloud.getDefaultState(), 0);
		this.setBlock(world, i + 10, j + 0, k + 9, KCore.BlueCloud.getDefaultState(), 0);
		this.setBlock(world, i + 10, j + 0, k + 10, KCore.BlueCloud.getDefaultState(), 0);
		this.setBlock(world, i + 10, j + 0, k + 11, KCore.BlueCloud.getDefaultState(), 0);
		this.setBlock(world, i + 10, j + 0, k + 12, KCore.BlueCloud.getDefaultState(), 0);
		this.setBlock(world, i + 10, j + 0, k + 13, KCore.BlueCloud.getDefaultState(), 0);
		this.setBlock(world, i + 10, j + 0, k + 14, KCore.BlueCloud.getDefaultState(), 0);
		this.setBlock(world, i + 10, j + 0, k + 15, KCore.BlueCloud.getDefaultState(), 0);
		this.setBlock(world, i + 10, j + 0, k + 16, KCore.BlueCloud.getDefaultState(), 0);
		this.setBlock(world, i + 10, j + 0, k + 17, KCore.BlueCloud.getDefaultState(), 0);
		this.setBlock(world, i + 10, j + 0, k + 18, KCore.BlueCloud.getDefaultState(), 0);
		this.setBlock(world, i + 10, j + 1, k + 4, KCore.BlueCloud.getDefaultState(), 0);
		this.setBlock(world, i + 10, j + 1, k + 5, KCore.BlueCloud.getDefaultState(), 0);
		this.setBlock(world, i + 10, j + 1, k + 6, KCore.BlueCloud.getDefaultState(), 0);
		this.setBlock(world, i + 10, j + 1, k + 7, KCore.BlueCloud.getDefaultState(), 0);
		this.setBlock(world, i + 10, j + 1, k + 8, KCore.BlueCloud.getDefaultState(), 0);
		this.setBlock(world, i + 10, j + 1, k + 9, KCore.BlueCloud.getDefaultState(), 0);
		this.setBlock(world, i + 10, j + 1, k + 10, KCore.BlueCloud.getDefaultState(), 0);
		this.setBlock(world, i + 10, j + 1, k + 11, KCore.BlueCloud.getDefaultState(), 0);
		this.setBlock(world, i + 10, j + 1, k + 12, KCore.BlueCloud.getDefaultState(), 0);
		this.setBlock(world, i + 10, j + 1, k + 13, KCore.BlueCloud.getDefaultState(), 0);
		this.setBlock(world, i + 10, j + 1, k + 14, KCore.BlueCloud.getDefaultState(), 0);
		this.setBlock(world, i + 10, j + 1, k + 15, KCore.BlueCloud.getDefaultState(), 0);
		this.setBlock(world, i + 10, j + 1, k + 16, KCore.BlueCloud.getDefaultState(), 0);
		this.setBlock(world, i + 10, j + 1, k + 17, KCore.BlueCloud.getDefaultState(), 0);
		this.setBlock(world, i + 10, j + 2, k + 5, KCore.BlueCondensedCloud.getDefaultState(), 0);
		this.setBlock(world, i + 10, j + 2, k + 6, KCore.BlueCondensedCloud.getDefaultState(), 0);
		this.setBlock(world, i + 10, j + 2, k + 7, KCore.BlueCondensedCloud.getDefaultState(), 0);
		this.setBlock(world, i + 10, j + 2, k + 8, KCore.ShinyRock.getDefaultState(), 0);
		this.setBlock(world, i + 10, j + 2, k + 9, KCore.ShinyRock.getDefaultState(), 0);
		this.setBlock(world, i + 10, j + 2, k + 10, KCore.ShinyRock.getDefaultState(), 0);
		this.setBlock(world, i + 10, j + 2, k + 11, KCore.BlueCondensedCloud.getDefaultState(), 0);
		this.setBlock(world, i + 10, j + 2, k + 12, KCore.BlueCondensedCloud.getDefaultState(), 0);
		this.setBlock(world, i + 10, j + 2, k + 13, KCore.BlueCondensedCloud.getDefaultState(), 0);
		this.setBlock(world, i + 10, j + 2, k + 14, KCore.BlueCondensedCloud.getDefaultState(), 0);
		this.setBlock(world, i + 10, j + 2, k + 15, KCore.BlueCondensedCloud.getDefaultState(), 0);
		this.setBlock(world, i + 10, j + 2, k + 16, KCore.BlueCondensedCloud.getDefaultState(), 0);
		this.setBlock(world, i + 10, j + 2, k + 17, KCore.BlueCondensedCloud.getDefaultState(), 0);
		this.setBlock(world, i + 10, j + 3, k + 5, KCore.BlueCloudBricks.getDefaultState(), 0);
		this.setBlock(world, i + 10, j + 3, k + 6, KCore.YellowCloudBlock.getDefaultState(), 0);
		this.setBlock(world, i + 10, j + 3, k + 7, KCore.YellowCloudBlock.getDefaultState(), 0);
		this.setBlock(world, i + 10, j + 3, k + 8, Blocks.WATER.getDefaultState(), 0);
		this.setBlock(world, i + 10, j + 3, k + 9, Blocks.WATER.getDefaultState(), 0);
		this.setBlock(world, i + 10, j + 3, k + 10, Blocks.WATER.getDefaultState(), 0);
		this.setBlock(world, i + 10, j + 3, k + 11, KCore.YellowCloudBlock.getDefaultState(), 0);
		this.setBlock(world, i + 10, j + 3, k + 12, KCore.YellowCloudBlock.getDefaultState(), 0);
		this.setBlock(world, i + 10, j + 3, k + 13, KCore.YellowCloudBlock.getDefaultState(), 0);
		this.setBlock(world, i + 10, j + 3, k + 14, KCore.YellowCloudBlock.getDefaultState(), 0);
		this.setBlock(world, i + 10, j + 3, k + 15, KCore.BlueCloudBricks.getDefaultState(), 0);
		this.setBlock(world, i + 10, j + 4, k + 6, KCore.BlueCloudBricks.getDefaultState(), 0);
		this.setBlock(world, i + 10, j + 5, k + 6, KCore.BlueCloudBricks.getDefaultState(), 0);
		this.setBlock(world, i + 10, j + 6, k + 6, KCore.BlueCloudBricks.getDefaultState(), 0);
		this.setBlock(world, i + 10, j + 7, k + 3, KCore.BlueCloudBricks.getDefaultState(), 0);
		this.setBlock(world, i + 10, j + 7, k + 4, KCore.BlueCloudBricks.getDefaultState(), 0);
		this.setBlock(world, i + 10, j + 7, k + 5, KCore.BlueCloudBricks.getDefaultState(), 0);
		this.setBlock(world, i + 10, j + 7, k + 6, KCore.BlueCloudBricks.getDefaultState(), 0);
		this.setBlock(world, i + 10, j + 7, k + 13, KCore.BlueCloudBricks.getDefaultState(), 0);
		this.setBlock(world, i + 10, j + 7, k + 14, KCore.BlueCloudBricks.getDefaultState(), 0);
		this.setBlock(world, i + 10, j + 7, k + 15, KCore.BlueCloudBricks.getDefaultState(), 0);
		this.setBlock(world, i + 10, j + 8, k + 4, KCore.BlueCloudBricks.getDefaultState(), 0);
		this.setBlock(world, i + 10, j + 8, k + 5, KCore.BlueCloudBricks.getDefaultState(), 0);
		this.setBlock(world, i + 10, j + 8, k + 6, KCore.BlueCloudBricks.getDefaultState(), 0);
		this.setBlock(world, i + 10, j + 8, k + 13, KCore.BlueCloudBricks.getDefaultState(), 0);
		this.setBlock(world, i + 10, j + 9, k + 7, KCore.BlueCloudBricks.getDefaultState(), 0);
		this.setBlock(world, i + 10, j + 9, k + 8, KCore.BlueCloudBricks.getDefaultState(), 0);
		this.setBlock(world, i + 10, j + 9, k + 12, KCore.BlueCloudBricks.getDefaultState(), 0);
		this.setBlock(world, i + 10, j + 10, k + 9, KCore.BlueCloudBricks.getDefaultState(), 0);
		this.setBlock(world, i + 10, j + 10, k + 10, KCore.BlueCloudBricks.getDefaultState(), 0);
		this.setBlock(world, i + 10, j + 10, k + 11, KCore.BlueCloudBricks.getDefaultState(), 0);
		this.setBlock(world, i + 11, j + 0, k + 3, KCore.BlueCloud.getDefaultState(), 0);
		this.setBlock(world, i + 11, j + 0, k + 4, KCore.BlueCloud.getDefaultState(), 0);
		this.setBlock(world, i + 11, j + 0, k + 5, KCore.BlueCloud.getDefaultState(), 0);
		this.setBlock(world, i + 11, j + 0, k + 6, KCore.BlueCloud.getDefaultState(), 0);
		this.setBlock(world, i + 11, j + 0, k + 7, KCore.BlueCloud.getDefaultState(), 0);
		this.setBlock(world, i + 11, j + 0, k + 8, KCore.BlueCloud.getDefaultState(), 0);
		this.setBlock(world, i + 11, j + 0, k + 9, KCore.BlueCloud.getDefaultState(), 0);
		this.setBlock(world, i + 11, j + 0, k + 10, KCore.BlueCloud.getDefaultState(), 0);
		this.setBlock(world, i + 11, j + 0, k + 11, KCore.BlueCloud.getDefaultState(), 0);
		this.setBlock(world, i + 11, j + 0, k + 12, KCore.BlueCloud.getDefaultState(), 0);
		this.setBlock(world, i + 11, j + 0, k + 13, KCore.BlueCloud.getDefaultState(), 0);
		this.setBlock(world, i + 11, j + 0, k + 14, KCore.BlueCloud.getDefaultState(), 0);
		this.setBlock(world, i + 11, j + 0, k + 15, KCore.BlueCloud.getDefaultState(), 0);
		this.setBlock(world, i + 11, j + 0, k + 16, KCore.BlueCloud.getDefaultState(), 0);
		this.setBlock(world, i + 11, j + 0, k + 17, KCore.BlueCloud.getDefaultState(), 0);
		this.setBlock(world, i + 11, j + 1, k + 5, KCore.BlueCloud.getDefaultState(), 0);
		this.setBlock(world, i + 11, j + 1, k + 6, KCore.BlueCloud.getDefaultState(), 0);
		this.setBlock(world, i + 11, j + 1, k + 7, KCore.BlueCloud.getDefaultState(), 0);
		this.setBlock(world, i + 11, j + 1, k + 8, KCore.BlueCloud.getDefaultState(), 0);
		this.setBlock(world, i + 11, j + 1, k + 9, KCore.BlueCloud.getDefaultState(), 0);
		this.setBlock(world, i + 11, j + 1, k + 10, KCore.BlueCloud.getDefaultState(), 0);
		this.setBlock(world, i + 11, j + 1, k + 11, KCore.BlueCloud.getDefaultState(), 0);
		this.setBlock(world, i + 11, j + 1, k + 12, KCore.BlueCloud.getDefaultState(), 0);
		this.setBlock(world, i + 11, j + 1, k + 13, KCore.BlueCloud.getDefaultState(), 0);
		this.setBlock(world, i + 11, j + 1, k + 14, KCore.BlueCloud.getDefaultState(), 0);
		this.setBlock(world, i + 11, j + 1, k + 15, KCore.BlueCloud.getDefaultState(), 0);
		this.setBlock(world, i + 11, j + 1, k + 16, KCore.BlueCloud.getDefaultState(), 0);
		this.setBlock(world, i + 11, j + 1, k + 17, KCore.BlueCloud.getDefaultState(), 0);
		this.setBlock(world, i + 11, j + 2, k + 6, KCore.BlueCondensedCloud.getDefaultState(), 0);
		this.setBlock(world, i + 11, j + 2, k + 7, KCore.BlueCondensedCloud.getDefaultState(), 0);
		this.setBlock(world, i + 11, j + 2, k + 8, KCore.BlueCondensedCloud.getDefaultState(), 0);
		this.setBlock(world, i + 11, j + 2, k + 9, KCore.BlueCondensedCloud.getDefaultState(), 0);
		this.setBlock(world, i + 11, j + 2, k + 10, KCore.BlueCondensedCloud.getDefaultState(), 0);
		this.setBlock(world, i + 11, j + 2, k + 11, KCore.BlueCondensedCloud.getDefaultState(), 0);
		this.setBlock(world, i + 11, j + 2, k + 12, KCore.BlueCondensedCloud.getDefaultState(), 0);
		this.setBlock(world, i + 11, j + 2, k + 13, KCore.BlueCondensedCloud.getDefaultState(), 0);
		this.setBlock(world, i + 11, j + 2, k + 14, KCore.BlueCondensedCloud.getDefaultState(), 0);
		this.setBlock(world, i + 11, j + 2, k + 15, KCore.BlueCondensedCloud.getDefaultState(), 0);
		this.setBlock(world, i + 11, j + 2, k + 16, KCore.BlueCondensedCloud.getDefaultState(), 0);
		this.setBlock(world, i + 11, j + 2, k + 17, KCore.BlueCondensedCloud.getDefaultState(), 0);
		this.setBlock(world, i + 11, j + 3, k + 6, KCore.BlueCloudBricks.getDefaultState(), 0);
		this.setBlock(world, i + 11, j + 3, k + 7, KCore.YellowCloudBlock.getDefaultState(), 0);
		this.setBlock(world, i + 11, j + 3, k + 8, KCore.YellowCloudBlock.getDefaultState(), 0);
		this.setBlock(world, i + 11, j + 3, k + 9, KCore.YellowCloudBlock.getDefaultState(), 0);
		this.setBlock(world, i + 11, j + 3, k + 10, KCore.YellowCloudBlock.getDefaultState(), 0);
		this.setBlock(world, i + 11, j + 3, k + 11, KCore.YellowCloudBlock.getDefaultState(), 0);
		this.setBlock(world, i + 11, j + 3, k + 12, KCore.YellowCloudBlock.getDefaultState(), 0);
		this.setBlock(world, i + 11, j + 3, k + 13, KCore.YellowCloudBlock.getDefaultState(), 0);
		this.setBlock(world, i + 11, j + 3, k + 14, KCore.YellowCloudBlock.getDefaultState(), 0);
		this.setBlock(world, i + 11, j + 3, k + 15, KCore.BlueCloudBricks.getDefaultState(), 0);
		this.setBlock(world, i + 11, j + 4, k + 14, KCore.BlueCloudBricks.getDefaultState(), 0);
		this.setBlock(world, i + 11, j + 5, k + 14, KCore.BlueCloudBricks.getDefaultState(), 0);
		this.setBlock(world, i + 11, j + 6, k + 14, KCore.BlueCloudBricks.getDefaultState(), 0);
		this.setBlock(world, i + 11, j + 7, k + 4, KCore.BlueCloudBricks.getDefaultState(), 0);
		this.setBlock(world, i + 11, j + 7, k + 5, KCore.BlueCloudBricks.getDefaultState(), 0);
		this.setBlock(world, i + 11, j + 7, k + 6, KCore.BlueCloudBricks.getDefaultState(), 0);
		this.setBlock(world, i + 11, j + 7, k + 7, KCore.BlueCloudBricks.getDefaultState(), 0);
		this.setBlock(world, i + 11, j + 7, k + 13, KCore.BlueCloudBricks.getDefaultState(), 0);
		this.setBlock(world, i + 11, j + 7, k + 14, KCore.BlueCloudBricks.getDefaultState(), 0);
		this.setBlock(world, i + 11, j + 7, k + 15, KCore.BlueCloudBricks.getDefaultState(), 0);
		this.setBlock(world, i + 11, j + 7, k + 16, KCore.BlueCloudBricks.getDefaultState(), 0);
		this.setBlock(world, i + 11, j + 8, k + 7, KCore.BlueCloudBricks.getDefaultState(), 0);
		this.setBlock(world, i + 11, j + 8, k + 13, KCore.BlueCloudBricks.getDefaultState(), 0);
		this.setBlock(world, i + 11, j + 8, k + 14, KCore.BlueCloudBricks.getDefaultState(), 0);
		this.setBlock(world, i + 11, j + 8, k + 15, KCore.BlueCloudBricks.getDefaultState(), 0);
		this.setBlock(world, i + 11, j + 9, k + 8, KCore.BlueCloudBricks.getDefaultState(), 0);
		this.setBlock(world, i + 11, j + 9, k + 9, KCore.BlueCloudBricks.getDefaultState(), 0);
		this.setBlock(world, i + 11, j + 9, k + 12, KCore.BlueCloudBricks.getDefaultState(), 0);
		this.setBlock(world, i + 11, j + 10, k + 10, KCore.BlueCloudBricks.getDefaultState(), 0);
		this.setBlock(world, i + 11, j + 10, k + 11, KCore.BlueCloudBricks.getDefaultState(), 0);
		this.setBlock(world, i + 12, j + 0, k + 5, KCore.BlueCloud.getDefaultState(), 0);
		this.setBlock(world, i + 12, j + 0, k + 6, KCore.BlueCloud.getDefaultState(), 0);
		this.setBlock(world, i + 12, j + 0, k + 7, KCore.BlueCloud.getDefaultState(), 0);
		this.setBlock(world, i + 12, j + 0, k + 8, KCore.BlueCloud.getDefaultState(), 0);
		this.setBlock(world, i + 12, j + 0, k + 9, KCore.BlueCloud.getDefaultState(), 0);
		this.setBlock(world, i + 12, j + 0, k + 10, KCore.BlueCloud.getDefaultState(), 0);
		this.setBlock(world, i + 12, j + 0, k + 11, KCore.BlueCloud.getDefaultState(), 0);
		this.setBlock(world, i + 12, j + 0, k + 12, KCore.BlueCloud.getDefaultState(), 0);
		this.setBlock(world, i + 12, j + 0, k + 13, KCore.BlueCloud.getDefaultState(), 0);
		this.setBlock(world, i + 12, j + 0, k + 14, KCore.BlueCloud.getDefaultState(), 0);
		this.setBlock(world, i + 12, j + 0, k + 15, KCore.BlueCloud.getDefaultState(), 0);
		this.setBlock(world, i + 12, j + 0, k + 16, KCore.BlueCloud.getDefaultState(), 0);
		this.setBlock(world, i + 12, j + 0, k + 17, KCore.BlueCloud.getDefaultState(), 0);
		this.setBlock(world, i + 12, j + 0, k + 18, KCore.BlueCloud.getDefaultState(), 0);
		this.setBlock(world, i + 12, j + 1, k + 5, KCore.BlueCloud.getDefaultState(), 0);
		this.setBlock(world, i + 12, j + 1, k + 6, KCore.BlueCloud.getDefaultState(), 0);
		this.setBlock(world, i + 12, j + 1, k + 7, KCore.BlueCloud.getDefaultState(), 0);
		this.setBlock(world, i + 12, j + 1, k + 8, KCore.BlueCloud.getDefaultState(), 0);
		this.setBlock(world, i + 12, j + 1, k + 9, KCore.BlueCloud.getDefaultState(), 0);
		this.setBlock(world, i + 12, j + 1, k + 10, KCore.BlueCloud.getDefaultState(), 0);
		this.setBlock(world, i + 12, j + 1, k + 11, KCore.BlueCloud.getDefaultState(), 0);
		this.setBlock(world, i + 12, j + 1, k + 12, KCore.BlueCloud.getDefaultState(), 0);
		this.setBlock(world, i + 12, j + 1, k + 13, KCore.BlueCloud.getDefaultState(), 0);
		this.setBlock(world, i + 12, j + 1, k + 14, KCore.BlueCloud.getDefaultState(), 0);
		this.setBlock(world, i + 12, j + 1, k + 15, KCore.BlueCloud.getDefaultState(), 0);
		this.setBlock(world, i + 12, j + 1, k + 16, KCore.BlueCloud.getDefaultState(), 0);
		this.setBlock(world, i + 12, j + 1, k + 17, KCore.BlueCloud.getDefaultState(), 0);
		this.setBlock(world, i + 12, j + 2, k + 6, KCore.BlueCondensedCloud.getDefaultState(), 0);
		this.setBlock(world, i + 12, j + 2, k + 7, KCore.BlueCondensedCloud.getDefaultState(), 0);
		this.setBlock(world, i + 12, j + 2, k + 8, KCore.BlueCondensedCloud.getDefaultState(), 0);
		this.setBlock(world, i + 12, j + 2, k + 9, KCore.BlueCondensedCloud.getDefaultState(), 0);
		this.setBlock(world, i + 12, j + 2, k + 10, KCore.BlueCondensedCloud.getDefaultState(), 0);
		this.setBlock(world, i + 12, j + 2, k + 11, KCore.BlueCondensedCloud.getDefaultState(), 0);
		this.setBlock(world, i + 12, j + 2, k + 12, KCore.BlueCondensedCloud.getDefaultState(), 0);
		this.setBlock(world, i + 12, j + 2, k + 13, KCore.BlueCondensedCloud.getDefaultState(), 0);
		this.setBlock(world, i + 12, j + 2, k + 14, KCore.BlueCondensedCloud.getDefaultState(), 0);
		this.setBlock(world, i + 12, j + 2, k + 15, KCore.BlueCondensedCloud.getDefaultState(), 0);
		this.setBlock(world, i + 12, j + 2, k + 16, KCore.BlueCondensedCloud.getDefaultState(), 0);
		this.setBlock(world, i + 12, j + 2, k + 17, KCore.BlueCondensedCloud.getDefaultState(), 0);
		this.setBlock(world, i + 12, j + 3, k + 7, KCore.BlueCloudBricks.getDefaultState(), 0);
		this.setBlock(world, i + 12, j + 3, k + 8, KCore.YellowCloudBlock.getDefaultState(), 0);
		this.setBlock(world, i + 12, j + 3, k + 9, KCore.YellowCloudBlock.getDefaultState(), 0);
		this.setBlock(world, i + 12, j + 3, k + 10, KCore.YellowCloudBlock.getDefaultState(), 0);
		this.setBlock(world, i + 12, j + 3, k + 11, KCore.YellowCloudBlock.getDefaultState(), 0);
		this.setBlock(world, i + 12, j + 3, k + 12, KCore.YellowCloudBlock.getDefaultState(), 0);
		this.setBlock(world, i + 12, j + 3, k + 13, KCore.YellowCloudBlock.getDefaultState(), 0);
		this.setBlock(world, i + 12, j + 3, k + 14, KCore.YellowCloudBlock.getDefaultState(), 0);
		this.setBlock(world, i + 12, j + 3, k + 15, KCore.YellowCloudBlock.getDefaultState(), 0);
		this.setBlock(world, i + 12, j + 3, k + 16, KCore.BlueCloudBricks.getDefaultState(), 0);
		this.setBlock(world, i + 12, j + 3, k + 17, KCore.BlueCloudBricks.getDefaultState(), 0);
		this.setBlock(world, i + 12, j + 4, k + 8, KCore.BlueCloudBricks.getDefaultState(), 0);
		this.setBlock(world, i + 12, j + 4, k + 10, Blocks.CHEST.getDefaultState(), 4);
		te=world.getTileEntity(new BlockPos(i+12,j+4,k+10));
		if(te!=null) {
		if(te instanceof TileEntityChest) {
			te=(TileEntityChest)world.getTileEntity(new BlockPos(i+12,j+4,k+10));
			for(int c=0;c<=rand.nextInt(10);c++) {
				ItemStack is=KCore.functionHelper.getCloudTempleReward();
				((TileEntityChest) te).setInventorySlotContents(1+rand.nextInt(9), is);
			}
		}
		}
		this.setBlock(world, i + 12, j + 5, k + 8, KCore.BlueCloudBricks.getDefaultState(), 0);
		this.setBlock(world, i + 12, j + 6, k + 8, KCore.BlueCloudBricks.getDefaultState(), 0);
		this.setBlock(world, i + 12, j + 7, k + 6, KCore.BlueCloudBricks.getDefaultState(), 0);
		this.setBlock(world, i + 12, j + 7, k + 7, KCore.BlueCloudBricks.getDefaultState(), 0);
		this.setBlock(world, i + 12, j + 7, k + 8, KCore.BlueCloudBricks.getDefaultState(), 0);
		this.setBlock(world, i + 12, j + 7, k + 15, KCore.BlueCloudBricks.getDefaultState(), 0);
		this.setBlock(world, i + 12, j + 7, k + 16, KCore.BlueCloudBricks.getDefaultState(), 0);
		this.setBlock(world, i + 12, j + 8, k + 8, KCore.BlueCloudBricks.getDefaultState(), 0);
		this.setBlock(world, i + 12, j + 8, k + 15, KCore.BlueCloudBricks.getDefaultState(), 0);
		this.setBlock(world, i + 12, j + 9, k + 9, KCore.BlueCloudBricks.getDefaultState(), 0);
		this.setBlock(world, i + 12, j + 9, k + 10, KCore.BlueCloudBricks.getDefaultState(), 0);
		this.setBlock(world, i + 12, j + 9, k + 11, KCore.BlueCloudBricks.getDefaultState(), 0);
		this.setBlock(world, i + 12, j + 9, k + 12, KCore.BlueCloudBricks.getDefaultState(), 0);
		this.setBlock(world, i + 12, j + 9, k + 13, KCore.BlueCloudBricks.getDefaultState(), 0);
		this.setBlock(world, i + 12, j + 9, k + 14, KCore.BlueCloudBricks.getDefaultState(), 0);
		this.setBlock(world, i + 13, j + 0, k + 6, KCore.BlueCloud.getDefaultState(), 0);
		this.setBlock(world, i + 13, j + 0, k + 7, KCore.BlueCloud.getDefaultState(), 0);
		this.setBlock(world, i + 13, j + 0, k + 8, KCore.BlueCloud.getDefaultState(), 0);
		this.setBlock(world, i + 13, j + 0, k + 9, KCore.BlueCloud.getDefaultState(), 0);
		this.setBlock(world, i + 13, j + 0, k + 10, KCore.BlueCloud.getDefaultState(), 0);
		this.setBlock(world, i + 13, j + 0, k + 11, KCore.BlueCloud.getDefaultState(), 0);
		this.setBlock(world, i + 13, j + 0, k + 12, KCore.BlueCloud.getDefaultState(), 0);
		this.setBlock(world, i + 13, j + 0, k + 13, KCore.BlueCloud.getDefaultState(), 0);
		this.setBlock(world, i + 13, j + 0, k + 14, KCore.BlueCloud.getDefaultState(), 0);
		this.setBlock(world, i + 13, j + 0, k + 15, KCore.BlueCloud.getDefaultState(), 0);
		this.setBlock(world, i + 13, j + 0, k + 16, KCore.BlueCloud.getDefaultState(), 0);
		this.setBlock(world, i + 13, j + 0, k + 17, KCore.BlueCloud.getDefaultState(), 0);
		this.setBlock(world, i + 13, j + 0, k + 18, KCore.BlueCloud.getDefaultState(), 0);
		this.setBlock(world, i + 13, j + 0, k + 19, KCore.BlueCloud.getDefaultState(), 0);
		this.setBlock(world, i + 13, j + 1, k + 6, KCore.BlueCloud.getDefaultState(), 0);
		this.setBlock(world, i + 13, j + 1, k + 7, KCore.BlueCloud.getDefaultState(), 0);
		this.setBlock(world, i + 13, j + 1, k + 8, KCore.BlueCloud.getDefaultState(), 0);
		this.setBlock(world, i + 13, j + 1, k + 9, KCore.BlueCloud.getDefaultState(), 0);
		this.setBlock(world, i + 13, j + 1, k + 10, KCore.BlueCloud.getDefaultState(), 0);
		this.setBlock(world, i + 13, j + 1, k + 11, KCore.BlueCloud.getDefaultState(), 0);
		this.setBlock(world, i + 13, j + 1, k + 12, KCore.BlueCloud.getDefaultState(), 0);
		this.setBlock(world, i + 13, j + 1, k + 13, KCore.BlueCloud.getDefaultState(), 0);
		this.setBlock(world, i + 13, j + 1, k + 14, KCore.BlueCloud.getDefaultState(), 0);
		this.setBlock(world, i + 13, j + 1, k + 15, KCore.BlueCloud.getDefaultState(), 0);
		this.setBlock(world, i + 13, j + 1, k + 16, KCore.BlueCloud.getDefaultState(), 0);
		this.setBlock(world, i + 13, j + 1, k + 17, KCore.BlueCloud.getDefaultState(), 0);
		this.setBlock(world, i + 13, j + 1, k + 18, KCore.BlueCloud.getDefaultState(), 0);
		this.setBlock(world, i + 13, j + 2, k + 7, KCore.BlueCondensedCloud.getDefaultState(), 0);
		this.setBlock(world, i + 13, j + 2, k + 8, KCore.BlueCondensedCloud.getDefaultState(), 0);
		this.setBlock(world, i + 13, j + 2, k + 9, KCore.BlueCondensedCloud.getDefaultState(), 0);
		this.setBlock(world, i + 13, j + 2, k + 10, KCore.BlueCondensedCloud.getDefaultState(), 0);
		this.setBlock(world, i + 13, j + 2, k + 11, KCore.BlueCondensedCloud.getDefaultState(), 0);
		this.setBlock(world, i + 13, j + 2, k + 12, KCore.BlueCondensedCloud.getDefaultState(), 0);
		this.setBlock(world, i + 13, j + 2, k + 13, KCore.BlueCondensedCloud.getDefaultState(), 0);
		this.setBlock(world, i + 13, j + 2, k + 14, KCore.BlueCondensedCloud.getDefaultState(), 0);
		this.setBlock(world, i + 13, j + 2, k + 15, KCore.BlueCondensedCloud.getDefaultState(), 0);
		this.setBlock(world, i + 13, j + 2, k + 16, KCore.BlueCondensedCloud.getDefaultState(), 0);
		this.setBlock(world, i + 13, j + 2, k + 17, KCore.BlueCondensedCloud.getDefaultState(), 0);
		this.setBlock(world, i + 13, j + 3, k + 8, KCore.BlueCloudBricks.getDefaultState(), 0);
		this.setBlock(world, i + 13, j + 3, k + 9, KCore.YellowCloudBlock.getDefaultState(), 0);
		this.setBlock(world, i + 13, j + 3, k + 10, KCore.YellowCloudBlock.getDefaultState(), 0);
		this.setBlock(world, i + 13, j + 3, k + 11, KCore.YellowCloudBlock.getDefaultState(), 0);
		this.setBlock(world, i + 13, j + 3, k + 12, KCore.YellowCloudBlock.getDefaultState(), 0);
		this.setBlock(world, i + 13, j + 3, k + 13, KCore.YellowCloudBlock.getDefaultState(), 0);
		this.setBlock(world, i + 13, j + 3, k + 14, KCore.YellowCloudBlock.getDefaultState(), 0);
		this.setBlock(world, i + 13, j + 3, k + 15, KCore.YellowCloudBlock.getDefaultState(), 0);
		this.setBlock(world, i + 13, j + 3, k + 16, KCore.YellowCloudBlock.getDefaultState(), 0);
		this.setBlock(world, i + 13, j + 3, k + 17, KCore.BlueCloudBricks.getDefaultState(), 0);
		this.setBlock(world, i + 13, j + 4, k + 10, KCore.BlueCloudBricks.getDefaultState(), 0);
		this.setBlock(world, i + 13, j + 4, k + 15, KCore.BlueCloudBricks.getDefaultState(), 0);
		this.setBlock(world, i + 13, j + 5, k + 10, KCore.BlueCloudBricks.getDefaultState(), 0);
		this.setBlock(world, i + 13, j + 5, k + 15, KCore.BlueCloudBricks.getDefaultState(), 0);
		this.setBlock(world, i + 13, j + 6, k + 10, KCore.BlueCloudBricks.getDefaultState(), 0);
		this.setBlock(world, i + 13, j + 6, k + 15, KCore.BlueCloudBricks.getDefaultState(), 0);
		this.setBlock(world, i + 13, j + 7, k + 7, KCore.BlueCloudBricks.getDefaultState(), 0);
		this.setBlock(world, i + 13, j + 7, k + 8, KCore.BlueCloudBricks.getDefaultState(), 0);
		this.setBlock(world, i + 13, j + 7, k + 9, KCore.BlueCloudBricks.getDefaultState(), 0);
		this.setBlock(world, i + 13, j + 7, k + 10, KCore.BlueCloudBricks.getDefaultState(), 0);
		this.setBlock(world, i + 13, j + 7, k + 15, KCore.BlueCloudBricks.getDefaultState(), 0);
		this.setBlock(world, i + 13, j + 7, k + 16, KCore.BlueCloudBricks.getDefaultState(), 0);
		this.setBlock(world, i + 13, j + 8, k + 9, KCore.BlueCloudBricks.getDefaultState(), 0);
		this.setBlock(world, i + 13, j + 8, k + 10, KCore.BlueCloudBricks.getDefaultState(), 0);
		this.setBlock(world, i + 13, j + 8, k + 15, KCore.BlueCloudBricks.getDefaultState(), 0);
		this.setBlock(world, i + 13, j + 9, k + 11, KCore.BlueCloudBricks.getDefaultState(), 0);
		this.setBlock(world, i + 13, j + 9, k + 12, KCore.BlueCloudBricks.getDefaultState(), 0);
		this.setBlock(world, i + 13, j + 9, k + 13, KCore.BlueCloudBricks.getDefaultState(), 0);
		this.setBlock(world, i + 13, j + 9, k + 14, KCore.BlueCloudBricks.getDefaultState(), 0);
		this.setBlock(world, i + 14, j + 0, k + 6, KCore.BlueCloud.getDefaultState(), 0);
		this.setBlock(world, i + 14, j + 0, k + 7, KCore.BlueCloud.getDefaultState(), 0);
		this.setBlock(world, i + 14, j + 0, k + 8, KCore.BlueCloud.getDefaultState(), 0);
		this.setBlock(world, i + 14, j + 0, k + 9, KCore.BlueCloud.getDefaultState(), 0);
		this.setBlock(world, i + 14, j + 0, k + 10, KCore.BlueCloud.getDefaultState(), 0);
		this.setBlock(world, i + 14, j + 0, k + 11, KCore.BlueCloud.getDefaultState(), 0);
		this.setBlock(world, i + 14, j + 0, k + 12, KCore.BlueCloud.getDefaultState(), 0);
		this.setBlock(world, i + 14, j + 0, k + 13, KCore.BlueCloud.getDefaultState(), 0);
		this.setBlock(world, i + 14, j + 0, k + 14, KCore.BlueCloud.getDefaultState(), 0);
		this.setBlock(world, i + 14, j + 0, k + 15, KCore.BlueCloud.getDefaultState(), 0);
		this.setBlock(world, i + 14, j + 0, k + 16, KCore.BlueCloud.getDefaultState(), 0);
		this.setBlock(world, i + 14, j + 0, k + 17, KCore.BlueCloud.getDefaultState(), 0);
		this.setBlock(world, i + 14, j + 0, k + 18, KCore.BlueCloud.getDefaultState(), 0);
		this.setBlock(world, i + 14, j + 0, k + 19, KCore.BlueCloud.getDefaultState(), 0);
		this.setBlock(world, i + 14, j + 0, k + 20, KCore.BlueCloud.getDefaultState(), 0);
		this.setBlock(world, i + 14, j + 1, k + 7, KCore.BlueCloud.getDefaultState(), 0);
		this.setBlock(world, i + 14, j + 1, k + 8, KCore.BlueCloud.getDefaultState(), 0);
		this.setBlock(world, i + 14, j + 1, k + 9, KCore.BlueCloud.getDefaultState(), 0);
		this.setBlock(world, i + 14, j + 1, k + 10, KCore.BlueCloud.getDefaultState(), 0);
		this.setBlock(world, i + 14, j + 1, k + 11, KCore.BlueCloud.getDefaultState(), 0);
		this.setBlock(world, i + 14, j + 1, k + 12, KCore.BlueCloud.getDefaultState(), 0);
		this.setBlock(world, i + 14, j + 1, k + 13, KCore.BlueCloud.getDefaultState(), 0);
		this.setBlock(world, i + 14, j + 1, k + 14, KCore.BlueCloud.getDefaultState(), 0);
		this.setBlock(world, i + 14, j + 1, k + 15, KCore.BlueCloud.getDefaultState(), 0);
		this.setBlock(world, i + 14, j + 1, k + 16, KCore.BlueCloud.getDefaultState(), 0);
		this.setBlock(world, i + 14, j + 1, k + 17, KCore.BlueCloud.getDefaultState(), 0);
		this.setBlock(world, i + 14, j + 1, k + 18, KCore.BlueCloud.getDefaultState(), 0);
		this.setBlock(world, i + 14, j + 1, k + 19, KCore.BlueCloud.getDefaultState(), 0);
		this.setBlock(world, i + 14, j + 2, k + 8, KCore.BlueCondensedCloud.getDefaultState(), 0);
		this.setBlock(world, i + 14, j + 2, k + 9, KCore.BlueCondensedCloud.getDefaultState(), 0);
		this.setBlock(world, i + 14, j + 2, k + 10, KCore.BlueCondensedCloud.getDefaultState(), 0);
		this.setBlock(world, i + 14, j + 2, k + 11, KCore.BlueCondensedCloud.getDefaultState(), 0);
		this.setBlock(world, i + 14, j + 2, k + 12, KCore.BlueCondensedCloud.getDefaultState(), 0);
		this.setBlock(world, i + 14, j + 2, k + 13, KCore.BlueCondensedCloud.getDefaultState(), 0);
		this.setBlock(world, i + 14, j + 2, k + 14, KCore.BlueCondensedCloud.getDefaultState(), 0);
		this.setBlock(world, i + 14, j + 2, k + 15, KCore.BlueCondensedCloud.getDefaultState(), 0);
		this.setBlock(world, i + 14, j + 2, k + 16, KCore.BlueCondensedCloud.getDefaultState(), 0);
		this.setBlock(world, i + 14, j + 2, k + 17, KCore.BlueCondensedCloud.getDefaultState(), 0);
		this.setBlock(world, i + 14, j + 2, k + 18, KCore.BlueCondensedCloud.getDefaultState(), 0);
		this.setBlock(world, i + 14, j + 3, k + 8, Blocks.WATER.getDefaultState(), 0);
		this.setBlock(world, i + 14, j + 3, k + 9, KCore.BlueCloudBricks.getDefaultState(), 0);
		this.setBlock(world, i + 14, j + 3, k + 10, KCore.YellowCloudBlock.getDefaultState(), 0);
		this.setBlock(world, i + 14, j + 3, k + 11, KCore.YellowCloudBlock.getDefaultState(), 0);
		this.setBlock(world, i + 14, j + 3, k + 12, KCore.YellowCloudBlock.getDefaultState(), 0);
		this.setBlock(world, i + 14, j + 3, k + 13, KCore.YellowCloudBlock.getDefaultState(), 0);
		this.setBlock(world, i + 14, j + 3, k + 14, KCore.YellowCloudBlock.getDefaultState(), 0);
		this.setBlock(world, i + 14, j + 3, k + 15, KCore.BlueCloudBricks.getDefaultState(), 0);
		this.setBlock(world, i + 14, j + 3, k + 16, KCore.YellowCloudBlock.getDefaultState(), 0);
		this.setBlock(world, i + 14, j + 3, k + 17, KCore.BlueCloudBricks.getDefaultState(), 0);
		this.setBlock(world, i + 14, j + 4, k + 13, KCore.BlueCloudBricks.getDefaultState(), 0);
		this.setBlock(world, i + 14, j + 5, k + 13, KCore.BlueCloudBricks.getDefaultState(), 0);
		this.setBlock(world, i + 14, j + 6, k + 13, KCore.BlueCloudBricks.getDefaultState(), 0);
		this.setBlock(world, i + 14, j + 7, k + 8, KCore.BlueCloudBricks.getDefaultState(), 0);
		this.setBlock(world, i + 14, j + 7, k + 9, KCore.BlueCloudBricks.getDefaultState(), 0);
		this.setBlock(world, i + 14, j + 7, k + 10, KCore.BlueCloudBricks.getDefaultState(), 0);
		this.setBlock(world, i + 14, j + 7, k + 13, KCore.BlueCloudBricks.getDefaultState(), 0);
		this.setBlock(world, i + 14, j + 7, k + 14, KCore.BlueCloudBricks.getDefaultState(), 0);
		this.setBlock(world, i + 14, j + 7, k + 15, KCore.BlueCloudBricks.getDefaultState(), 0);
		this.setBlock(world, i + 14, j + 7, k + 16, KCore.BlueCloudBricks.getDefaultState(), 0);
		this.setBlock(world, i + 14, j + 8, k + 10, KCore.BlueCloudBricks.getDefaultState(), 0);
		this.setBlock(world, i + 14, j + 8, k + 13, KCore.BlueCloudBricks.getDefaultState(), 0);
		this.setBlock(world, i + 14, j + 8, k + 14, KCore.BlueCloudBricks.getDefaultState(), 0);
		this.setBlock(world, i + 14, j + 8, k + 15, KCore.BlueCloudBricks.getDefaultState(), 0);
		this.setBlock(world, i + 14, j + 9, k + 11, KCore.BlueCloudBricks.getDefaultState(), 0);
		this.setBlock(world, i + 14, j + 9, k + 12, KCore.BlueCloudBricks.getDefaultState(), 0);
		this.setBlock(world, i + 15, j + 0, k + 6, KCore.BlueCloud.getDefaultState(), 0);
		this.setBlock(world, i + 15, j + 0, k + 7, KCore.BlueCloud.getDefaultState(), 0);
		this.setBlock(world, i + 15, j + 0, k + 8, KCore.BlueCloud.getDefaultState(), 0);
		this.setBlock(world, i + 15, j + 0, k + 9, KCore.BlueCloud.getDefaultState(), 0);
		this.setBlock(world, i + 15, j + 0, k + 10, KCore.BlueCloud.getDefaultState(), 0);
		this.setBlock(world, i + 15, j + 0, k + 11, KCore.BlueCloud.getDefaultState(), 0);
		this.setBlock(world, i + 15, j + 0, k + 12, KCore.BlueCloud.getDefaultState(), 0);
		this.setBlock(world, i + 15, j + 0, k + 13, KCore.BlueCloud.getDefaultState(), 0);
		this.setBlock(world, i + 15, j + 0, k + 14, KCore.BlueCloud.getDefaultState(), 0);
		this.setBlock(world, i + 15, j + 0, k + 15, KCore.BlueCloud.getDefaultState(), 0);
		this.setBlock(world, i + 15, j + 0, k + 16, KCore.BlueCloud.getDefaultState(), 0);
		this.setBlock(world, i + 15, j + 0, k + 17, KCore.BlueCloud.getDefaultState(), 0);
		this.setBlock(world, i + 15, j + 0, k + 18, KCore.BlueCloud.getDefaultState(), 0);
		this.setBlock(world, i + 15, j + 0, k + 19, KCore.BlueCloud.getDefaultState(), 0);
		this.setBlock(world, i + 15, j + 1, k + 7, KCore.BlueCloud.getDefaultState(), 0);
		this.setBlock(world, i + 15, j + 1, k + 8, KCore.BlueCloud.getDefaultState(), 0);
		this.setBlock(world, i + 15, j + 1, k + 9, KCore.BlueCloud.getDefaultState(), 0);
		this.setBlock(world, i + 15, j + 1, k + 10, KCore.BlueCloud.getDefaultState(), 0);
		this.setBlock(world, i + 15, j + 1, k + 11, KCore.BlueCloud.getDefaultState(), 0);
		this.setBlock(world, i + 15, j + 1, k + 12, KCore.BlueCloud.getDefaultState(), 0);
		this.setBlock(world, i + 15, j + 1, k + 13, KCore.BlueCloud.getDefaultState(), 0);
		this.setBlock(world, i + 15, j + 1, k + 14, Blocks.WATER.getDefaultState(), 0);
		this.setBlock(world, i + 15, j + 1, k + 15, KCore.BlueCloud.getDefaultState(), 0);
		this.setBlock(world, i + 15, j + 1, k + 16, KCore.BlueCloud.getDefaultState(), 0);
		this.setBlock(world, i + 15, j + 1, k + 17, KCore.BlueCloud.getDefaultState(), 0);
		this.setBlock(world, i + 15, j + 1, k + 18, KCore.BlueCloud.getDefaultState(), 0);
		this.setBlock(world, i + 15, j + 1, k + 19, KCore.BlueCloud.getDefaultState(), 0);
		this.setBlock(world, i + 15, j + 2, k + 8, KCore.BlueCondensedCloud.getDefaultState(), 0);
		this.setBlock(world, i + 15, j + 2, k + 9, KCore.BlueCondensedCloud.getDefaultState(), 0);
		this.setBlock(world, i + 15, j + 2, k + 10, KCore.BlueCondensedCloud.getDefaultState(), 0);
		this.setBlock(world, i + 15, j + 2, k + 11, KCore.BlueCondensedCloud.getDefaultState(), 0);
		this.setBlock(world, i + 15, j + 2, k + 12, KCore.BlueCondensedCloud.getDefaultState(), 0);
		this.setBlock(world, i + 15, j + 2, k + 13, KCore.BlueCondensedCloud.getDefaultState(), 0);
		this.setBlock(world, i + 15, j + 2, k + 14, KCore.BlueCondensedCloud.getDefaultState(), 0);
		this.setBlock(world, i + 15, j + 2, k + 15, KCore.BlueCondensedCloud.getDefaultState(), 0);
		this.setBlock(world, i + 15, j + 2, k + 16, KCore.BlueCondensedCloud.getDefaultState(), 0);
		this.setBlock(world, i + 15, j + 2, k + 17, KCore.BlueCondensedCloud.getDefaultState(), 0);
		this.setBlock(world, i + 15, j + 2, k + 18, KCore.BlueCondensedCloud.getDefaultState(), 0);
		this.setBlock(world, i + 15, j + 3, k + 9, KCore.BlueCloudBricks.getDefaultState(), 0);
		this.setBlock(world, i + 15, j + 3, k + 10, KCore.YellowCloudBlock.getDefaultState(), 0);
		this.setBlock(world, i + 15, j + 3, k + 11, KCore.YellowCloudBlock.getDefaultState(), 0);
		this.setBlock(world, i + 15, j + 3, k + 12, KCore.BlueCloudBricks.getDefaultState(), 0);
		this.setBlock(world, i + 15, j + 3, k + 13, KCore.BlueCloudBricks.getDefaultState(), 0);
		this.setBlock(world, i + 15, j + 3, k + 14, KCore.BlueCloudBricks.getDefaultState(), 0);
		this.setBlock(world, i + 15, j + 3, k + 16, KCore.BlueCloudBricks.getDefaultState(), 0);
		this.setBlock(world, i + 15, j + 4, k + 11, KCore.BlueCloudBricks.getDefaultState(), 0);
		this.setBlock(world, i + 15, j + 5, k + 11, KCore.BlueCloudBricks.getDefaultState(), 0);
		this.setBlock(world, i + 15, j + 6, k + 11, KCore.BlueCloudBricks.getDefaultState(), 0);
		this.setBlock(world, i + 15, j + 7, k + 9, KCore.BlueCloudBricks.getDefaultState(), 0);
		this.setBlock(world, i + 15, j + 7, k + 10, KCore.BlueCloudBricks.getDefaultState(), 0);
		this.setBlock(world, i + 15, j + 7, k + 11, KCore.BlueCloudBricks.getDefaultState(), 0);
		this.setBlock(world, i + 15, j + 7, k + 12, KCore.BlueCloudBricks.getDefaultState(), 0);
		this.setBlock(world, i + 15, j + 7, k + 13, KCore.BlueCloudBricks.getDefaultState(), 0);
		this.setBlock(world, i + 15, j + 7, k + 14, KCore.BlueCloudBricks.getDefaultState(), 0);
		this.setBlock(world, i + 15, j + 7, k + 15, KCore.BlueCloudBricks.getDefaultState(), 0);
		this.setBlock(world, i + 15, j + 8, k + 10, KCore.BlueCloudBricks.getDefaultState(), 0);
		this.setBlock(world, i + 15, j + 8, k + 11, KCore.BlueCloudBricks.getDefaultState(), 0);
		this.setBlock(world, i + 15, j + 8, k + 12, KCore.BlueCloudBricks.getDefaultState(), 0);
		this.setBlock(world, i + 15, j + 8, k + 13, KCore.BlueCloudBricks.getDefaultState(), 0);
		this.setBlock(world, i + 16, j + 0, k + 7, KCore.BlueCloud.getDefaultState(), 0);
		this.setBlock(world, i + 16, j + 0, k + 8, KCore.BlueCloud.getDefaultState(), 0);
		this.setBlock(world, i + 16, j + 0, k + 9, KCore.BlueCloud.getDefaultState(), 0);
		this.setBlock(world, i + 16, j + 0, k + 10, KCore.BlueCloud.getDefaultState(), 0);
		this.setBlock(world, i + 16, j + 0, k + 11, KCore.BlueCloud.getDefaultState(), 0);
		this.setBlock(world, i + 16, j + 0, k + 12, KCore.BlueCloud.getDefaultState(), 0);
		this.setBlock(world, i + 16, j + 0, k + 13, KCore.BlueCloud.getDefaultState(), 0);
		this.setBlock(world, i + 16, j + 0, k + 14, KCore.BlueCloud.getDefaultState(), 0);
		this.setBlock(world, i + 16, j + 0, k + 15, KCore.BlueCloud.getDefaultState(), 0);
		this.setBlock(world, i + 16, j + 0, k + 16, KCore.BlueCloud.getDefaultState(), 0);
		this.setBlock(world, i + 16, j + 0, k + 17, KCore.BlueCloud.getDefaultState(), 0);
		this.setBlock(world, i + 16, j + 0, k + 18, KCore.BlueCloud.getDefaultState(), 0);
		this.setBlock(world, i + 16, j + 0, k + 19, KCore.BlueCloud.getDefaultState(), 0);
		this.setBlock(world, i + 16, j + 0, k + 20, KCore.BlueCloud.getDefaultState(), 0);
		this.setBlock(world, i + 16, j + 1, k + 7, KCore.BlueCloud.getDefaultState(), 0);
		this.setBlock(world, i + 16, j + 1, k + 8, KCore.BlueCloud.getDefaultState(), 0);
		this.setBlock(world, i + 16, j + 1, k + 9, KCore.BlueCloud.getDefaultState(), 0);
		this.setBlock(world, i + 16, j + 1, k + 10, KCore.BlueCloud.getDefaultState(), 0);
		this.setBlock(world, i + 16, j + 1, k + 11, KCore.BlueCloud.getDefaultState(), 0);
		this.setBlock(world, i + 16, j + 1, k + 12, KCore.BlueCloud.getDefaultState(), 0);
		this.setBlock(world, i + 16, j + 1, k + 13, KCore.BlueCloud.getDefaultState(), 0);
		this.setBlock(world, i + 16, j + 1, k + 15, KCore.BlueCloud.getDefaultState(), 0);
		this.setBlock(world, i + 16, j + 1, k + 16, KCore.BlueCloud.getDefaultState(), 0);
		this.setBlock(world, i + 16, j + 1, k + 17, KCore.BlueCloud.getDefaultState(), 0);
		this.setBlock(world, i + 16, j + 1, k + 18, KCore.BlueCloud.getDefaultState(), 0);
		this.setBlock(world, i + 16, j + 1, k + 19, KCore.BlueCloud.getDefaultState(), 0);
		this.setBlock(world, i + 16, j + 2, k + 9, KCore.BlueCondensedCloud.getDefaultState(), 0);
		this.setBlock(world, i + 16, j + 2, k + 10, KCore.BlueCondensedCloud.getDefaultState(), 0);
		this.setBlock(world, i + 16, j + 2, k + 11, KCore.BlueCondensedCloud.getDefaultState(), 0);
		this.setBlock(world, i + 16, j + 2, k + 12, KCore.BlueCondensedCloud.getDefaultState(), 0);
		this.setBlock(world, i + 16, j + 2, k + 16, KCore.BlueCondensedCloud.getDefaultState(), 0);
		this.setBlock(world, i + 16, j + 2, k + 17, KCore.BlueCondensedCloud.getDefaultState(), 0);
		this.setBlock(world, i + 16, j + 2, k + 18, KCore.BlueCondensedCloud.getDefaultState(), 0);
		this.setBlock(world, i + 16, j + 2, k + 19, KCore.BlueCondensedCloud.getDefaultState(), 0);
		this.setBlock(world, i + 16, j + 3, k + 9, KCore.BlueCloudBricks.getDefaultState(), 0);
		this.setBlock(world, i + 16, j + 3, k + 10, KCore.YellowCloudBlock.getDefaultState(), 0);
		this.setBlock(world, i + 16, j + 3, k + 11, KCore.YellowCloudBlock.getDefaultState(), 0);
		this.setBlock(world, i + 16, j + 3, k + 12, KCore.BlueCloudBricks.getDefaultState(), 0);
		this.setBlock(world, i + 16, j + 7, k + 10, KCore.BlueCloudBricks.getDefaultState(), 0);
		this.setBlock(world, i + 16, j + 7, k + 11, KCore.BlueCloudBricks.getDefaultState(), 0);
		this.setBlock(world, i + 16, j + 7, k + 12, KCore.BlueCloudBricks.getDefaultState(), 0);
		this.setBlock(world, i + 16, j + 7, k + 13, KCore.BlueCloudBricks.getDefaultState(), 0);
		this.setBlock(world, i + 17, j + 0, k + 8, KCore.BlueCloud.getDefaultState(), 0);
		this.setBlock(world, i + 17, j + 0, k + 9, KCore.BlueCloud.getDefaultState(), 0);
		this.setBlock(world, i + 17, j + 0, k + 10, KCore.BlueCloud.getDefaultState(), 0);
		this.setBlock(world, i + 17, j + 0, k + 11, KCore.BlueCloud.getDefaultState(), 0);
		this.setBlock(world, i + 17, j + 0, k + 12, KCore.BlueCloud.getDefaultState(), 0);
		this.setBlock(world, i + 17, j + 0, k + 13, KCore.BlueCloud.getDefaultState(), 0);
		this.setBlock(world, i + 17, j + 0, k + 14, KCore.BlueCloud.getDefaultState(), 0);
		this.setBlock(world, i + 17, j + 0, k + 15, KCore.BlueCloud.getDefaultState(), 0);
		this.setBlock(world, i + 17, j + 0, k + 16, KCore.BlueCloud.getDefaultState(), 0);
		this.setBlock(world, i + 17, j + 0, k + 17, KCore.BlueCloud.getDefaultState(), 0);
		this.setBlock(world, i + 17, j + 0, k + 18, KCore.BlueCloud.getDefaultState(), 0);
		this.setBlock(world, i + 17, j + 0, k + 19, KCore.BlueCloud.getDefaultState(), 0);
		this.setBlock(world, i + 17, j + 0, k + 20, KCore.BlueCloud.getDefaultState(), 0);
		this.setBlock(world, i + 17, j + 0, k + 21, KCore.BlueCloud.getDefaultState(), 0);
		this.setBlock(world, i + 17, j + 1, k + 9, KCore.BlueCloud.getDefaultState(), 0);
		this.setBlock(world, i + 17, j + 1, k + 10, KCore.BlueCloud.getDefaultState(), 0);
		this.setBlock(world, i + 17, j + 1, k + 11, KCore.BlueCloud.getDefaultState(), 0);
		this.setBlock(world, i + 17, j + 1, k + 12, KCore.BlueCloud.getDefaultState(), 0);
		this.setBlock(world, i + 17, j + 1, k + 15, KCore.BlueCloud.getDefaultState(), 0);
		this.setBlock(world, i + 17, j + 1, k + 16, KCore.BlueCloud.getDefaultState(), 0);
		this.setBlock(world, i + 17, j + 1, k + 17, KCore.BlueCloud.getDefaultState(), 0);
		this.setBlock(world, i + 17, j + 1, k + 18, KCore.BlueCloud.getDefaultState(), 0);
		this.setBlock(world, i + 17, j + 1, k + 19, KCore.BlueCloud.getDefaultState(), 0);
		this.setBlock(world, i + 17, j + 1, k + 20, KCore.BlueCloud.getDefaultState(), 0);
		this.setBlock(world, i + 17, j + 1, k + 21, KCore.BlueCloud.getDefaultState(), 0);
		this.setBlock(world, i + 17, j + 2, k + 9, KCore.BlueCondensedCloud.getDefaultState(), 0);
		this.setBlock(world, i + 17, j + 2, k + 10, KCore.BlueCondensedCloud.getDefaultState(), 0);
		this.setBlock(world, i + 17, j + 2, k + 11, KCore.BlueCondensedCloud.getDefaultState(), 0);
		this.setBlock(world, i + 17, j + 2, k + 12, KCore.BlueCondensedCloud.getDefaultState(), 0);
		this.setBlock(world, i + 17, j + 2, k + 16, KCore.BlueCondensedCloud.getDefaultState(), 0);
		this.setBlock(world, i + 17, j + 2, k + 17, KCore.BlueCondensedCloud.getDefaultState(), 0);
		this.setBlock(world, i + 17, j + 2, k + 18, KCore.BlueCondensedCloud.getDefaultState(), 0);
		this.setBlock(world, i + 17, j + 2, k + 19, KCore.BlueCondensedCloud.getDefaultState(), 0);
		this.setBlock(world, i + 17, j + 3, k + 10, KCore.BlueCloudBricks.getDefaultState(), 0);
		this.setBlock(world, i + 17, j + 3, k + 11, KCore.BlueCloudBricks.getDefaultState(), 0);
		this.setBlock(world, i + 18, j + 0, k + 8, KCore.BlueCloud.getDefaultState(), 0);
		this.setBlock(world, i + 18, j + 0, k + 9, KCore.BlueCloud.getDefaultState(), 0);
		this.setBlock(world, i + 18, j + 0, k + 10, KCore.BlueCloud.getDefaultState(), 0);
		this.setBlock(world, i + 18, j + 0, k + 11, KCore.BlueCloud.getDefaultState(), 0);
		this.setBlock(world, i + 18, j + 0, k + 12, KCore.BlueCloud.getDefaultState(), 0);
		this.setBlock(world, i + 18, j + 0, k + 13, KCore.BlueCloud.getDefaultState(), 0);
		this.setBlock(world, i + 18, j + 0, k + 15, KCore.BlueCloud.getDefaultState(), 0);
		this.setBlock(world, i + 18, j + 0, k + 16, KCore.BlueCloud.getDefaultState(), 0);
		this.setBlock(world, i + 18, j + 0, k + 17, KCore.BlueCloud.getDefaultState(), 0);
		this.setBlock(world, i + 18, j + 0, k + 18, KCore.BlueCloud.getDefaultState(), 0);
		this.setBlock(world, i + 18, j + 0, k + 19, KCore.BlueCloud.getDefaultState(), 0);
		this.setBlock(world, i + 18, j + 0, k + 20, KCore.BlueCloud.getDefaultState(), 0);
		this.setBlock(world, i + 18, j + 0, k + 21, KCore.BlueCloud.getDefaultState(), 0);
		this.setBlock(world, i + 18, j + 1, k + 9, KCore.BlueCloud.getDefaultState(), 0);
		this.setBlock(world, i + 18, j + 1, k + 10, KCore.BlueCloud.getDefaultState(), 0);
		this.setBlock(world, i + 18, j + 1, k + 11, KCore.BlueCloud.getDefaultState(), 0);
		this.setBlock(world, i + 18, j + 1, k + 12, KCore.BlueCloud.getDefaultState(), 0);
		this.setBlock(world, i + 18, j + 1, k + 16, KCore.BlueCloud.getDefaultState(), 0);
		this.setBlock(world, i + 18, j + 1, k + 17, KCore.BlueCloud.getDefaultState(), 0);
		this.setBlock(world, i + 18, j + 1, k + 18, KCore.BlueCloud.getDefaultState(), 0);
		this.setBlock(world, i + 18, j + 1, k + 19, KCore.BlueCloud.getDefaultState(), 0);
		this.setBlock(world, i + 18, j + 1, k + 20, KCore.BlueCloud.getDefaultState(), 0);
		this.setBlock(world, i + 18, j + 1, k + 21, KCore.BlueCloud.getDefaultState(), 0);
		this.setBlock(world, i + 18, j + 2, k + 10, KCore.BlueCondensedCloud.getDefaultState(), 0);
		this.setBlock(world, i + 18, j + 2, k + 11, KCore.BlueCondensedCloud.getDefaultState(), 0);
		this.setBlock(world, i + 18, j + 2, k + 17, KCore.BlueCondensedCloud.getDefaultState(), 0);
		this.setBlock(world, i + 18, j + 2, k + 18, KCore.BlueCondensedCloud.getDefaultState(), 0);
		this.setBlock(world, i + 18, j + 2, k + 19, KCore.BlueCondensedCloud.getDefaultState(), 0);
		this.setBlock(world, i + 18, j + 2, k + 20, KCore.BlueCondensedCloud.getDefaultState(), 0);
		this.setBlock(world, i + 19, j + 0, k + 9, KCore.BlueCloud.getDefaultState(), 0);
		this.setBlock(world, i + 19, j + 0, k + 10, KCore.BlueCloud.getDefaultState(), 0);
		this.setBlock(world, i + 19, j + 0, k + 11, KCore.BlueCloud.getDefaultState(), 0);
		this.setBlock(world, i + 19, j + 0, k + 12, KCore.BlueCloud.getDefaultState(), 0);
		this.setBlock(world, i + 19, j + 0, k + 15, KCore.BlueCloud.getDefaultState(), 0);
		this.setBlock(world, i + 19, j + 0, k + 17, KCore.BlueCloud.getDefaultState(), 0);
		this.setBlock(world, i + 19, j + 0, k + 18, KCore.BlueCloud.getDefaultState(), 0);
		this.setBlock(world, i + 19, j + 0, k + 19, KCore.BlueCloud.getDefaultState(), 0);
		this.setBlock(world, i + 19, j + 0, k + 20, KCore.BlueCloud.getDefaultState(), 0);
		this.setBlock(world, i + 19, j + 1, k + 10, KCore.BlueCloud.getDefaultState(), 0);
		this.setBlock(world, i + 19, j + 1, k + 11, KCore.BlueCloud.getDefaultState(), 0);
		this.setBlock(world, i + 19, j + 1, k + 12, KCore.BlueCloud.getDefaultState(), 0);
		this.setBlock(world, i + 19, j + 1, k + 18, KCore.BlueCloud.getDefaultState(), 0);
		this.setBlock(world, i + 19, j + 1, k + 19, KCore.BlueCloud.getDefaultState(), 0);
